Workbook

Sheet Inventario_Columnas
A1: archivo | B1: hoja | C1: fila_encabezado | D1: filas_datos | E1: filas_excel | F1: n_columnas | G1: n_columna | H1: nombre_columna | I1: columnas_completas | J1: ejemplo_1 | K1: ejemplo_2 | L1: ejemplo_3
A2: 01_Data\01_Raw\PARATEC\GENERACION\EOLICA\PARATEC_Peólica_14-08-2026.xlsx | B2: Peólica | C2: 6 | D2: 3 | E2: 2000 | F2: 33 | G2: 1 | H2: Nombre | I2: Nombre | Operador | Estado | Fecha de puesta en operación FPO | Modo de operación | Punto de conexión o barra del STR/STN | Tipo de proceso productivo | Unidades equivalentes eólica | Voltaje de conexión [kV] | Potencia nominal [MW] | Potencia máxima [MW] | Mínimo técnico [MW] | Capacidad efectiva neta [MW] | Arranque autónomo [Si/No] | Estatismo en frecuencia [%] | Estatismo en frecuencia mínimo [%] | Estatismo en frecuencia máximo [%] | Estatismo en tensión [%] | Banda muerta de operación [mHz] | Rango banda muerta de operación [mHz] | Capacidad de absorción [MVAr] | Capacidad de generación [MVAr] | Constante K | Tiempo de respuesta inicial del control rápido de corriente reactiva [ms] | Tiempo de respuesta inicial máximo-frecuencia [s] | Tiempo de establecimiento máximo-frecuencia [s] | Tiempo de respuesta inicial de tensión [s] | Tiempo de establecimiento de tensión [s] | Velocidad de toma de carga [MW/min] | Velocidad de descarga [MW/min] | Departamento | Municipio | Subárea | J2: PARQUE EOLICO CARRETO | K2: PARQUE EOLICO GUAJIRA I | L2: PARQUE EOLICO WESP01
A3: 01_Data\01_Raw\PARATEC\GENERACION\EOLICA\PARATEC_Peólica_14-08-2026.xlsx | B3: Peólica | C3: 6 | D3: 3 | E3: 2000 | F3: 33 | G3: 2 | H3: Operador | I3: Nombre | Operador | Estado | Fecha de puesta en operación FPO | Modo de operación | Punto de conexión o barra del STR/STN | Tipo de proceso productivo | Unidades equivalentes eólica | Voltaje de conexión [kV] | Potencia nominal [MW] | Potencia máxima [MW] | Mínimo técnico [MW] | Capacidad efectiva neta [MW] | Arranque autónomo [Si/No] | Estatismo en frecuencia [%] | Estatismo en frecuencia mínimo [%] | Estatismo en frecuencia máximo [%] | Estatismo en tensión [%] | Banda muerta de operación [mHz] | Rango banda muerta de operación [mHz] | Capacidad de absorción [MVAr] | Capacidad de generación [MVAr] | Constante K | Tiempo de respuesta inicial del control rápido de corriente reactiva [ms] | Tiempo de respuesta inicial máximo-frecuencia [s] | Tiempo de establecimiento máximo-frecuencia [s] | Tiempo de respuesta inicial de tensión [s] | Tiempo de establecimiento de tensión [s] | Velocidad de toma de carga [MW/min] | Velocidad de descarga [MW/min] | Departamento | Municipio | Subárea | J3: CELSIA COLOMBIA S.A. E.S.P. | K3: ISAGEN S.A. E.S.P.
A4: 01_Data\01_Raw\PARATEC\GENERACION\EOLICA\PARATEC_Peólica_14-08-2026.xlsx | B4: Peólica | C4: 6 | D4: 3 | E4: 2000 | F4: 33 | G4: 3 | H4: Estado | I4: Nombre | Operador | Estado | Fecha de puesta en operación FPO | Modo de operación | Punto de conexión o barra del STR/STN | Tipo de proceso productivo | Unidades equivalentes eólica | Voltaje de conexión [kV] | Potencia nominal [MW] | Potencia máxima [MW] | Mínimo técnico [MW] | Capacidad efectiva neta [MW] | Arranque autónomo [Si/No] | Estatismo en frecuencia [%] | Estatismo en frecuencia mínimo [%] | Estatismo en frecuencia máximo [%] | Estatismo en tensión [%] | Banda muerta de operación [mHz] | Rango banda muerta de operación [mHz] | Capacidad de absorción [MVAr] | Capacidad de generación [MVAr] | Constante K | Tiempo de respuesta inicial del control rápido de corriente reactiva [ms] | Tiempo de respuesta inicial máximo-frecuencia [s] | Tiempo de establecimiento máximo-frecuencia [s] | Tiempo de respuesta inicial de tensión [s] | Tiempo de establecimiento de tensión [s] | Velocidad de toma de carga [MW/min] | Velocidad de descarga [MW/min] | Departamento | Municipio | Subárea | J4: Pruebas
A5: 01_Data\01_Raw\PARATEC\GENERACION\EOLICA\PARATEC_Peólica_14-08-2026.xlsx | B5: Peólica | C5: 6 | D5: 3 | E5: 2000 | F5: 33 | G5: 4 | H5: Fecha de puesta en operación FPO | I5: Nombre | Operador | Estado | Fecha de puesta en operación FPO | Modo de operación | Punto de conexión o barra del STR/STN | Tipo de proceso productivo | Unidades equivalentes eólica | Voltaje de conexión [kV] | Potencia nominal [MW] | Potencia máxima [MW] | Mínimo técnico [MW] | Capacidad efectiva neta [MW] | Arranque autónomo [Si/No] | Estatismo en frecuencia [%] | Estatismo en frecuencia mínimo [%] | Estatismo en frecuencia máximo [%] | Estatismo en tensión [%] | Banda muerta de operación [mHz] | Rango banda muerta de operación [mHz] | Capacidad de absorción [MVAr] | Capacidad de generación [MVAr] | Constante K | Tiempo de respuesta inicial del control rápido de corriente reactiva [ms] | Tiempo de respuesta inicial máximo-frecuencia [s] | Tiempo de establecimiento máximo-frecuencia [s] | Tiempo de respuesta inicial de tensión [s] | Tiempo de establecimiento de tensión [s] | Velocidad de toma de carga [MW/min] | Velocidad de descarga [MW/min] | Departamento | Municipio | Subárea | J5: -
A6: 01_Data\01_Raw\PARATEC\GENERACION\EOLICA\PARATEC_Peólica_14-08-2026.xlsx | B6: Peólica | C6: 6 | D6: 3 | E6: 2000 | F6: 33 | G6: 5 | H6: Modo de operación | I6: Nombre | Operador | Estado | Fecha de puesta en operación FPO | Modo de operación | Punto de conexión o barra del STR/STN | Tipo de proceso productivo | Unidades equivalentes eólica | Voltaje de conexión [kV] | Potencia nominal [MW] | Potencia máxima [MW] | Mínimo técnico [MW] | Capacidad efectiva neta [MW] | Arranque autónomo [Si/No] | Estatismo en frecuencia [%] | Estatismo en frecuencia mínimo [%] | Estatismo en frecuencia máximo [%] | Estatismo en tensión [%] | Banda muerta de operación [mHz] | Rango banda muerta de operación [mHz] | Capacidad de absorción [MVAr] | Capacidad de generación [MVAr] | Constante K | Tiempo de respuesta inicial del control rápido de corriente reactiva [ms] | Tiempo de respuesta inicial máximo-frecuencia [s] | Tiempo de establecimiento máximo-frecuencia [s] | Tiempo de respuesta inicial de tensión [s] | Tiempo de establecimiento de tensión [s] | Velocidad de toma de carga [MW/min] | Velocidad de descarga [MW/min] | Departamento | Municipio | Subárea | J6: No Despachada Centralmente
A7: 01_Data\01_Raw\PARATEC\GENERACION\EOLICA\PARATEC_Peólica_14-08-2026.xlsx | B7: Peólica | C7: 6 | D7: 3 | E7: 2000 | F7: 33 | G7: 6 | H7: Punto de conexión o barra del STR/STN | I7: Nombre | Operador | Estado | Fecha de puesta en operación FPO | Modo de operación | Punto de conexión o barra del STR/STN | Tipo de proceso productivo | Unidades equivalentes eólica | Voltaje de conexión [kV] | Potencia nominal [MW] | Potencia máxima [MW] | Mínimo técnico [MW] | Capacidad efectiva neta [MW] | Arranque autónomo [Si/No] | Estatismo en frecuencia [%] | Estatismo en frecuencia mínimo [%] | Estatismo en frecuencia máximo [%] | Estatismo en tensión [%] | Banda muerta de operación [mHz] | Rango banda muerta de operación [mHz] | Capacidad de absorción [MVAr] | Capacidad de generación [MVAr] | Constante K | Tiempo de respuesta inicial del control rápido de corriente reactiva [ms] | Tiempo de respuesta inicial máximo-frecuencia [s] | Tiempo de establecimiento máximo-frecuencia [s] | Tiempo de respuesta inicial de tensión [s] | Tiempo de establecimiento de tensión [s] | Velocidad de toma de carga [MW/min] | Velocidad de descarga [MW/min] | Departamento | Municipio | Subárea | J7: BARANOA 34.5 | K7: CUESTECITAS 110 | L7: JOUKTAI 110
A8: 01_Data\01_Raw\PARATEC\GENERACION\EOLICA\PARATEC_Peólica_14-08-2026.xlsx | B8: Peólica | C8: 6 | D8: 3 | E8: 2000 | F8: 33 | G8: 7 | H8: Tipo de proceso productivo | I8: Nombre | Operador | Estado | Fecha de puesta en operación FPO | Modo de operación | Punto de conexión o barra del STR/STN | Tipo de proceso productivo | Unidades equivalentes eólica | Voltaje de conexión [kV] | Potencia nominal [MW] | Potencia máxima [MW] | Mínimo técnico [MW] | Capacidad efectiva neta [MW] | Arranque autónomo [Si/No] | Estatismo en frecuencia [%] | Estatismo en frecuencia mínimo [%] | Estatismo en frecuencia máximo [%] | Estatismo en tensión [%] | Banda muerta de operación [mHz] | Rango banda muerta de operación [mHz] | Capacidad de absorción [MVAr] | Capacidad de generación [MVAr] | Constante K | Tiempo de respuesta inicial del control rápido de corriente reactiva [ms] | Tiempo de respuesta inicial máximo-frecuencia [s] | Tiempo de establecimiento máximo-frecuencia [s] | Tiempo de respuesta inicial de tensión [s] | Tiempo de establecimiento de tensión [s] | Velocidad de toma de carga [MW/min] | Velocidad de descarga [MW/min] | Departamento | Municipio | Subárea | J8: Generador
A9: 01_Data\01_Raw\PARATEC\GENERACION\EOLICA\PARATEC_Peólica_14-08-2026.xlsx | B9: Peólica | C9: 6 | D9: 3 | E9: 2000 | F9: 33 | G9: 8 | H9: Unidades equivalentes eólica | I9: Nombre | Operador | Estado | Fecha de puesta en operación FPO | Modo de operación | Punto de conexión o barra del STR/STN | Tipo de proceso productivo | Unidades equivalentes eólica | Voltaje de conexión [kV] | Potencia nominal [MW] | Potencia máxima [MW] | Mínimo técnico [MW] | Capacidad efectiva neta [MW] | Arranque autónomo [Si/No] | Estatismo en frecuencia [%] | Estatismo en frecuencia mínimo [%] | Estatismo en frecuencia máximo [%] | Estatismo en tensión [%] | Banda muerta de operación [mHz] | Rango banda muerta de operación [mHz] | Capacidad de absorción [MVAr] | Capacidad de generación [MVAr] | Constante K | Tiempo de respuesta inicial del control rápido de corriente reactiva [ms] | Tiempo de respuesta inicial máximo-frecuencia [s] | Tiempo de establecimiento máximo-frecuencia [s] | Tiempo de respuesta inicial de tensión [s] | Tiempo de establecimiento de tensión [s] | Velocidad de toma de carga [MW/min] | Velocidad de descarga [MW/min] | Departamento | Municipio | Subárea | J9: PARQUE EOLICO CARRETO 1 | K9: PARQUE EOLICO GUAJIRA I 1 | L9: PARQUE EOLICO WESP01 1
A10: 01_Data\01_Raw\PARATEC\GENERACION\EOLICA\PARATEC_Peólica_14-08-2026.xlsx | B10: Peólica | C10: 6 | D10: 3 | E10: 2000 | F10: 33 | G10: 9 | H10: Voltaje de conexión [kV] | I10: Nombre | Operador | Estado | Fecha de puesta en operación FPO | Modo de operación | Punto de conexión o barra del STR/STN | Tipo de proceso productivo | Unidades equivalentes eólica | Voltaje de conexión [kV] | Potencia nominal [MW] | Potencia máxima [MW] | Mínimo técnico [MW] | Capacidad efectiva neta [MW] | Arranque autónomo [Si/No] | Estatismo en frecuencia [%] | Estatismo en frecuencia mínimo [%] | Estatismo en frecuencia máximo [%] | Estatismo en tensión [%] | Banda muerta de operación [mHz] | Rango banda muerta de operación [mHz] | Capacidad de absorción [MVAr] | Capacidad de generación [MVAr] | Constante K | Tiempo de respuesta inicial del control rápido de corriente reactiva [ms] | Tiempo de respuesta inicial máximo-frecuencia [s] | Tiempo de establecimiento máximo-frecuencia [s] | Tiempo de respuesta inicial de tensión [s] | Tiempo de establecimiento de tensión [s] | Velocidad de toma de carga [MW/min] | Velocidad de descarga [MW/min] | Departamento | Municipio | Subárea | J10: 34,5 | K10: 110
A11: 01_Data\01_Raw\PARATEC\GENERACION\EOLICA\PARATEC_Peólica_14-08-2026.xlsx | B11: Peólica | C11: 6 | D11: 3 | E11: 2000 | F11: 33 | G11: 10 | H11: Potencia nominal [MW] | I11: Nombre | Operador | Estado | Fecha de puesta en operación FPO | Modo de operación | Punto de conexión o barra del STR/STN | Tipo de proceso productivo | Unidades equivalentes eólica | Voltaje de conexión [kV] | Potencia nominal [MW] | Potencia máxima [MW] | Mínimo técnico [MW] | Capacidad efectiva neta [MW] | Arranque autónomo [Si/No] | Estatismo en frecuencia [%] | Estatismo en frecuencia mínimo [%] | Estatismo en frecuencia máximo [%] | Estatismo en tensión [%] | Banda muerta de operación [mHz] | Rango banda muerta de operación [mHz] | Capacidad de absorción [MVAr] | Capacidad de generación [MVAr] | Constante K | Tiempo de respuesta inicial del control rápido de corriente reactiva [ms] | Tiempo de respuesta inicial máximo-frecuencia [s] | Tiempo de establecimiento máximo-frecuencia [s] | Tiempo de respuesta inicial de tensión [s] | Tiempo de establecimiento de tensión [s] | Velocidad de toma de carga [MW/min] | Velocidad de descarga [MW/min] | Departamento | Municipio | Subárea | J11: 9,6 | K11: 20 | L11: 13,8
A12: 01_Data\01_Raw\PARATEC\GENERACION\EOLICA\PARATEC_Peólica_14-08-2026.xlsx | B12: Peólica | C12: 6 | D12: 3 | E12: 2000 | F12: 33 | G12: 11 | H12: Potencia máxima [MW] | I12: Nombre | Operador | Estado | Fecha de puesta en operación FPO | Modo de operación | Punto de conexión o barra del STR/STN | Tipo de proceso productivo | Unidades equivalentes eólica | Voltaje de conexión [kV] | Potencia nominal [MW] | Potencia máxima [MW] | Mínimo técnico [MW] | Capacidad efectiva neta [MW] | Arranque autónomo [Si/No] | Estatismo en frecuencia [%] | Estatismo en frecuencia mínimo [%] | Estatismo en frecuencia máximo [%] | Estatismo en tensión [%] | Banda muerta de operación [mHz] | Rango banda muerta de operación [mHz] | Capacidad de absorción [MVAr] | Capacidad de generación [MVAr] | Constante K | Tiempo de respuesta inicial del control rápido de corriente reactiva [ms] | Tiempo de respuesta inicial máximo-frecuencia [s] | Tiempo de establecimiento máximo-frecuencia [s] | Tiempo de respuesta inicial de tensión [s] | Tiempo de establecimiento de tensión [s] | Velocidad de toma de carga [MW/min] | Velocidad de descarga [MW/min] | Departamento | Municipio | Subárea | J12: 9,6 | K12: 20 | L12: 13,438
A13: 01_Data\01_Raw\PARATEC\GENERACION\EOLICA\PARATEC_Peólica_14-08-2026.xlsx | B13: Peólica | C13: 6 | D13: 3 | E13: 2000 | F13: 33 | G13: 12 | H13: Mínimo técnico [MW] | I13: Nombre | Operador | Estado | Fecha de puesta en operación FPO | Modo de operación | Punto de conexión o barra del STR/STN | Tipo de proceso productivo | Unidades equivalentes eólica | Voltaje de conexión [kV] | Potencia nominal [MW] | Potencia máxima [MW] | Mínimo técnico [MW] | Capacidad efectiva neta [MW] | Arranque autónomo [Si/No] | Estatismo en frecuencia [%] | Estatismo en frecuencia mínimo [%] | Estatismo en frecuencia máximo [%] | Estatismo en tensión [%] | Banda muerta de operación [mHz] | Rango banda muerta de operación [mHz] | Capacidad de absorción [MVAr] | Capacidad de generación [MVAr] | Constante K | Tiempo de respuesta inicial del control rápido de corriente reactiva [ms] | Tiempo de respuesta inicial máximo-frecuencia [s] | Tiempo de establecimiento máximo-frecuencia [s] | Tiempo de respuesta inicial de tensión [s] | Tiempo de establecimiento de tensión [s] | Velocidad de toma de carga [MW/min] | Velocidad de descarga [MW/min] | Departamento | Municipio | Subárea | J13: 0,48 | K13: 0,4 | L13: 0,35
A14: 01_Data\01_Raw\PARATEC\GENERACION\EOLICA\PARATEC_Peólica_14-08-2026.xlsx | B14: Peólica | C14: 6 | D14: 3 | E14: 2000 | F14: 33 | G14: 13 | H14: Capacidad efectiva neta [MW] | I14: Nombre | Operador | Estado | Fecha de puesta en operación FPO | Modo de operación | Punto de conexión o barra del STR/STN | Tipo de proceso productivo | Unidades equivalentes eólica | Voltaje de conexión [kV] | Potencia nominal [MW] | Potencia máxima [MW] | Mínimo técnico [MW] | Capacidad efectiva neta [MW] | Arranque autónomo [Si/No] | Estatismo en frecuencia [%] | Estatismo en frecuencia mínimo [%] | Estatismo en frecuencia máximo [%] | Estatismo en tensión [%] | Banda muerta de operación [mHz] | Rango banda muerta de operación [mHz] | Capacidad de absorción [MVAr] | Capacidad de generación [MVAr] | Constante K | Tiempo de respuesta inicial del control rápido de corriente reactiva [ms] | Tiempo de respuesta inicial máximo-frecuencia [s] | Tiempo de establecimiento máximo-frecuencia [s] | Tiempo de respuesta inicial de tensión [s] | Tiempo de establecimiento de tensión [s] | Velocidad de toma de carga [MW/min] | Velocidad de descarga [MW/min] | Departamento | Municipio | Subárea | J14: 9,1 | K14: 19,9 | L14: 12
A15: 01_Data\01_Raw\PARATEC\GENERACION\EOLICA\PARATEC_Peólica_14-08-2026.xlsx | B15: Peólica | C15: 6 | D15: 3 | E15: 2000 | F15: 33 | G15: 14 | H15: Arranque autónomo [Si/No] | I15: Nombre | Operador | Estado | Fecha de puesta en operación FPO | Modo de operación | Punto de conexión o barra del STR/STN | Tipo de proceso productivo | Unidades equivalentes eólica | Voltaje de conexión [kV] | Potencia nominal [MW] | Potencia máxima [MW] | Mínimo técnico [MW] | Capacidad efectiva neta [MW] | Arranque autónomo [Si/No] | Estatismo en frecuencia [%] | Estatismo en frecuencia mínimo [%] | Estatismo en frecuencia máximo [%] | Estatismo en tensión [%] | Banda muerta de operación [mHz] | Rango banda muerta de operación [mHz] | Capacidad de absorción [MVAr] | Capacidad de generación [MVAr] | Constante K | Tiempo de respuesta inicial del control rápido de corriente reactiva [ms] | Tiempo de respuesta inicial máximo-frecuencia [s] | Tiempo de establecimiento máximo-frecuencia [s] | Tiempo de respuesta inicial de tensión [s] | Tiempo de establecimiento de tensión [s] | Velocidad de toma de carga [MW/min] | Velocidad de descarga [MW/min] | Departamento | Municipio | Subárea | J15: No
A16: 01_Data\01_Raw\PARATEC\GENERACION\EOLICA\PARATEC_Peólica_14-08-2026.xlsx | B16: Peólica | C16: 6 | D16: 3 | E16: 2000 | F16: 33 | G16: 15 | H16: Estatismo en frecuencia [%] | I16: Nombre | Operador | Estado | Fecha de puesta en operación FPO | Modo de operación | Punto de conexión o barra del STR/STN | Tipo de proceso productivo | Unidades equivalentes eólica | Voltaje de conexión [kV] | Potencia nominal [MW] | Potencia máxima [MW] | Mínimo técnico [MW] | Capacidad efectiva neta [MW] | Arranque autónomo [Si/No] | Estatismo en frecuencia [%] | Estatismo en frecuencia mínimo [%] | Estatismo en frecuencia máximo [%] | Estatismo en tensión [%] | Banda muerta de operación [mHz] | Rango banda muerta de operación [mHz] | Capacidad de absorción [MVAr] | Capacidad de generación [MVAr] | Constante K | Tiempo de respuesta inicial del control rápido de corriente reactiva [ms] | Tiempo de respuesta inicial máximo-frecuencia [s] | Tiempo de establecimiento máximo-frecuencia [s] | Tiempo de respuesta inicial de tensión [s] | Tiempo de establecimiento de tensión [s] | Velocidad de toma de carga [MW/min] | Velocidad de descarga [MW/min] | Departamento | Municipio | Subárea | J16: 5
A17: 01_Data\01_Raw\PARATEC\GENERACION\EOLICA\PARATEC_Peólica_14-08-2026.xlsx | B17: Peólica | C17: 6 | D17: 3 | E17: 2000 | F17: 33 | G17: 16 | H17: Estatismo en frecuencia mínimo [%] | I17: Nombre | Operador | Estado | Fecha de puesta en operación FPO | Modo de operación | Punto de conexión o barra del STR/STN | Tipo de proceso productivo | Unidades equivalentes eólica | Voltaje de conexión [kV] | Potencia nominal [MW] | Potencia máxima [MW] | Mínimo técnico [MW] | Capacidad efectiva neta [MW] | Arranque autónomo [Si/No] | Estatismo en frecuencia [%] | Estatismo en frecuencia mínimo [%] | Estatismo en frecuencia máximo [%] | Estatismo en tensión [%] | Banda muerta de operación [mHz] | Rango banda muerta de operación [mHz] | Capacidad de absorción [MVAr] | Capacidad de generación [MVAr] | Constante K | Tiempo de respuesta inicial del control rápido de corriente reactiva [ms] | Tiempo de respuesta inicial máximo-frecuencia [s] | Tiempo de establecimiento máximo-frecuencia [s] | Tiempo de respuesta inicial de tensión [s] | Tiempo de establecimiento de tensión [s] | Velocidad de toma de carga [MW/min] | Velocidad de descarga [MW/min] | Departamento | Municipio | Subárea | J17: 2
A18: 01_Data\01_Raw\PARATEC\GENERACION\EOLICA\PARATEC_Peólica_14-08-2026.xlsx | B18: Peólica | C18: 6 | D18: 3 | E18: 2000 | F18: 33 | G18: 17 | H18: Estatismo en frecuencia máximo [%] | I18: Nombre | Operador | Estado | Fecha de puesta en operación FPO | Modo de operación | Punto de conexión o barra del STR/STN | Tipo de proceso productivo | Unidades equivalentes eólica | Voltaje de conexión [kV] | Potencia nominal [MW] | Potencia máxima [MW] | Mínimo técnico [MW] | Capacidad efectiva neta [MW] | Arranque autónomo [Si/No] | Estatismo en frecuencia [%] | Estatismo en frecuencia mínimo [%] | Estatismo en frecuencia máximo [%] | Estatismo en tensión [%] | Banda muerta de operación [mHz] | Rango banda muerta de operación [mHz] | Capacidad de absorción [MVAr] | Capacidad de generación [MVAr] | Constante K | Tiempo de respuesta inicial del control rápido de corriente reactiva [ms] | Tiempo de respuesta inicial máximo-frecuencia [s] | Tiempo de establecimiento máximo-frecuencia [s] | Tiempo de respuesta inicial de tensión [s] | Tiempo de establecimiento de tensión [s] | Velocidad de toma de carga [MW/min] | Velocidad de descarga [MW/min] | Departamento | Municipio | Subárea | J18: 6
A19: 01_Data\01_Raw\PARATEC\GENERACION\EOLICA\PARATEC_Peólica_14-08-2026.xlsx | B19: Peólica | C19: 6 | D19: 3 | E19: 2000 | F19: 33 | G19: 18 | H19: Estatismo en tensión [%] | I19: Nombre | Operador | Estado | Fecha de puesta en operación FPO | Modo de operación | Punto de conexión o barra del STR/STN | Tipo de proceso productivo | Unidades equivalentes eólica | Voltaje de conexión [kV] | Potencia nominal [MW] | Potencia máxima [MW] | Mínimo técnico [MW] | Capacidad efectiva neta [MW] | Arranque autónomo [Si/No] | Estatismo en frecuencia [%] | Estatismo en frecuencia mínimo [%] | Estatismo en frecuencia máximo [%] | Estatismo en tensión [%] | Banda muerta de operación [mHz] | Rango banda muerta de operación [mHz] | Capacidad de absorción [MVAr] | Capacidad de generación [MVAr] | Constante K | Tiempo de respuesta inicial del control rápido de corriente reactiva [ms] | Tiempo de respuesta inicial máximo-frecuencia [s] | Tiempo de establecimiento máximo-frecuencia [s] | Tiempo de respuesta inicial de tensión [s] | Tiempo de establecimiento de tensión [s] | Velocidad de toma de carga [MW/min] | Velocidad de descarga [MW/min] | Departamento | Municipio | Subárea | J19: 5
A20: 01_Data\01_Raw\PARATEC\GENERACION\EOLICA\PARATEC_Peólica_14-08-2026.xlsx | B20: Peólica | C20: 6 | D20: 3 | E20: 2000 | F20: 33 | G20: 19 | H20: Banda muerta de operación [mHz] | I20: Nombre | Operador | Estado | Fecha de puesta en operación FPO | Modo de operación | Punto de conexión o barra del STR/STN | Tipo de proceso productivo | Unidades equivalentes eólica | Voltaje de conexión [kV] | Potencia nominal [MW] | Potencia máxima [MW] | Mínimo técnico [MW] | Capacidad efectiva neta [MW] | Arranque autónomo [Si/No] | Estatismo en frecuencia [%] | Estatismo en frecuencia mínimo [%] | Estatismo en frecuencia máximo [%] | Estatismo en tensión [%] | Banda muerta de operación [mHz] | Rango banda muerta de operación [mHz] | Capacidad de absorción [MVAr] | Capacidad de generación [MVAr] | Constante K | Tiempo de respuesta inicial del control rápido de corriente reactiva [ms] | Tiempo de respuesta inicial máximo-frecuencia [s] | Tiempo de establecimiento máximo-frecuencia [s] | Tiempo de respuesta inicial de tensión [s] | Tiempo de establecimiento de tensión [s] | Velocidad de toma de carga [MW/min] | Velocidad de descarga [MW/min] | Departamento | Municipio | Subárea | J20: 30
A21: 01_Data\01_Raw\PARATEC\GENERACION\EOLICA\PARATEC_Peólica_14-08-2026.xlsx | B21: Peólica | C21: 6 | D21: 3 | E21: 2000 | F21: 33 | G21: 20 | H21: Rango banda muerta de operación [mHz] | I21: Nombre | Operador | Estado | Fecha de puesta en operación FPO | Modo de operación | Punto de conexión o barra del STR/STN | Tipo de proceso productivo | Unidades equivalentes eólica | Voltaje de conexión [kV] | Potencia nominal [MW] | Potencia máxima [MW] | Mínimo técnico [MW] | Capacidad efectiva neta [MW] | Arranque autónomo [Si/No] | Estatismo en frecuencia [%] | Estatismo en frecuencia mínimo [%] | Estatismo en frecuencia máximo [%] | Estatismo en tensión [%] | Banda muerta de operación [mHz] | Rango banda muerta de operación [mHz] | Capacidad de absorción [MVAr] | Capacidad de generación [MVAr] | Constante K | Tiempo de respuesta inicial del control rápido de corriente reactiva [ms] | Tiempo de respuesta inicial máximo-frecuencia [s] | Tiempo de establecimiento máximo-frecuencia [s] | Tiempo de respuesta inicial de tensión [s] | Tiempo de establecimiento de tensión [s] | Velocidad de toma de carga [MW/min] | Velocidad de descarga [MW/min] | Departamento | Municipio | Subárea | J21: 120
A22: 01_Data\01_Raw\PARATEC\GENERACION\EOLICA\PARATEC_Peólica_14-08-2026.xlsx | B22: Peólica | C22: 6 | D22: 3 | E22: 2000 | F22: 33 | G22: 21 | H22: Capacidad de absorción [MVAr] | I22: Nombre | Operador | Estado | Fecha de puesta en operación FPO | Modo de operación | Punto de conexión o barra del STR/STN | Tipo de proceso productivo | Unidades equivalentes eólica | Voltaje de conexión [kV] | Potencia nominal [MW] | Potencia máxima [MW] | Mínimo técnico [MW] | Capacidad efectiva neta [MW] | Arranque autónomo [Si/No] | Estatismo en frecuencia [%] | Estatismo en frecuencia mínimo [%] | Estatismo en frecuencia máximo [%] | Estatismo en tensión [%] | Banda muerta de operación [mHz] | Rango banda muerta de operación [mHz] | Capacidad de absorción [MVAr] | Capacidad de generación [MVAr] | Constante K | Tiempo de respuesta inicial del control rápido de corriente reactiva [ms] | Tiempo de respuesta inicial máximo-frecuencia [s] | Tiempo de establecimiento máximo-frecuencia [s] | Tiempo de respuesta inicial de tensión [s] | Tiempo de establecimiento de tensión [s] | Velocidad de toma de carga [MW/min] | Velocidad de descarga [MW/min] | Departamento | Municipio | Subárea | J22: 3,003 | K22: 6,6 | L22: 4,55
A23: 01_Data\01_Raw\PARATEC\GENERACION\EOLICA\PARATEC_Peólica_14-08-2026.xlsx | B23: Peólica | C23: 6 | D23: 3 | E23: 2000 | F23: 33 | G23: 22 | H23: Capacidad de generación [MVAr] | I23: Nombre | Operador | Estado | Fecha de puesta en operación FPO | Modo de operación | Punto de conexión o barra del STR/STN | Tipo de proceso productivo | Unidades equivalentes eólica | Voltaje de conexión [kV] | Potencia nominal [MW] | Potencia máxima [MW] | Mínimo técnico [MW] | Capacidad efectiva neta [MW] | Arranque autónomo [Si/No] | Estatismo en frecuencia [%] | Estatismo en frecuencia mínimo [%] | Estatismo en frecuencia máximo [%] | Estatismo en tensión [%] | Banda muerta de operación [mHz] | Rango banda muerta de operación [mHz] | Capacidad de absorción [MVAr] | Capacidad de generación [MVAr] | Constante K | Tiempo de respuesta inicial del control rápido de corriente reactiva [ms] | Tiempo de respuesta inicial máximo-frecuencia [s] | Tiempo de establecimiento máximo-frecuencia [s] | Tiempo de respuesta inicial de tensión [s] | Tiempo de establecimiento de tensión [s] | Velocidad de toma de carga [MW/min] | Velocidad de descarga [MW/min] | Departamento | Municipio | Subárea | J23: 3,003 | K23: 6,6 | L23: 4,55
A24: 01_Data\01_Raw\PARATEC\GENERACION\EOLICA\PARATEC_Peólica_14-08-2026.xlsx | B24: Peólica | C24: 6 | D24: 3 | E24: 2000 | F24: 33 | G24: 23 | H24: Constante K | I24: Nombre | Operador | Estado | Fecha de puesta en operación FPO | Modo de operación | Punto de conexión o barra del STR/STN | Tipo de proceso productivo | Unidades equivalentes eólica | Voltaje de conexión [kV] | Potencia nominal [MW] | Potencia máxima [MW] | Mínimo técnico [MW] | Capacidad efectiva neta [MW] | Arranque autónomo [Si/No] | Estatismo en frecuencia [%] | Estatismo en frecuencia mínimo [%] | Estatismo en frecuencia máximo [%] | Estatismo en tensión [%] | Banda muerta de operación [mHz] | Rango banda muerta de operación [mHz] | Capacidad de absorción [MVAr] | Capacidad de generación [MVAr] | Constante K | Tiempo de respuesta inicial del control rápido de corriente reactiva [ms] | Tiempo de respuesta inicial máximo-frecuencia [s] | Tiempo de establecimiento máximo-frecuencia [s] | Tiempo de respuesta inicial de tensión [s] | Tiempo de establecimiento de tensión [s] | Velocidad de toma de carga [MW/min] | Velocidad de descarga [MW/min] | Departamento | Municipio | Subárea | J24: 2 | K24: 4
A25: 01_Data\01_Raw\PARATEC\GENERACION\EOLICA\PARATEC_Peólica_14-08-2026.xlsx | B25: Peólica | C25: 6 | D25: 3 | E25: 2000 | F25: 33 | G25: 24 | H25: Tiempo de respuesta inicial del control rápido de corriente reactiva [ms] | I25: Nombre | Operador | Estado | Fecha de puesta en operación FPO | Modo de operación | Punto de conexión o barra del STR/STN | Tipo de proceso productivo | Unidades equivalentes eólica | Voltaje de conexión [kV] | Potencia nominal [MW] | Potencia máxima [MW] | Mínimo técnico [MW] | Capacidad efectiva neta [MW] | Arranque autónomo [Si/No] | Estatismo en frecuencia [%] | Estatismo en frecuencia mínimo [%] | Estatismo en frecuencia máximo [%] | Estatismo en tensión [%] | Banda muerta de operación [mHz] | Rango banda muerta de operación [mHz] | Capacidad de absorción [MVAr] | Capacidad de generación [MVAr] | Constante K | Tiempo de respuesta inicial del control rápido de corriente reactiva [ms] | Tiempo de respuesta inicial máximo-frecuencia [s] | Tiempo de establecimiento máximo-frecuencia [s] | Tiempo de respuesta inicial de tensión [s] | Tiempo de establecimiento de tensión [s] | Velocidad de toma de carga [MW/min] | Velocidad de descarga [MW/min] | Departamento | Municipio | Subárea | J25: 50
A26: 01_Data\01_Raw\PARATEC\GENERACION\EOLICA\PARATEC_Peólica_14-08-2026.xlsx | B26: Peólica | C26: 6 | D26: 3 | E26: 2000 | F26: 33 | G26: 25 | H26: Tiempo de respuesta inicial máximo-frecuencia [s] | I26: Nombre | Operador | Estado | Fecha de puesta en operación FPO | Modo de operación | Punto de conexión o barra del STR/STN | Tipo de proceso productivo | Unidades equivalentes eólica | Voltaje de conexión [kV] | Potencia nominal [MW] | Potencia máxima [MW] | Mínimo técnico [MW] | Capacidad efectiva neta [MW] | Arranque autónomo [Si/No] | Estatismo en frecuencia [%] | Estatismo en frecuencia mínimo [%] | Estatismo en frecuencia máximo [%] | Estatismo en tensión [%] | Banda muerta de operación [mHz] | Rango banda muerta de operación [mHz] | Capacidad de absorción [MVAr] | Capacidad de generación [MVAr] | Constante K | Tiempo de respuesta inicial del control rápido de corriente reactiva [ms] | Tiempo de respuesta inicial máximo-frecuencia [s] | Tiempo de establecimiento máximo-frecuencia [s] | Tiempo de respuesta inicial de tensión [s] | Tiempo de establecimiento de tensión [s] | Velocidad de toma de carga [MW/min] | Velocidad de descarga [MW/min] | Departamento | Municipio | Subárea | J26: 2
A27: 01_Data\01_Raw\PARATEC\GENERACION\EOLICA\PARATEC_Peólica_14-08-2026.xlsx | B27: Peólica | C27: 6 | D27: 3 | E27: 2000 | F27: 33 | G27: 26 | H27: Tiempo de establecimiento máximo-frecuencia [s] | I27: Nombre | Operador | Estado | Fecha de puesta en operación FPO | Modo de operación | Punto de conexión o barra del STR/STN | Tipo de proceso productivo | Unidades equivalentes eólica | Voltaje de conexión [kV] | Potencia nominal [MW] | Potencia máxima [MW] | Mínimo técnico [MW] | Capacidad efectiva neta [MW] | Arranque autónomo [Si/No] | Estatismo en frecuencia [%] | Estatismo en frecuencia mínimo [%] | Estatismo en frecuencia máximo [%] | Estatismo en tensión [%] | Banda muerta de operación [mHz] | Rango banda muerta de operación [mHz] | Capacidad de absorción [MVAr] | Capacidad de generación [MVAr] | Constante K | Tiempo de respuesta inicial del control rápido de corriente reactiva [ms] | Tiempo de respuesta inicial máximo-frecuencia [s] | Tiempo de establecimiento máximo-frecuencia [s] | Tiempo de respuesta inicial de tensión [s] | Tiempo de establecimiento de tensión [s] | Velocidad de toma de carga [MW/min] | Velocidad de descarga [MW/min] | Departamento | Municipio | Subárea | J27: 15
A28: 01_Data\01_Raw\PARATEC\GENERACION\EOLICA\PARATEC_Peólica_14-08-2026.xlsx | B28: Peólica | C28: 6 | D28: 3 | E28: 2000 | F28: 33 | G28: 27 | H28: Tiempo de respuesta inicial de tensión [s] | I28: Nombre | Operador | Estado | Fecha de puesta en operación FPO | Modo de operación | Punto de conexión o barra del STR/STN | Tipo de proceso productivo | Unidades equivalentes eólica | Voltaje de conexión [kV] | Potencia nominal [MW] | Potencia máxima [MW] | Mínimo técnico [MW] | Capacidad efectiva neta [MW] | Arranque autónomo [Si/No] | Estatismo en frecuencia [%] | Estatismo en frecuencia mínimo [%] | Estatismo en frecuencia máximo [%] | Estatismo en tensión [%] | Banda muerta de operación [mHz] | Rango banda muerta de operación [mHz] | Capacidad de absorción [MVAr] | Capacidad de generación [MVAr] | Constante K | Tiempo de respuesta inicial del control rápido de corriente reactiva [ms] | Tiempo de respuesta inicial máximo-frecuencia [s] | Tiempo de establecimiento máximo-frecuencia [s] | Tiempo de respuesta inicial de tensión [s] | Tiempo de establecimiento de tensión [s] | Velocidad de toma de carga [MW/min] | Velocidad de descarga [MW/min] | Departamento | Municipio | Subárea | J28: 2
A29: 01_Data\01_Raw\PARATEC\GENERACION\EOLICA\PARATEC_Peólica_14-08-2026.xlsx | B29: Peólica | C29: 6 | D29: 3 | E29: 2000 | F29: 33 | G29: 28 | H29: Tiempo de establecimiento de tensión [s] | I29: Nombre | Operador | Estado | Fecha de puesta en operación FPO | Modo de operación | Punto de conexión o barra del STR/STN | Tipo de proceso productivo | Unidades equivalentes eólica | Voltaje de conexión [kV] | Potencia nominal [MW] | Potencia máxima [MW] | Mínimo técnico [MW] | Capacidad efectiva neta [MW] | Arranque autónomo [Si/No] | Estatismo en frecuencia [%] | Estatismo en frecuencia mínimo [%] | Estatismo en frecuencia máximo [%] | Estatismo en tensión [%] | Banda muerta de operación [mHz] | Rango banda muerta de operación [mHz] | Capacidad de absorción [MVAr] | Capacidad de generación [MVAr] | Constante K | Tiempo de respuesta inicial del control rápido de corriente reactiva [ms] | Tiempo de respuesta inicial máximo-frecuencia [s] | Tiempo de establecimiento máximo-frecuencia [s] | Tiempo de respuesta inicial de tensión [s] | Tiempo de establecimiento de tensión [s] | Velocidad de toma de carga [MW/min] | Velocidad de descarga [MW/min] | Departamento | Municipio | Subárea | J29: 10 | K29: 5
A30: 01_Data\01_Raw\PARATEC\GENERACION\EOLICA\PARATEC_Peólica_14-08-2026.xlsx | B30: Peólica | C30: 6 | D30: 3 | E30: 2000 | F30: 33 | G30: 29 | H30: Velocidad de toma de carga [MW/min] | I30: Nombre | Operador | Estado | Fecha de puesta en operación FPO | Modo de operación | Punto de conexión o barra del STR/STN | Tipo de proceso productivo | Unidades equivalentes eólica | Voltaje de conexión [kV] | Potencia nominal [MW] | Potencia máxima [MW] | Mínimo técnico [MW] | Capacidad efectiva neta [MW] | Arranque autónomo [Si/No] | Estatismo en frecuencia [%] | Estatismo en frecuencia mínimo [%] | Estatismo en frecuencia máximo [%] | Estatismo en tensión [%] | Banda muerta de operación [mHz] | Rango banda muerta de operación [mHz] | Capacidad de absorción [MVAr] | Capacidad de generación [MVAr] | Constante K | Tiempo de respuesta inicial del control rápido de corriente reactiva [ms] | Tiempo de respuesta inicial máximo-frecuencia [s] | Tiempo de establecimiento máximo-frecuencia [s] | Tiempo de respuesta inicial de tensión [s] | Tiempo de establecimiento de tensión [s] | Velocidad de toma de carga [MW/min] | Velocidad de descarga [MW/min] | Departamento | Municipio | Subárea | J30: 1,27 | K30: 12 | L30: 1,38
A31: 01_Data\01_Raw\PARATEC\GENERACION\EOLICA\PARATEC_Peólica_14-08-2026.xlsx | B31: Peólica | C31: 6 | D31: 3 | E31: 2000 | F31: 33 | G31: 30 | H31: Velocidad de descarga [MW/min] | I31: Nombre | Operador | Estado | Fecha de puesta en operación FPO | Modo de operación | Punto de conexión o barra del STR/STN | Tipo de proceso productivo | Unidades equivalentes eólica | Voltaje de conexión [kV] | Potencia nominal [MW] | Potencia máxima [MW] | Mínimo técnico [MW] | Capacidad efectiva neta [MW] | Arranque autónomo [Si/No] | Estatismo en frecuencia [%] | Estatismo en frecuencia mínimo [%] | Estatismo en frecuencia máximo [%] | Estatismo en tensión [%] | Banda muerta de operación [mHz] | Rango banda muerta de operación [mHz] | Capacidad de absorción [MVAr] | Capacidad de generación [MVAr] | Constante K | Tiempo de respuesta inicial del control rápido de corriente reactiva [ms] | Tiempo de respuesta inicial máximo-frecuencia [s] | Tiempo de establecimiento máximo-frecuencia [s] | Tiempo de respuesta inicial de tensión [s] | Tiempo de establecimiento de tensión [s] | Velocidad de toma de carga [MW/min] | Velocidad de descarga [MW/min] | Departamento | Municipio | Subárea | J31: 1,27 | K31: 12 | L31: 1,38
A32: 01_Data\01_Raw\PARATEC\GENERACION\EOLICA\PARATEC_Peólica_14-08-2026.xlsx | B32: Peólica | C32: 6 | D32: 3 | E32: 2000 | F32: 33 | G32: 31 | H32: Departamento | I32: Nombre | Operador | Estado | Fecha de puesta en operación FPO | Modo de operación | Punto de conexión o barra del STR/STN | Tipo de proceso productivo | Unidades equivalentes eólica | Voltaje de conexión [kV] | Potencia nominal [MW] | Potencia máxima [MW] | Mínimo técnico [MW] | Capacidad efectiva neta [MW] | Arranque autónomo [Si/No] | Estatismo en frecuencia [%] | Estatismo en frecuencia mínimo [%] | Estatismo en frecuencia máximo [%] | Estatismo en tensión [%] | Banda muerta de operación [mHz] | Rango banda muerta de operación [mHz] | Capacidad de absorción [MVAr] | Capacidad de generación [MVAr] | Constante K | Tiempo de respuesta inicial del control rápido de corriente reactiva [ms] | Tiempo de respuesta inicial máximo-frecuencia [s] | Tiempo de establecimiento máximo-frecuencia [s] | Tiempo de respuesta inicial de tensión [s] | Tiempo de establecimiento de tensión [s] | Velocidad de toma de carga [MW/min] | Velocidad de descarga [MW/min] | Departamento | Municipio | Subárea | J32: ATLÁNTICO | K32: LA GUAJIRA
A33: 01_Data\01_Raw\PARATEC\GENERACION\EOLICA\PARATEC_Peólica_14-08-2026.xlsx | B33: Peólica | C33: 6 | D33: 3 | E33: 2000 | F33: 33 | G33: 32 | H33: Municipio | I33: Nombre | Operador | Estado | Fecha de puesta en operación FPO | Modo de operación | Punto de conexión o barra del STR/STN | Tipo de proceso productivo | Unidades equivalentes eólica | Voltaje de conexión [kV] | Potencia nominal [MW] | Potencia máxima [MW] | Mínimo técnico [MW] | Capacidad efectiva neta [MW] | Arranque autónomo [Si/No] | Estatismo en frecuencia [%] | Estatismo en frecuencia mínimo [%] | Estatismo en frecuencia máximo [%] | Estatismo en tensión [%] | Banda muerta de operación [mHz] | Rango banda muerta de operación [mHz] | Capacidad de absorción [MVAr] | Capacidad de generación [MVAr] | Constante K | Tiempo de respuesta inicial del control rápido de corriente reactiva [ms] | Tiempo de respuesta inicial máximo-frecuencia [s] | Tiempo de establecimiento máximo-frecuencia [s] | Tiempo de respuesta inicial de tensión [s] | Tiempo de establecimiento de tensión [s] | Velocidad de toma de carga [MW/min] | Velocidad de descarga [MW/min] | Departamento | Municipio | Subárea | J33: JUAN DE ACOSTA | K33: URIBIA
A34: 01_Data\01_Raw\PARATEC\GENERACION\EOLICA\PARATEC_Peólica_14-08-2026.xlsx | B34: Peólica | C34: 6 | D34: 3 | E34: 2000 | F34: 33 | G34: 33 | H34: Subárea | I34: Nombre | Operador | Estado | Fecha de puesta en operación FPO | Modo de operación | Punto de conexión o barra del STR/STN | Tipo de proceso productivo | Unidades equivalentes eólica | Voltaje de conexión [kV] | Potencia nominal [MW] | Potencia máxima [MW] | Mínimo técnico [MW] | Capacidad efectiva neta [MW] | Arranque autónomo [Si/No] | Estatismo en frecuencia [%] | Estatismo en frecuencia mínimo [%] | Estatismo en frecuencia máximo [%] | Estatismo en tensión [%] | Banda muerta de operación [mHz] | Rango banda muerta de operación [mHz] | Capacidad de absorción [MVAr] | Capacidad de generación [MVAr] | Constante K | Tiempo de respuesta inicial del control rápido de corriente reactiva [ms] | Tiempo de respuesta inicial máximo-frecuencia [s] | Tiempo de establecimiento máximo-frecuencia [s] | Tiempo de respuesta inicial de tensión [s] | Tiempo de establecimiento de tensión [s] | Velocidad de toma de carga [MW/min] | Velocidad de descarga [MW/min] | Departamento | Municipio | Subárea | J34: SubArea Atlantico | K34: SubArea GCM
A35: 01_Data\01_Raw\PARATEC\GENERACION\EOLICA\PARATEC_Ueólica_14-08-2026.xlsx | B35: Ueólica | C35: 6 | D35: 3 | E35: 2000 | F35: 35 | G35: 1 | H35: Nombre | I35: Nombre | Operador | Estado | Fecha de puesta en operación FPO | Modo de operación | Punto de conexión | Planta eólica | Voltaje de conexión [kV] | Voltaje máximo [kV] | Voltaje mínimo [kV] | Voltaje nominal [kV] | Frecuencia máxima [Hz] | Frecuencia mínima [Hz] | Número inversores | Impedancia equivalente [Ω] | Potencia de la unidad equivalente [MW] | Tipo de aerogenerador | Altura de buje [m] | Fabricante | Temperatura máxima de operación [°C] | Temperatura mínima de operación [°C] | Modelo | Potencia nominal del inversor AC (Pnom - AC) [MW] | Modelo del inversor | Factor de eficiencia inversor [%] | Coeficiente de derrateo capacidad nominal del inversor por altura [p.u.] | Nivel de corriente de cortocircuito subtransitorio pico [kAp] | Nivel de corriente de cortocircuito subtransitorio para fallas 3F [kA] | Nivel de corriente de cortocircuito subtransitorio para fallas 2F [kA] | Nivel de corriente de cortocircuito subtransitorio para fallas 1F [kA] | Nivel de cortocircuito en estado estable [kA] | Nivel de corriente de cortocircuito de secuencia negativa [kA] | Departamento | Municipio | Subárea | J35: PARQUE EOLICO CARRETO 1 | K35: PARQUE EOLICO GUAJIRA I 1 | L35: PARQUE EOLICO WESP01 1
A36: 01_Data\01_Raw\PARATEC\GENERACION\EOLICA\PARATEC_Ueólica_14-08-2026.xlsx | B36: Ueólica | C36: 6 | D36: 3 | E36: 2000 | F36: 35 | G36: 2 | H36: Operador | I36: Nombre | Operador | Estado | Fecha de puesta en operación FPO | Modo de operación | Punto de conexión | Planta eólica | Voltaje de conexión [kV] | Voltaje máximo [kV] | Voltaje mínimo [kV] | Voltaje nominal [kV] | Frecuencia máxima [Hz] | Frecuencia mínima [Hz] | Número inversores | Impedancia equivalente [Ω] | Potencia de la unidad equivalente [MW] | Tipo de aerogenerador | Altura de buje [m] | Fabricante | Temperatura máxima de operación [°C] | Temperatura mínima de operación [°C] | Modelo | Potencia nominal del inversor AC (Pnom - AC) [MW] | Modelo del inversor | Factor de eficiencia inversor [%] | Coeficiente de derrateo capacidad nominal del inversor por altura [p.u.] | Nivel de corriente de cortocircuito subtransitorio pico [kAp] | Nivel de corriente de cortocircuito subtransitorio para fallas 3F [kA] | Nivel de corriente de cortocircuito subtransitorio para fallas 2F [kA] | Nivel de corriente de cortocircuito subtransitorio para fallas 1F [kA] | Nivel de cortocircuito en estado estable [kA] | Nivel de corriente de cortocircuito de secuencia negativa [kA] | Departamento | Municipio | Subárea | J36: CELSIA COLOMBIA S.A. E.S.P. | K36: ISAGEN S.A. E.S.P.
A37: 01_Data\01_Raw\PARATEC\GENERACION\EOLICA\PARATEC_Ueólica_14-08-2026.xlsx | B37: Ueólica | C37: 6 | D37: 3 | E37: 2000 | F37: 35 | G37: 3 | H37: Estado | I37: Nombre | Operador | Estado | Fecha de puesta en operación FPO | Modo de operación | Punto de conexión | Planta eólica | Voltaje de conexión [kV] | Voltaje máximo [kV] | Voltaje mínimo [kV] | Voltaje nominal [kV] | Frecuencia máxima [Hz] | Frecuencia mínima [Hz] | Número inversores | Impedancia equivalente [Ω] | Potencia de la unidad equivalente [MW] | Tipo de aerogenerador | Altura de buje [m] | Fabricante | Temperatura máxima de operación [°C] | Temperatura mínima de operación [°C] | Modelo | Potencia nominal del inversor AC (Pnom - AC) [MW] | Modelo del inversor | Factor de eficiencia inversor [%] | Coeficiente de derrateo capacidad nominal del inversor por altura [p.u.] | Nivel de corriente de cortocircuito subtransitorio pico [kAp] | Nivel de corriente de cortocircuito subtransitorio para fallas 3F [kA] | Nivel de corriente de cortocircuito subtransitorio para fallas 2F [kA] | Nivel de corriente de cortocircuito subtransitorio para fallas 1F [kA] | Nivel de cortocircuito en estado estable [kA] | Nivel de corriente de cortocircuito de secuencia negativa [kA] | Departamento | Municipio | Subárea | J37: Pruebas
A38: 01_Data\01_Raw\PARATEC\GENERACION\EOLICA\PARATEC_Ueólica_14-08-2026.xlsx | B38: Ueólica | C38: 6 | D38: 3 | E38: 2000 | F38: 35 | G38: 4 | H38: Fecha de puesta en operación FPO | I38: Nombre | Operador | Estado | Fecha de puesta en operación FPO | Modo de operación | Punto de conexión | Planta eólica | Voltaje de conexión [kV] | Voltaje máximo [kV] | Voltaje mínimo [kV] | Voltaje nominal [kV] | Frecuencia máxima [Hz] | Frecuencia mínima [Hz] | Número inversores | Impedancia equivalente [Ω] | Potencia de la unidad equivalente [MW] | Tipo de aerogenerador | Altura de buje [m] | Fabricante | Temperatura máxima de operación [°C] | Temperatura mínima de operación [°C] | Modelo | Potencia nominal del inversor AC (Pnom - AC) [MW] | Modelo del inversor | Factor de eficiencia inversor [%] | Coeficiente de derrateo capacidad nominal del inversor por altura [p.u.] | Nivel de corriente de cortocircuito subtransitorio pico [kAp] | Nivel de corriente de cortocircuito subtransitorio para fallas 3F [kA] | Nivel de corriente de cortocircuito subtransitorio para fallas 2F [kA] | Nivel de corriente de cortocircuito subtransitorio para fallas 1F [kA] | Nivel de cortocircuito en estado estable [kA] | Nivel de corriente de cortocircuito de secuencia negativa [kA] | Departamento | Municipio | Subárea | J38: -
A39: 01_Data\01_Raw\PARATEC\GENERACION\EOLICA\PARATEC_Ueólica_14-08-2026.xlsx | B39: Ueólica | C39: 6 | D39: 3 | E39: 2000 | F39: 35 | G39: 5 | H39: Modo de operación | I39: Nombre | Operador | Estado | Fecha de puesta en operación FPO | Modo de operación | Punto de conexión | Planta eólica | Voltaje de conexión [kV] | Voltaje máximo [kV] | Voltaje mínimo [kV] | Voltaje nominal [kV] | Frecuencia máxima [Hz] | Frecuencia mínima [Hz] | Número inversores | Impedancia equivalente [Ω] | Potencia de la unidad equivalente [MW] | Tipo de aerogenerador | Altura de buje [m] | Fabricante | Temperatura máxima de operación [°C] | Temperatura mínima de operación [°C] | Modelo | Potencia nominal del inversor AC (Pnom - AC) [MW] | Modelo del inversor | Factor de eficiencia inversor [%] | Coeficiente de derrateo capacidad nominal del inversor por altura [p.u.] | Nivel de corriente de cortocircuito subtransitorio pico [kAp] | Nivel de corriente de cortocircuito subtransitorio para fallas 3F [kA] | Nivel de corriente de cortocircuito subtransitorio para fallas 2F [kA] | Nivel de corriente de cortocircuito subtransitorio para fallas 1F [kA] | Nivel de cortocircuito en estado estable [kA] | Nivel de corriente de cortocircuito de secuencia negativa [kA] | Departamento | Municipio | Subárea | J39: No Despachada Centralmente
A40: 01_Data\01_Raw\PARATEC\GENERACION\EOLICA\PARATEC_Ueólica_14-08-2026.xlsx | B40: Ueólica | C40: 6 | D40: 3 | E40: 2000 | F40: 35 | G40: 6 | H40: Punto de conexión | I40: Nombre | Operador | Estado | Fecha de puesta en operación FPO | Modo de operación | Punto de conexión | Planta eólica | Voltaje de conexión [kV] | Voltaje máximo [kV] | Voltaje mínimo [kV] | Voltaje nominal [kV] | Frecuencia máxima [Hz] | Frecuencia mínima [Hz] | Número inversores | Impedancia equivalente [Ω] | Potencia de la unidad equivalente [MW] | Tipo de aerogenerador | Altura de buje [m] | Fabricante | Temperatura máxima de operación [°C] | Temperatura mínima de operación [°C] | Modelo | Potencia nominal del inversor AC (Pnom - AC) [MW] | Modelo del inversor | Factor de eficiencia inversor [%] | Coeficiente de derrateo capacidad nominal del inversor por altura [p.u.] | Nivel de corriente de cortocircuito subtransitorio pico [kAp] | Nivel de corriente de cortocircuito subtransitorio para fallas 3F [kA] | Nivel de corriente de cortocircuito subtransitorio para fallas 2F [kA] | Nivel de corriente de cortocircuito subtransitorio para fallas 1F [kA] | Nivel de cortocircuito en estado estable [kA] | Nivel de corriente de cortocircuito de secuencia negativa [kA] | Departamento | Municipio | Subárea | J40: BARANOA 34.5 kV | K40: CUESTECITAS 110 kV | L40: JOUKTAI 110 kV
...

Sheet Generadores
A1: subarea | B1: values_enersource | D1: Tipo | E1: pmax_mw | F1: pmin_mw | G1: pmin_missing | H1: cost_avg_cop_mwh_weighted_pmax | I1: ramp_up_sum_mw_min | J1: ramp_down_sum_mw_min | K1: min_on_max_h | L1: min_off_max_h | M1: n_units | N1: n_resources | O1: offer_codes | P1: resource_names | Q1: representative_date | R1: demand_representative_mw | S1: trm_cop_usd | T1: missing_fields | U1: precoferdesp_diario_por_recurso | V1: cost_avg_usd_mwh
A2: SubArea Antioquia | B2: ACPM | C2: Diésel (aceite combustible para motores) | D2: Térmica | E2: 352 | F2: 220 | G2: FALSE | H2: 1389156 | I2: 49.91 | J2: 103.36 | K2: 8 | L2: 2 | M2: 3 | N2: 1 | O2: TSR1 | P2: TERMOSIERRA CC | Q2: 46209 | R2: 10516.626 | S2: 3334.93 | U2: {"TSR1": 1389156.0} | V2: 416.54727
A3: SubArea Antioquia | B3: AGUA | C3: Hidráulica | D3: Hidráulica | E3: 5483 | F3: 1768.1 | G3: FALSE | H3: 589372.2 | I3: 2727.73 | J3: 3014.89 | M3: 45 | N3: 12 | O3: CLL1, GTPE, GTRG, HMIN, JAGS, LTSJ, PES1, PLYS, PRC2, PRC3, SMI1, SNCR | P3: CARLOS LLERAS, GUATAPE, GUATRON, ESCUELA DE MINAS, JAGUAS, LA TASAJERA, ITUANGO, PLAYAS, PORCE II, PORCE III, SAN MIGUEL, SAN CARLOS | Q3: 46209 | R3: 10516.626 | S3: 3334.93 | U3: {"CLL1": 80000.01000000001, "GTPE": 709000.0, "GTRG": 752000.0, "HMIN": 80000.0, "JAGS": 1070000.0, "LTSJ": 895000.0, "PES1": 87878.01000000001, "PLYS": 90683.0, "PRC2": 710000.0, "PRC3": 900000.0, "SMI1": 89176.01000000001, "SNCR": 755500.0} | V3: 176.72701
A4: SubArea Antioquia | B4: GAS | C4: Gas natural | D4: Térmica | E4: 272 | F4: 110 | G4: FALSE | H4: 1003326 | I4: 13.88 | J4: 13.17 | K4: 6 | L4: 8 | M4: 3 | N4: 1 | O4: TRM1 | P4: TERMOCENTRO CC | Q4: 46209 | R4: 10516.626 | S4: 3334.93 | U4: {"TRM1": 1003326.0} | V4: 300.85369
A5: SubArea Atlantico | B5: GAS | C5: Gas natural | D5: Térmica | E5: 1516 | F5: 726 | G5: FALSE | H5: 914509.51 | I5: 34.3025 | J5: 26.8 | K5: 72 | L5: 72 | M5: 14 | N5: 5 | O5: TBQ3, TBQ4, TBST, TFL1, TFL4 | P5: BARRANQUILLA 3, BARRANQUILLA 4, TEBSAB CC, FLORES I CC, FLORES 4 CC | Q5: 46209 | R5: 10516.626 | S5: 3334.93 | U5: {"TBQ3": 1097684.0, "TBQ4": 1048522.0, "TBST": 750293.0, "TFL1": 1060979.0, "TFL4": 1110979.0} | V5: 274.2215
A6: SubArea Bogota | B6: AGUA | C6: Hidráulica | D6: Hidráulica | E6: 3056 | F6: 433.2 | G6: FALSE | H6: 207492.72 | I6: 1116.59 | J6: 1101.8 | M6: 21 | N6: 6 | O6: 2QEK, CHVR, DVS1, GVIO, PGUG, TUJ1 | P6: SALTO II, CHIVOR, DARIO VALENCIA SAMPER, GUAVIO, PAGUA, TUNJITA | Q6: 46209 | R6: 10516.626 | S6: 3334.93 | U6: {"2QEK": 90855.0, "CHVR": 87878.02, "DVS1": 90854.0, "GVIO": 90853.01, "PGUG": 690000.0, "TUJ1": 87878.0} | V6: 62.218013
A7: SubArea Bogota | B7: CARBON | C7: Carbón | D7: Térmica | E7: 224 | F7: 92 | G7: FALSE | H7: 306049.86 | I7: 3.54 | J7: 3.49 | K7: 72 | L7: 9 | M7: 4 | N7: 4 | O7: ZPA2, ZPA3, ZPA4, ZPA5 | P7: ZIPAEMG 2, ZIPAEMG 3, ZIPAEMG 4, ZIPAEMG 5 | Q7: 46209 | R7: 10516.626 | S7: 3334.93 | U7: {"ZPA2": 325736.0, "ZPA3": 300949.0, "ZPA4": 312370.0, "ZPA5": 294106.0} | V7: 91.771
A8: SubArea Bolivar | B8: COMBUSTOLEO | C8: Fuel oil, residuo pesado | D8: Térmica | E8: 178 | F8: 90 | G8: FALSE | H8: 1422845.3 | I8: 1.48 | J8: 1.48 | K8: 72 | L8: 18 | M8: 3 | N8: 3 | O8: CTG1, CTG2, CTG3 | P8: CARTAGENA 1, CARTAGENA 2, CARTAGENA 3 | Q8: 46209 | R8: 10516.626 | S8: 3334.93 | U8: {"CTG1": 1399863.0, "CTG2": 1398206.0, "CTG3": 1463352.0} | V8: 426.64923
A9: SubArea Bolivar | B9: GAS | C9: Gas natural | D9: Térmica | E9: 645 | F9: 385 | G9: FALSE | H9: 692048.84 | I9: 15.75 | J9: 23.85 | K9: 36 | L9: 15 | M9: 5 | N9: 3 | O9: PRG1, PRG2, TCDT | P9: PROELECTRICA 1, PROELECTRICA 2, TERMOCANDELARIA CC | Q9: 46209 | R9: 10516.626 | S9: 3334.93 | U9: {"PRG1": 901548.0, "PRG2": 901548.0, "TCDT": 658076.0} | V9: 207.51525
A10: SubArea Bolivar | B10: GLP | C10: Gas licuado de petróleo | D10: Térmica | E10: 52 | F10: 38 | G10: FALSE | H10: 880000 | I10: 3.07 | J10: 3.08 | K10: 4 | L10: 2 | M10: 1 | N10: 1 | O10: TCBE | P10: TERMOCARIBE III 1 | Q10: 46209 | R10: 10516.626 | S10: 3334.93 | U10: {"TCBE": 880000.0} | V10: 263.8736
A11: SubArea Boyaca-Casanare | B11: BIOMASA | C11: Bagazo, residuos agrícolas | D11: Térmica | E11: 25 | F11: 17 | G11: FALSE | H11: 237230 | I11: 0.22 | J11: 0.3 | K11: 24 | L11: 12 | M11: 1 | N11: 1 | O11: 4YCN | P11: VILLANUEVA 1 | Q11: 46209 | R11: 10516.626 | S11: 3334.93 | U11: {"4YCN": 237230.0} | V11: 71.134926
A12: SubArea Boyaca-Casanare | B12: CARBON | C12: Carbón | D12: Térmica | E12: 343 | F12: 148 | G12: FALSE | H12: 277718.16 | I12: 1.73 | J12: 3.12 | K12: 24 | L12: 18 | M12: 4 | N12: 4 | O12: PPA1, PPA2, PPA3, PPA4 | P12: PAIPA 1, PAIPA 2, PAIPA 3, PAIPA 4 | Q12: 46209 | R12: 10516.626 | S12: 3334.93 | U12: {"PPA1": 286480.0, "PPA2": 262762.0, "PPA3": 273885.0, "PPA4": 283959.0} | V12: 83.275559
A13: SubArea Boyaca-Casanare | B13: GAS | C13: Gas natural | D13: Térmica | E13: 186 | F13: 118 | G13: FALSE | H13: 84100.022 | I13: 42.79 | J13: 43.11 | K13: 12 | L13: 2 | M13: 5 | N13: 5 | O13: TYP1, TYP2, TYP3, TYP4, TYP5 | P13: TERMOYOPAL 1, TERMOYOPAL 2, TERMOYOPAL G3, TERMOYOPAL G4, TERMOYOPAL G5 | Q13: 46209 | R13: 10516.626 | S13: 3334.93 | U13: {"TYP1": 84100.01, "TYP2": 84100.02, "TYP3": 84100.03, "TYP4": 84100.0, "TYP5": 84100.04000000001} | V13: 25.217927
A14: SubArea CQR | B14: AGUA | C14: Hidráulica | D14: Hidráulica | E14: 561 | F14: 96 | G14: FALSE | H14: 789024.42 | I14: 217.69 | J14: 218.33 | M14: 8 | N14: 3 | O14: ESMR, HMLG, SNFR | P14: ESMERALDA, MIEL I, SAN FRANCISCO | Q14: 46209 | R14: 10516.626 | S14: 3334.93 | U14: {"ESMR": 90683.02, "HMLG": 1080000.0, "SNFR": 90683.01} | V14: 236.594
A15: SubArea CQR | B15: JET-A1 | C15: Queroseno de aviación | D15: Térmica | E15: 48 | F15: 10 | G15: FALSE | H15: 2695210 | I15: 5.94 | J15: 5.8 | K15: 1 | L15: 1 | M15: 1 | N15: 1 | O15: TDR1 | P15: TERMODORADA 1 | Q15: 46209 | R15: 10516.626 | S15: 3334.93 | U15: {"TDR1": 2695210.0} | V15: 808.17588
A16: SubArea Cauca-Narino | B16: AGUA | C16: Hidráulica | D16: Hidráulica | E16: 400 | F16: 0 | G16: FALSE | H16: 810000 | I16: 33.81 | J16: 36.02 | M16: 2 | N16: 1 | O16: QUI1 | P16: EL QUIMBO | Q16: 46209 | R16: 10516.626 | S16: 3334.93 | U16: {"QUI1": 810000.0} | V16: 242.88366
A17: SubArea Cerromatoso | B17: CARBON | C17: Carbón | D17: Térmica | E17: 434 | F17: 220 | G17: FALSE | H17: 253749.59 | I17: 2 | J17: 1.38 | K17: 72 | L17: 72 | M17: 2 | N17: 2 | O17: GE32, GEC3 | P17: GECELCA 32, GECELCA 3 | Q17: 46209 | R17: 10516.626 | S17: 3334.93 | U17: {"GE32": 253295.0, "GEC3": 254498.0} | V17: 76.088431
A18: SubArea Cordoba_Sucre | B18: AGUA | C18: Hidráulica | D18: Hidráulica | E18: 338 | F18: 120 | G18: FALSE | H18: 700000 | I18: 155.67 | J18: 165.66 | M18: 4 | N18: 1 | O18: URA1 | P18: URRA | Q18: 46209 | R18: 10516.626 | S18: 3334.93 | U18: {"URA1": 700000.0} | V18: 209.89946
A19: SubArea Cordoba_Sucre | B19: GAS | C19: Gas natural | D19: Térmica | E19: 200 | F19: 88 | G19: FALSE | H19: 1160244 | I19: 23.4 | J19: 29.45 | K19: 3 | L19: 1 | M19: 11 | N19: 1 | O19: 3ENA | P19: TESORITO | Q19: 46209 | R19: 10516.626 | S19: 3334.93 | U19: {"3ENA": 1160244.0} | V19: 347.90655
A20: SubArea GCM | B20: CARBON | C20: Carbón | D20: Térmica | E20: 275 | F20: 144 | G20: FALSE | H20: 682656.55 | I20: 3.28 | J20: 4.26 | K20: 24 | L20: 24 | M20: 2 | N20: 2 | O20: TGJ1, TGJ2 | P20: GUAJIRA 1, GUAJIRA 2 | Q20: 46209 | R20: 10516.626 | S20: 3334.93 | U20: {"TGJ1": 623516.0, "TGJ2": 748621.0} | V20: 204.69891
A21: SubArea GCM | B21: COMBUSTOLEO | C21: Fuel oil, residuo pesado | D21: Térmica | E21: 88 | F21: 52 | G21: FALSE | H21: 1135000 | I21: 0.36 | J21: 0.36 | K21: 4 | L21: 1 | M21: 10 | N21: 1 | O21: TRN1 | P21: TERMONORTE | Q21: 46209 | R21: 10516.626 | S21: 3334.93 | U21: {"TRN1": 1135000.0} | V21: 340.33698
A22: SubArea Huila-Tolima | B22: AGUA | C22: Hidráulica | D22: Hidráulica | E22: 727 | F22: 202.2 | G22: FALSE | H22: 169003.94 | I22: 132.97 | J22: 151.87 | M22: 10 | N22: 4 | O22: CHBG, CUC1, MOY1, PRDO | P22: BETANIA, CUCUANA, AMOYA LA ESPERANZA, PRADO | Q22: 46209 | R22: 10516.626 | S22: 3334.93 | U22: {"CHBG": 90853.0, "CUC1": 95878.0, "MOY1": 89176.0, "PRDO": 1202000.0} | V22: 50.676909
A23: SubArea Norte de Santander | B23: CARBON | C23: Carbón | D23: Térmica | E23: 335 | F23: 134 | G23: FALSE | H23: 228838.21 | I23: 5.57 | J23: 5.57 | K23: 72 | L23: 8 | M23: 2 | N23: 2 | O23: TSJ1, TSJ2 | P23: TASAJERO 1, TASAJERO 2 | Q23: 46209 | R23: 10516.626 | S23: 3334.93 | U23: {"TSJ1": 238480.0, "TSJ2": 219480.0} | V23: 68.618594
A24: SubArea Santander | B24: AGUA | C24: Hidráulica | D24: Hidráulica | E24: 819 | F24: 360 | G24: FALSE | H24: 990000 | I24: 51.05 | J24: 52.43 | M24: 3 | N24: 1 | O24: SOG1 | P24: SOGAMOSO | Q24: 46209 | R24: 10516.626 | S24: 3334.93 | U24: {"SOG1": 990000.0} | V24: 296.85781
A25: SubArea Santander | B25: GAS | C25: Gas natural | D25: Térmica | E25: 164 | F25: 90 | G25: FALSE | H25: 1237860 | I25: 6.02 | J25: 6.01 | K25: 6 | L25: 2 | M25: 1 | N25: 1 | O25: MRL1 | P25: MERILECTRICA 1 | Q25: 46209 | R25: 10516.626 | S25: 3334.93 | U25: {"MRL1": 1237860.0} | V25: 371.1802
A26: SubArea Valle | B26: ACPM | C26: Diésel (aceite combustible para motores) | D26: Térmica | E26: 466 | F26: 200 | G26: FALSE | H26: 1564465.4 | I26: 2 | J26: 8 | K26: 10 | L26: 4 | M26: 4 | N26: 2 | O26: TEC1, TVL1 | P26: TERMOEMCALI CC, TERMOVALLE CC | Q26: 46209 | R26: 10516.626 | S26: 3334.93 | U26: {"TEC1": 1533693.0, "TVL1": 1594199.0} | V26: 469.1149
A27: SubArea Valle | B27: AGUA | C27: Hidráulica | D27: Hidráulica | E27: 874 | F27: 154 | G27: FALSE | H27: 1204337.5 | I27: 378.37 | J27: 388.9 | M27: 9 | N27: 3 | O27: ALBG, CLMG, SLVJ | P27: ALBAN, CALIMA, SALVAJINA | Q27: 46209 | R27: 10516.626 | S27: 3334.93 | U27: {"ALBG": 1205000.0, "CLMG": 1203000.0, "SLVJ": 1204000.0} | V27: 361.12828

Sheet Térmica
A1: Generadores - Unidades termicas
A2: Costo cuadratico c2*P^2+c1*P+c0. min_on/off y cost_su/sd para UC.
A3: id | B3: nodo | C3: Pmin | D3: Pmax | E3: rampa_sub_min | F3: rampa_sub | G3: rampa_baj_min | H3: rampa_baj | I3: c2 | J3: c1 | K3: c0 | L3: u_init | M3: min_on | N3: min_off | O3: Carga_sincronizante_frío | P3: Tiempo_calentamiento_frío | Q3: cost_su | R3: cost_sd | S3: combustible | T3: Planta | U3: codigo | V3: Latitud | W3: Longitud
C4: MW | D4: MW | E4: MW/min | F4: MW/h | G4: MW/min | H4: MW/h | I4: $/MW2 | J4: $/MW | K4: $ | M4: h | N4: h | O4: MW | P4: h | Q4: USD | R4: USD | V4: ° | W4: °
A5: TERMOCENTRO 1 | B5: SubArea Antioquia | C5: 30 | D5: 97 | E5: 5 | F5: =E5*60 -> 300 | G5: 4.99 | H5: =G5*60 -> 299.4 | I5: 0 | K5: 0 | M5: 1 | N5: 0 | O5: 5 | P5: 0 | Q5: =O5*P5*J5 -> 0 | R5: 0 | S5: Gas | T5: TERMOCENTRO CC | U5: =_xlfn.XLOOKUP(T5,Detalle_Unidades!F2:F548,Detalle_Unidades!A2:A548) -> TRM1
A6: TERMOCENTRO 2 | B6: SubArea Antioquia | C6: 40 | D6: 80 | E6: 5 | F6: =E6*60 -> 300 | G6: 5.07 | H6: =G6*60 -> 304.2 | I6: 0 | K6: 0 | M6: 6 | N6: 6 | O6: 5 | P6: 2 | Q6: =O6*P6*J6 -> 0 | R6: 0 | S6: ACPM | T6: TERMOCENTRO CC | U6: =_xlfn.XLOOKUP(T6,Detalle_Unidades!F3:F549,Detalle_Unidades!A3:A549) -> TRM1
A7: TERMOCENTRO 3 | B7: SubArea Antioquia | C7: 30 | D7: 77 | E7: 3.88 | F7: =E7*60 -> 232.8 | G7: 3.11 | H7: =G7*60 -> 186.6 | I7: 0 | K7: 0 | M7: 10 | N7: 8 | O7: 5 | P7: 4 | Q7: =O7*P7*J7 -> 0 | R7: 0 | S7: ACPM | T7: TERMOCENTRO CC | U7: =_xlfn.XLOOKUP(T7,Detalle_Unidades!F4:F550,Detalle_Unidades!A4:A550) -> TRM1
A8: TERMOSIERRA 1 | B8: SubArea Antioquia | C8: 89 | D8: 110 | E8: 42.41 | F8: =E8*60 -> 2544.6 | G8: 41.41 | H8: =G8*60 -> 2484.6 | I8: 0 | K8: 0 | M8: 8 | N8: 1 | O8: 12 | P8: 2 | Q8: =O8*P8*J8 -> 0 | R8: 0 | S8: ACPM | T8: TERMOSIERRA CC | U8: =_xlfn.XLOOKUP(T8,Detalle_Unidades!F5:F551,Detalle_Unidades!A5:A551) -> TSR1
