Workbook

Sheet INSTRUCCIONES
A1: Plantilla de datos - Modelo TEP con BESS y FACTS | C1: Fuentes y trazabilidad
A2: Hoja auxiliar. data_loader no la lee. | C2: Hoja auxiliar. data_loader no la lee.
C3: dato | D3: archivo_de_origen | E3: Comentarios
A4: Esta plantilla define un CASO de estudio. Un archivo = un caso. | C4: Nodos | D4: \01_Data\02_Processed\Datos_hojas_excel_COL\18_nodos\01_Nodos_Lineas | E4: STN es tensión nominal mayor o igual a 220 kV
A5: Cada hoja corresponde a un tipo de dato. Llene solo las que aplican; | C5: nodos | D5: PARATEC_Subestaciones.xlsx
A6: las hojas vacias se interpretan como 'ese componente no existe'. | C6: Lineas | D6: \01_Data\02_Processed\Datos_hojas_excel_COL\18_nodos\01_Nodos_Lineas
C7: desde / hasta | D7: PARATEC_Líneas.xlsx
A8: HOJAS: | C8: R, X | D8: PARATEC_Líneas.xlsx
A9: Config -> parametros globales (S_base, horizonte, etc.) | C9: capacidad línea | D9: PARATEC_Líneas.xlsx | E9: Se pasa a MWA a partir de la corriente nominal
A10: Nodos -> buses del sistema (id, tipo, demanda base) | C10: Generadores | D10: \01_Data\02_Processed\Datos_hojas_excel_COL\18_nodos\02_Generadores
A11: Lineas -> lineas existentes (R, X, capacidad) | C11: id | D11: PARATEC_Utérmica.xlsx -> InfoCombustible | E11: Filtros de Modo de operación "Desapacho centralmente" y Estado "Operación"
A12: Generadores -> unidades termicas (limites, costos, rampas) | C12: Pmin/Pmax | D12: PARATEC_Utérmica.xlsx -> InfoCombustible
A13: Hidraulicos -> unidades hidraulicas y embalses (opcional) | C13: rampa_sub | D13: PARATEC_Utérmica.xlsx -> VelCarga-Descarga
A14: Aportes -> xxxx | C14: rampa_baj | D14: PARATEC_Utérmica.xlsx -> VelCarga-Descarga
A15: Renovables -> solar/eolica (opcional) | C15: costo | D15: PrecOferDesp_Jul26.xlsx
A16: Renov_Perfil -> xxxxx | C16: u_init | D16: Gene.xlsx
A17: BESS_Cand -> nodos candidatos a instalar BESS | C17: min_on | D17: PARATEC_Utérmica.xlsx -> InfoCombustible
A18: FACTS_Cand -> lineas candidatas a instalar TCSC | C18: min_off | D18: PARATEC_Utérmica.xlsx -> InfoCombustible
A19: Demanda -> perfil horario {hora x nodo} (como XM/Alvaro) | C19: cost_su | D19: PARATEC_Utérmica.xlsx -> InfoCombustible
C20: cost_sd | D20: no disponible en la fuente | E20: Se establece en cero
A21: CONVENCION DE COLOR: | C21: combustible | D21: PARATEC_Utérmica.xlsx -> InfoCombustible
A22: Encabezado fondo azul y letras blancas = dato leído por el código | C22: planta | D22: PARATEC_Ptérmica.xlsx -> Ptérmica
A23: Encabezado fondo rojo y letras blancas = dato no leído por el código | C23: Hidraulicos | D23: \01_Data\02_Processed\Datos_hojas_excel_COL\18_nodos\03_Hidraulicos | E23: Filtros de Modo de operación "Desapacho centralmente" y Estado "Operación"
A24: Texto azul = dato de entrada (lo edita el usuario). | C24: id | D24: PARATEC_Detalle_Embalse.xlsx -> Información_Técnica e Información_Básica / PARATEC_Phidráulica.xlsx / PARATEC_Chidraulicas.xlsx | E24: Embalse
C25: Pmin | D25: no disponible en la fuente | E25: Se establece en cero
A26: NODO SLACK: en la hoja Nodos, marque tipo=slack en un unico nodo. | C26: Pmax | D26: Capacidadefectiva.xlsx
A27: UNIDADES: indicadas en la fila bajo cada encabezado. (No borrarlas ni modificarlas) | C27: qmin | D27: Pmin / eta
C28: qmax | D28: Pmáx / eta
C29: eta | D29: PARATEC_Phidráulica.xlsx -> Phidráulica
C30: Vmin | D30: PARATEC_Detalle_Embalse.xlsx -> Información_Técnica | E30: Se establece en cero para las filo de agua y las que comparten cadena hidrico (ALBAN;GUATRON; PAGUA)
C31: Vmax | D31: PARATEC_Detalle_Embalse.xlsx -> Información_Técnica | E31: Se establece en cero para las filo de agua y las que comparten cadena hidrico (ALBAN;GUATRON; PAGUA)
C32: Vinit | D32: VoluUtilDiarMasa_Jul26.xlsx/CapaUtilDiarMasa_Jul26.xlsx
C33: Smax | D33: no disponible en la fuente
C34: costo | D34: PrecOferDesp_Jul26.xlsx
C35: Pmin_PARATEC | D35: PARATEC_Uhidráulica.xlsx -> Uhidráulica
C36: clasificación | D36: PARATEC_Phidráulica.xlsx -> Phidráulica
C37: Aportes | D37: /01_Data/02_Processed/Datos_hojas_excel_COL/18_nodos/04_Aportes -> AporCaudal_Jul26.xlsx | E37: Aporte de embalses; filo de agua no aplica
C38: Renovables | D38: /01_Data/02_Processed/Datos_hojas_excel_COL/18_nodos/05_Renovables
C39: id | D39: Capacidadefectiva.xlsx
C40: tipo | D40: Capacidadefectiva.xlsx
...

Sheet Config
A1: Config - Parametros globales del caso
A2: Parametros generales que aplican a todo el sistema.
A4: parametro | B4: valor | C4: descripcion
A6: S_base | B6: 100 | C6: Potencia base del sistema (MVA)
A7: horizonte | B7: 24 | C7: Numero de horas a simular
A8: n_seg_costo | B8: 3 | C8: Segmentos linealizacion costo termico
A9: n_seg_perdidas | B9: 4 | C9: Segmentos linealizacion perdidas
A10: mip_gap | B10: 0.005 | C10: Tolerancia de optimalidad del solver
A11: time_limit | B11: 0 | C11: Limite de tiempo del solver (s)
A12: vida_bess | B12: 15 | C12: años NREL
A13: vida_facts | B13: 20 | C13: años
A14: incluir_perdidas | B14: 1 | C14: 0 (sin pérdidas - validación DC); 1(con pérdidas)
A15: tasa_descuento | B15: 0.115 | C15: CREG
A16: c_tcsc | B16: 135000 | C16: [USD/MVAr]
A17: sigma_niveles | B17: 0.15,0.30,0.45,0.60 | C17: Solo compensacion capacitiva
A18: theta_max_grados | B18: 20
A19: solver | B19: gurobi
A20: costo_vertimiento | B20: 0.01 | C20: Regularizacion del vertimiento [USD por m3/s y hora]. No es un costo real.
A21: tol_volumen_inf | B21: 0.3 | C21: Banda inferior del cierre de volumen: Vinit - tol*(Vmax-Vmin)
A22: tol_volumen_sup | B22: 0.05 | C22: Banda superior del cierre de volumen: Vinit + tol*(Vmax-Vmin)
A23: fecha_inicio_simulacion | B23: 46211
A24: fecha_fin_simulacion | B24: 46211

Sheet Nodos
A1: Nodos - Buses del sistema
A2: tipo: 'slack' (referencia, UNO solo), 'pv' (con gen), 'pq' (carga).
A4: id | B4: tipo | C4: latitud | D4: longitud | E4: nombre_subarea
B5: slack/pv/pq
A6: ANT | B6: slack | E6: Antioquia
A7: ARA | B7: 0 | E7: Arauca
A8: ATL | B8: 0 | E8: Atlántico
A9: BOG | B9: 0 | E9: Bogotá
A10: BOL | B10: 0 | E10: Bolivar
A11: BYC | B11: 0 | E11: Boyaca-Casanare
A12: CQR | B12: 0 | E12: CQR
A13: CAQ | B13: 0 | E13: Caquetá
A14: CAN | B14: 0 | E14: Cauca-Nariño
A15: CER | B15: 0 | E15: Cerromatoso
A16: CSU | B16: 0 | E16: Cordoba_Sucre
A17: GCM | B17: 0 | E17: GCM
A18: HTO | B18: 0 | E18: Huila-Tolima
... A23: VAL | B23: 0 | E23: Valle del Cauca

Sheet Lineas
A1: Lineas - Lineas de transmision existentes
A2: R y X en por unidad. La susceptancia se calcula como 1/X.
A4: id | B4: desde | C4: hasta | D4: R | E4: X | F4: capacidad
B5: nodo | C5: nodo | D5: p.u. | E5: p.u. | F5: MW
A6: l1 | B6: ANT | C6: BOG | D6: 0.0018431712 | E6: 0.026072208 | F6: 1649.7784
A7: l2 | B7: ANT | C7: CQR | D7: 0.00056770178 | E7: 0.0064577107 | F7: 6935.3393
A8: l3 | B8: ANT | C8: CER | D8: 0.00034403534 | E8: 0.004455995 | F8: 7971.7638
A9: l4 | B9: ANT | C9: SAN | D9: 0.00076857032 | E9: 0.0087522696 | F9: 4763.209
A10: l5 | B10: ARA | C10: SAN | D10: 0.0080801701 | E10: 0.07752758 | F10: 318.69735
A11: l6 | B11: ATL | C11: BOL | D11: 0.0005410517 | E11: 0.0061995171 | F11: 2912.582
A12: l7 | B12: ATL | C12: CSU | D12: 0.00097970417 | E12: 0.012142476 | F12: 4221.8738
A13: l8 | B13: ATL | C13: GCM | D13: 0.0056753236 | E13: 0.031803693 | F13: 943.10166
A14: l9 | B14: BOG | C14: BYC | D14: 0.0054395917 | E14: 0.053167622 | F14: 764.87364
A15: l10 | B15: BOG | C15: CQR | D15: 0.0010778944 | E15: 0.012044697 | F15: 3609.8017
A16: l11 | B16: BOG | C16: HTO | D16: 0.00438543 | E16: 0.039567234 | F16: 769.6541
A17: l12 | B17: BOG | C17: MET | D17: 0.0012967325 | E17: 0.015094391 | F17: 1912.1841
... A31: l26 | B31: NDS | C31: SAN | D31: 0.0013058842 | E31: 0.014079347 | F31: 2722.9917

Sheet Lineas_Cand
A1: Lineas_Cand - Lineas candidatas a construir (TEP)
A2: Vacia si no hay candidatas. 'costo' = costo de construccion.
A4: id | B4: desde | C4: hasta | D4: R | E4: X | F4: capacidad | G4: costo
B5: nodo | C5: nodo | D5: p.u. | E5: p.u. | F5: MW | G5: USD

Sheet Generadores
A1: Generadores - Unidades termicas
A2: Costo cuadratico c2*P^2+c1*P+c0. min_on/off y cost_su/sd para UC.
A4: id | B4: nodo | C4: Pmin | D4: Pmax | E4: rampa_sub_min | F4: rampa_sub | G4: rampa_baj_min | H4: rampa_baj | I4: c2 | J4: c1 | K4: c0 | L4: u_init | M4: min_on | N4: min_off | O4: Carga_sincronizante_frío | P4: Tiempo_calentamiento_frío | Q4: cost_su | R4: cost_sd | S4: combustible | T4: Planta | U4: codigo | V4: Latitud | W4: Longitud
C5: MW | D5: MW | E5: MW/min | F5: MW/h | G5: MW/min | H5: MW/h | I5: $/MW2 | J5: $/MW | K5: $ | M5: h | N5: h | O5: MW | P5: h | Q5: USD | R5: USD | V5: ° | W5: °
A6: TERMOCENTRO 1 | B6: ANT | C6: 30 | D6: 97 | E6: 5 | F6: =E6*60 -> 300 | G6: 4.99 | H6: =G6*60 -> 299.4 | I6: 0 | J6: 279.62677 | K6: 0 | L6: 0 | M6: 1 | N6: 0 | O6: 5 | P6: 0 | Q6: =O6*P6*J6 -> 0 | R6: 0 | S6: Gas | T6: TERMOCENTRO CC | U6: =_xlfn.XLOOKUP(T6,[1]Detalle_Unidades!F3:F549,[1]Detalle_Unidades!A3:A549) -> TRM1
A7: TERMOCENTRO 2 | B7: ANT | C7: 40 | D7: 80 | E7: 5 | F7: =E7*60 -> 300 | G7: 5.07 | H7: =G7*60 -> 304.2 | I7: 0 | J7: 279.62677 | K7: 0 | L7: 0 | M7: 6 | N7: 6 | O7: 5 | P7: 2 | Q7: =O7*P7*J7 -> 2796.2677 | R7: 0 | S7: ACPM | T7: TERMOCENTRO CC | U7: =_xlfn.XLOOKUP(T7,[1]Detalle_Unidades!F4:F550,[1]Detalle_Unidades!A4:A550) -> TRM1
A8: TERMOCENTRO 3 | B8: ANT | C8: 30 | D8: 77 | E8: 3.88 | F8: =E8*60 -> 232.8 | G8: 3.11 | H8: =G8*60 -> 186.6 | I8: 0 | J8: 279.62677 | K8: 0 | L8: 0 | M8: 10 | N8: 8 | O8: 5 | P8: 4 | Q8: =O8*P8*J8 -> 5592.5353 | R8: 0 | S8: ACPM | T8: TERMOCENTRO CC | U8: =_xlfn.XLOOKUP(T8,[1]Detalle_Unidades!F5:F551,[1]Detalle_Unidades!A5:A551) -> TRM1
A9: TERMOSIERRA 1 | B9: ANT | C9: 89 | D9: 110 | E9: 42.41 | F9: =E9*60 -> 2544.6 | G9: 41.41 | H9: =G9*60 -> 2484.6 | I9: 0 | J9: 387.15751 | K9: 0 | L9: 0 | M9: 8 | N9: 1 | O9: 12 | P9: 2 | Q9: =O9*P9*J9 -> 9291.7803 | R9: 0 | S9: ACPM | T9: TERMOSIERRA CC | U9: =_xlfn.XLOOKUP(T9,[1]Detalle_Unidades!F6:F552,[1]Detalle_Unidades!A6:A552) -> TSR1
A10: TERMOSIERRA 2 | B10: ANT | C10: 89 | D10: 110 | E10: 2.5 | F10: =E10*60 -> 150 | G10: 49.25 | H10: =G10*60 -> 2955 | I10: 0 | J10: 387.15751 | K10: 0 | L10: 0 | M10: 8 | N10: 1 | O10: 12 | P10: 2 | Q10: =O10*P10*J10 -> 9291.7803 | R10: 0 | S10: ACPM | T10: TERMOSIERRA CC | U10: =_xlfn.XLOOKUP(T10,[1]Detalle_Unidades!F7:F553,[1]Detalle_Unidades!A7:A553) -> TSR1
A11: TERMOSIERRA 3 | B11: ANT | C11: 42 | D11: 132 | E11: 5 | F11: =E11*60 -> 300 | G11: 12.7 | H11: =G11*60 -> 762 | I11: 0 | J11: 387.15751 | K11: 0 | L11: 0 | M11: 8 | N11: 1 | O11: 12 | P11: 2 | Q11: =O11*P11*J11 -> 9291.7803 | R11: 0 | S11: ACPM | T11: TERMOSIERRA CC | U11: =_xlfn.XLOOKUP(T11,[1]Detalle_Unidades!F8:F554,[1]Detalle_Unidades!A8:A554) -> TSR1
A12: BARRANQUILLA 3 | B12: ATL | C12: 33 | D12: 60 | E12: 0.94 | F12: =E12*60 -> 56.4 | G12: 0.94 | H12: =G12*60 -> 56.4 | I12: 0 | J12: 305.81256 | K12: 0 | L12: 0 | M12: 48 | N12: 24 | O12: 5 | P12: 8 | Q12: =O12*P12*J12 -> 12232.503 | R12: 0 | S12: Gas | T12: BARRANQUILLA 3 | U12: =_xlfn.XLOOKUP(T12,[1]Detalle_Unidades!F9:F555,[1]Detalle_Unidades!A9:A555) -> TBQ3
A13: BARRANQUILLA 4 | B13: ATL | C13: 33 | D13: 60 | E13: 1.05 | F13: =E13*60 -> 63 | G13: 0.96 | H13: =G13*60 -> 57.6 | I13: 0 | J13: 292.11057 | K13: 0 | L13: 0 | M13: 48 | N13: 24 | O13: 5 | P13: 8 | Q13: =O13*P13*J13 -> 11684.423 | R13: 0 | S13: Gas | T13: BARRANQUILLA 4 | U13: =_xlfn.XLOOKUP(T13,[1]Detalle_Unidades!F10:F556,[1]Detalle_Unidades!A10:A556) -> TBQ4
A14: FLORES 1 GAS | B14: ATL | C14: 45 | D14: 119 | E14: 2 | F14: =E14*60 -> 120 | G14: 0.5 | H14: =G14*60 -> 30 | I14: 0 | J14: 295.69465 | K14: 0 | L14: 1 | M14: 8 | N14: 4 | O14: 5 | P14: 0.75 | Q14: =O14*P14*J14 -> 1108.8549 | R14: 0 | S14: Gas | T14: FLORES I CC | U14: =_xlfn.XLOOKUP(T14,[1]Detalle_Unidades!F11:F557,[1]Detalle_Unidades!A11:A557) -> TFL1
A15: FLORES 1 VAPOR | B15: ATL | C15: 20 | D15: 46 | E15: 1.5 | F15: =E15*60 -> 90 | G15: 0.1 | H15: =G15*60 -> 6 | I15: 0 | J15: 295.69465 | K15: 0 | L15: 1 | M15: 8 | N15: 4 | O15: 10 | P15: 0.75 | Q15: =O15*P15*J15 -> 2217.7098 | R15: 0 | S15: Gas | T15: FLORES I CC | U15: =_xlfn.XLOOKUP(T15,[1]Detalle_Unidades!F12:F558,[1]Detalle_Unidades!A12:A558) -> TFL1
A16: FLORES 2 | B16: ATL | C16: 80 | D16: 120 | E16: 2 | F16: =E16*60 -> 120 | G16: 0.4 | H16: =G16*60 -> 24 | I16: 0 | J16: 309.62964 | K16: 0 | L16: 1 | M16: 16 | N16: 4 | O16: 5 | P16: 0.75 | Q16: =O16*P16*J16 -> 1161.1111 | R16: 0 | S16: Gas | T16: FLORES 4 CC | U16: =_xlfn.XLOOKUP(T16,[1]Detalle_Unidades!F13:F559,[1]Detalle_Unidades!A13:A559) -> TFL4
A17: FLORES 3 | B17: ATL | C17: 60 | D17: 169 | E17: 2 | F17: =E17*60 -> 120 | G17: 0.77 | H17: =G17*60 -> 46.2 | I17: 0 | J17: 309.62964 | K17: 0 | L17: 1 | M17: 16 | N17: 4 | O17: 5 | P17: 0.75 | Q17: =O17*P17*J17 -> 1161.1111 | R17: 0 | S17: Gas | T17: FLORES 4 CC | U17: =_xlfn.XLOOKUP(T17,[1]Detalle_Unidades!F14:F560,[1]Detalle_Unidades!A14:A560) -> TFL4
... A81: TERMOVALLE 1 VAPOR | B81: VAL | C81: 35 | D81: 74 | E81: 1 | F81: =E81*60 -> 60 | G81: 4 | H81: =G81*60 -> 240 | I81: 0 | J81: 444.30296 | K81: 0 | L81: 0 | M81: 10 | N81: 4 | O81: 10 | P81: 0.75 | Q81: =O81*P81*J81 -> 3332.2722 | R81: 0 | S81: ACPM | T81: TERMOVALLE CC | U81: =_xlfn.XLOOKUP(T81,[1]Detalle_Unidades!F78:F624,[1]Detalle_Unidades!A78:A624) -> TVL1

Sheet Hidraulicos
A1: Hidraulicos - Unidades hidraulicas y embalses
A2: Vacia si el sistema no tiene hidraulica. Embalse: vol_min/max/ini.
A4: id | B4: nodo | C4: Pmin | D4: Pmax | E4: qmin | F4: qmax | G4: eta | H4: Vmin | I4: Vmax | J4: Vol/Capa | K4: Vinit | L4: Smax | M4: costo | N4: Pmin_PARATEC | O4: Clasificación | P4: Planta | Q4: codigo | R4: Latitud | S4: Longitud
A5: embalse | B5: nodo | C5: MW | D5: MW | E5: m3/s | F5: m3/s | G5: MW/(m3/s) | H5: hm3 | I5: Mm3 | J5: - | K5: hm3 | L5: m3/s | M5: $/MWh | N5: MW | R5: ° | S5: °
A6: GUAVIO | B6: BOG | C6: 0 | D6: =_xlfn.XLOOKUP(P6,[2]CapacidadEfectiva!$B$145:$B$179,[2]CapacidadEfectiva!$C$145:$C$179) -> 1250 | E6: =C6/G6 -> 0 | F6: =D6/G6 -> 126.95898 | G6: =_xlfn.XLOOKUP(P6,[3]Phidráulica!$A$10:$A$166,[3]Phidráulica!$J$10:$J$166) -> 9,8457 | H6: =_xlfn.XLOOKUP(A6,[4]Información_Técnica!$A$8:$A$36,[4]Información_Técnica!$F$8:$F$36) -> 18,47 | I6: =_xlfn.XLOOKUP(A6,[4]Información_Técnica!$A$8:$A$36,[4]Información_Técnica!$G$8:$G$36) -> 741.69 | J6: 0.96002599 | K6: =H6+J6*(I6-H6) -> 712.78 | L6: 0 | M6: =_xlfn.XLOOKUP(Q6,'[5]01_SERIE'!$H$14042:$H$16057,'[5]01_SERIE'!$K$14042:$K$16057) -> 25.320717 | N6: 300 | O6: =_xlfn.XLOOKUP(P6,[3]Phidráulica!$A$10:$A$166,[3]Phidráulica!$K$10:$K$166) -> Cuenta con embalse | P6: GUAVIO | Q6: =_xlfn.XLOOKUP(P6,[6]Detalle_Unidades!$F$2:$F$886,[6]Detalle_Unidades!$A$2:$A$886) -> GVIO | R6: 4.4355 | S6: -73.29007
A7: PUNCHINA | B7: ANT | C7: 0 | D7: =_xlfn.XLOOKUP(P7,[2]CapacidadEfectiva!$B$145:$B$179,[2]CapacidadEfectiva!$C$145:$C$179) -> 1240 | E7: =C7/G7 -> 0 | F7: =D7/G7 -> 229.63813 | G7: =_xlfn.XLOOKUP(P7,[3]Phidráulica!$A$10:$A$166,[3]Phidráulica!$J$10:$J$166) -> 5,3998 | H7: =_xlfn.XLOOKUP(A7,[4]Información_Técnica!$A$8:$A$36,[4]Información_Técnica!$F$8:$F$36) -> 13,98 | I7: =_xlfn.XLOOKUP(A7,[4]Información_Técnica!$A$8:$A$36,[4]Información_Técnica!$G$8:$G$36) -> 57.94 | J7: 0.38034577 | K7: =H7+J7*(I7-H7) -> 30.7 | L7: 0 | M7: =_xlfn.XLOOKUP(Q7,'[5]01_SERIE'!$H$14042:$H$16057,'[5]01_SERIE'!$K$14042:$K$16057) -> 207.77071 | N7: 176 | O7: =_xlfn.XLOOKUP(P7,[3]Phidráulica!$A$10:$A$166,[3]Phidráulica!$K$10:$K$166) -> Cuenta con embalse | P7: SAN CARLOS | Q7: =_xlfn.XLOOKUP(P7,[6]Detalle_Unidades!$F$2:$F$886,[6]Detalle_Unidades!$A$2:$A$886) -> SNCR | R7: 6.2115 | S7: -74.8405
A8: ITUANGO | B8: ANT | C8: 0 | D8: =_xlfn.XLOOKUP(P8,[2]CapacidadEfectiva!$B$145:$B$179,[2]CapacidadEfectiva!$C$145:$C$179) -> 1200 | E8: =C8/G8 -> 0 | F8: =D8/G8 -> 695.16858 | G8: =_xlfn.XLOOKUP(P8,[3]Phidráulica!$A$10:$A$166,[3]Phidráulica!$J$10:$J$166) -> 1,7262 | H8: =_xlfn.XLOOKUP(A8,[4]Información_Técnica!$A$8:$A$36,[4]Información_Técnica!$F$8:$F$36) -> 1.299 | I8: =_xlfn.XLOOKUP(A8,[4]Información_Técnica!$A$8:$A$36,[4]Información_Técnica!$G$8:$G$36) -> 1431 | J8: 0.50166667 | K8: =H8+J8*(I8-H8) -> 1365.22 | L8: 0 | M8: =_xlfn.XLOOKUP(Q8,'[5]01_SERIE'!$H$14042:$H$16057,'[5]01_SERIE'!$K$14042:$K$16057) -> 24.491582 | N8: 616 | O8: =_xlfn.XLOOKUP(P8,[3]Phidráulica!$A$10:$A$166,[3]Phidráulica!$K$10:$K$166) -> Cuenta con embalse | P8: ITUANGO | Q8: =_xlfn.XLOOKUP(P8,[6]Detalle_Unidades!$F$2:$F$886,[6]Detalle_Unidades!$A$2:$A$886) -> PES1 | R8: 7.1345 | S8: -75.6622
A9: ESMERALDA | B9: BOG | C9: 0 | D9: =_xlfn.XLOOKUP(P9,[2]CapacidadEfectiva!$B$145:$B$179,[2]CapacidadEfectiva!$C$145:$C$179) -> 1000 | E9: =C9/G9 -> 0 | F9: =D9/G9 -> 143.19877 | G9: =_xlfn.XLOOKUP(P9,[3]Phidráulica!$A$10:$A$166,[3]Phidráulica!$J$10:$J$166) -> 6,9833 | H9: =_xlfn.XLOOKUP(A9,[4]Información_Técnica!$A$8:$A$36,[4]Información_Técnica!$F$8:$F$36) -> 67,7 | I9: =_xlfn.XLOOKUP(A9,[4]Información_Técnica!$A$8:$A$36,[4]Información_Técnica!$G$8:$G$36) -> 528.48 | J9: 0.86798472 | K9: =H9+J9*(I9-H9) -> 467.65 | L9: 0 | M9: =_xlfn.XLOOKUP(Q9,'[5]01_SERIE'!$H$14042:$H$16057,'[5]01_SERIE'!$K$14042:$K$16057) -> 42.083671 | N9: 80 | O9: =_xlfn.XLOOKUP(P9,[3]Phidráulica!$A$10:$A$166,[3]Phidráulica!$K$10:$K$166) -> Cuenta con embalse | P9: CHIVOR | Q9: =_xlfn.XLOOKUP(P9,[6]Detalle_Unidades!$F$2:$F$886,[6]Detalle_Unidades!$A$2:$A$886) -> CHVR | R9: 4.9 | S9: -73.3
A10: TOPOCORO | B10: SAN | C10: 0 | D10: =_xlfn.XLOOKUP(P10,[2]CapacidadEfectiva!$B$145:$B$179,[2]CapacidadEfectiva!$C$145:$C$179) -> 819 | E10: =C10/G10 -> 0 | F10: =D10/G10 -> 586.2143 | G10: =_xlfn.XLOOKUP(P10,[3]Phidráulica!$A$10:$A$166,[3]Phidráulica!$J$10:$J$166) -> 1,3971 | H10: =_xlfn.XLOOKUP(A10,[4]Información_Técnica!$A$8:$A$36,[4]Información_Técnica!$F$8:$F$36) -> 555,84 | I10: =_xlfn.XLOOKUP(A10,[4]Información_Técnica!$A$8:$A$36,[4]Información_Técnica!$G$8:$G$36) -> 3206.49 | J10: 0.84208779 | K10: =H10+J10*(I10-H10) -> 2787.92 | L10: 0 | M10: =_xlfn.XLOOKUP(Q10,'[5]01_SERIE'!$H$14042:$H$16057,'[5]01_SERIE'!$K$14042:$K$16057) -> 197.73751 | N10: 360 | O10: =_xlfn.XLOOKUP(P10,[3]Phidráulica!$A$10:$A$166,[3]Phidráulica!$K$10:$K$166) -> Cuenta con embalse | P10: SOGAMOSO | Q10: =_xlfn.XLOOKUP(P10,[6]Detalle_Unidades!$F$2:$F$886,[6]Detalle_Unidades!$A$2:$A$886) -> SOG1 | R10: 7.100364 | S10: -73.407011
A11: PORCE III | B11: ANT | C11: 0 | D11: =_xlfn.XLOOKUP(P11,[2]CapacidadEfectiva!$B$145:$B$179,[2]CapacidadEfectiva!$C$145:$C$179) -> 700 | E11: =C11/G11 -> 0 | F11: =D11/G11 -> 228.70585 | G11: =_xlfn.XLOOKUP(P11,[3]Phidráulica!$A$10:$A$166,[3]Phidráulica!$J$10:$J$166) -> 3,0607 | H11: =_xlfn.XLOOKUP(A11,[4]Información_Técnica!$A$8:$A$36,[4]Información_Técnica!$F$8:$F$36) -> 29,45 | I11: =_xlfn.XLOOKUP(A11,[4]Información_Técnica!$A$8:$A$36,[4]Información_Técnica!$G$8:$G$36) -> 161.28 | J11: 0.26116969 | K11: =H11+J11*(I11-H11) -> 63.88 | L11: 0 | M11: =_xlfn.XLOOKUP(Q11,'[5]01_SERIE'!$H$14042:$H$16057,'[5]01_SERIE'!$K$14042:$K$16057) -> 197.62604 | N11: 500 | O11: =_xlfn.XLOOKUP(P11,[3]Phidráulica!$A$10:$A$166,[3]Phidráulica!$K$10:$K$166) -> Cuenta con embalse | P11: PORCE III | Q11: =_xlfn.XLOOKUP(P11,[6]Detalle_Unidades!$F$2:$F$886,[6]Detalle_Unidades!$A$2:$A$886) -> PRC3
A12: PENOL | B12: ANT | C12: 0 | D12: =_xlfn.XLOOKUP(P12,[2]CapacidadEfectiva!$B$145:$B$179,[2]CapacidadEfectiva!$C$145:$C$179) -> 560 | E12: =C12/G12 -> 0 | F12: =D12/G12 -> 77.580594 | G12: =_xlfn.XLOOKUP(P12,[3]Phidráulica!$A$10:$A$166,[3]Phidráulica!$J$10:$J$166) -> 7,2183 | H12: =_xlfn.XLOOKUP(A12,[4]Información_Técnica!$A$8:$A$36,[4]Información_Técnica!$F$8:$F$36) -> 77,84 | I12: =_xlfn.XLOOKUP(A12,[4]Información_Técnica!$A$8:$A$36,[4]Información_Técnica!$G$8:$G$36) -> 1120.02 | J12: 0.92000422 | K12: =H12+J12*(I12-H12) -> 1036.65 | L12: 0 | M12: =_xlfn.XLOOKUP(Q12,'[5]01_SERIE'!$H$14042:$H$16057,'[5]01_SERIE'!$K$14042:$K$16057) -> 197.59817 | N12: 0 | O12: =_xlfn.XLOOKUP(P12,[3]Phidráulica!$A$10:$A$166,[3]Phidráulica!$K$10:$K$166) -> Cuenta con embalse | P12: GUATAPE | Q12: =_xlfn.XLOOKUP(P12,[6]Detalle_Unidades!$F$2:$F$886,[6]Detalle_Unidades!$A$2:$A$886) -> GTPE | R12: 6.319869 | S12: -75.177636
A13: BETANIA | B13: HTO | C13: 0 | D13: =_xlfn.XLOOKUP(P13,[2]CapacidadEfectiva!$B$145:$B$179,[2]CapacidadEfectiva!$C$145:$C$179) -> 540 | E13: =C13/G13 -> 0 | F13: =D13/G13 -> 916.03053 | G13: =_xlfn.XLOOKUP(P13,[3]Phidráulica!$A$10:$A$166,[3]Phidráulica!$J$10:$J$166) -> 0,5895 | H13: =_xlfn.XLOOKUP(A13,[4]Información_Técnica!$A$8:$A$36,[4]Información_Técnica!$F$8:$F$36) -> 448,19 | I13: =_xlfn.XLOOKUP(A13,[4]Información_Técnica!$A$8:$A$36,[4]Información_Técnica!$G$8:$G$36) -> 1171.79 | J13: 0.77616086 | K13: =H13+J13*(I13-H13) -> 1009.82 | L13: 0 | M13: =_xlfn.XLOOKUP(Q13,'[5]01_SERIE'!$H$14042:$H$16057,'[5]01_SERIE'!$K$14042:$K$16057) -> 25.320714 | N13: 180 | O13: =_xlfn.XLOOKUP(P13,[3]Phidráulica!$A$10:$A$166,[3]Phidráulica!$K$10:$K$166) -> Cuenta con embalse | P13: BETANIA | Q13: =_xlfn.XLOOKUP(P13,[6]Detalle_Unidades!$F$2:$F$886,[6]Detalle_Unidades!$A$2:$A$886) -> CHBG | R13: 2.423 | S13: -75.259
A14: PORCE II | B14: ANT | C14: 0 | D14: =_xlfn.XLOOKUP(P14,[2]CapacidadEfectiva!$B$145:$B$179,[2]CapacidadEfectiva!$C$145:$C$179) -> 405 | E14: =C14/G14 -> 0 | F14: =D14/G14 -> 188.96976 | G14: =_xlfn.XLOOKUP(P14,[3]Phidráulica!$A$10:$A$166,[3]Phidráulica!$J$10:$J$166) -> 2,1432 | H14: =_xlfn.XLOOKUP(A14,[4]Información_Técnica!$A$8:$A$36,[4]Información_Técnica!$F$8:$F$36) -> 38,79 | I14: =_xlfn.XLOOKUP(A14,[4]Información_Técnica!$A$8:$A$36,[4]Información_Técnica!$G$8:$G$36) -> 124.67 | J14: 0.28039124 | K14: =H14+J14*(I14-H14) -> 62.87 | L14: 0 | M14: =_xlfn.XLOOKUP(Q14,'[5]01_SERIE'!$H$14042:$H$16057,'[5]01_SERIE'!$K$14042:$K$16057) -> 209.16421 | N14: 225 | O14: =_xlfn.XLOOKUP(P14,[3]Phidráulica!$A$10:$A$166,[3]Phidráulica!$K$10:$K$166) -> Cuenta con embalse | P14: PORCE II | Q14: =_xlfn.XLOOKUP(P14,[6]Detalle_Unidades!$F$2:$F$886,[6]Detalle_Unidades!$A$2:$A$886) -> PRC2
A15: EL QUIMBO | B15: CAN | C15: 0 | D15: =_xlfn.XLOOKUP(P15,[2]CapacidadEfectiva!$B$145:$B$179,[2]CapacidadEfectiva!$C$145:$C$179) -> 400 | E15: =C15/G15 -> 0 | F15: =D15/G15 -> 363.47115 | G15: =_xlfn.XLOOKUP(P15,[3]Phidráulica!$A$10:$A$166,[3]Phidráulica!$J$10:$J$166) -> 1,1005 | H15: =_xlfn.XLOOKUP(A15,[4]Información_Técnica!$A$8:$A$36,[4]Información_Técnica!$F$8:$F$36) -> 453,72 | I15: =_xlfn.XLOOKUP(A15,[4]Información_Técnica!$A$8:$A$36,[4]Información_Técnica!$G$8:$G$36) -> 2742.14 | J15: 0.64587794 | K15: =H15+J15*(I15-H15) -> 1931.76 | L15: 0 | M15: =_xlfn.XLOOKUP(Q15,'[5]01_SERIE'!$H$14042:$H$16057,'[5]01_SERIE'!$K$14042:$K$16057) -> 178.36788 | N15: 0 | O15: =_xlfn.XLOOKUP(P15,[3]Phidráulica!$A$10:$A$166,[3]Phidráulica!$K$10:$K$166) -> Cuenta con embalse | P15: EL QUIMBO | Q15: =_xlfn.XLOOKUP(P15,[6]Detalle_Unidades!$F$2:$F$886,[6]Detalle_Unidades!$A$2:$A$886) -> QUI1 | R15: 2.4494 | S15: -75.5644
A16: AMANI | B16: CQR | C16: 0 | D16: =_xlfn.XLOOKUP(P16,[2]CapacidadEfectiva!$B$145:$B$179,[2]CapacidadEfectiva!$C$145:$C$179) -> 396 | E16: =C16/G16 -> 0 | F16: =D16/G16 -> 191.5542 | G16: =_xlfn.XLOOKUP(P16,[3]Phidráulica!$A$10:$A$166,[3]Phidráulica!$J$10:$J$166) -> 2,0673 | H16: =_xlfn.XLOOKUP(A16,[4]Información_Técnica!$A$8:$A$36,[4]Información_Técnica!$F$8:$F$36) -> 48,01 | I16: =_xlfn.XLOOKUP(A16,[4]Información_Técnica!$A$8:$A$36,[4]Información_Técnica!$G$8:$G$36) -> 489.8 | J16: 0.76602005 | K16: =H16+J16*(I16-H16) -> 386.43 | L16: 0 | M16: =_xlfn.XLOOKUP(Q16,'[5]01_SERIE'!$H$14042:$H$16057,'[5]01_SERIE'!$K$14042:$K$16057) -> 300.99579 | N16: 60 | O16: =_xlfn.XLOOKUP(P16,[3]Phidráulica!$A$10:$A$166,[3]Phidráulica!$K$10:$K$166) -> Cuenta con embalse | P16: MIEL I | Q16: =_xlfn.XLOOKUP(P16,[6]Detalle_Unidades!$F$2:$F$886,[6]Detalle_Unidades!$A$2:$A$886) -> HMLG | R16: 5.37 | S16: -74.57
A17: ALTO ANCHICAYA | B17: VAL | C17: 0 | D17: =_xlfn.XLOOKUP(P17,[2]CapacidadEfectiva!$B$145:$B$179,[2]CapacidadEfectiva!$C$145:$C$179) -> 355 | E17: =C17/G17 -> 0 | F17: =D17/G17 -> 101.16266 | G17: =_xlfn.XLOOKUP(P17,[3]Phidráulica!$A$10:$A$166,[3]Phidráulica!$J$10:$J$166) -> 3,5092 | H17: =_xlfn.XLOOKUP(A17,[4]Información_Técnica!$A$8:$A$36,[4]Información_Técnica!$F$8:$F$36) -> 6,32 | I17: =_xlfn.XLOOKUP(A17,[4]Información_Técnica!$A$8:$A$36,[4]Información_Técnica!$G$8:$G$36) -> 38.38 | J17: 0.64285714 | K17: =H17+J17*(I17-H17) -> 26.93 | L17: 0 | M17: =_xlfn.XLOOKUP(Q17,'[5]01_SERIE'!$H$14042:$H$16057,'[5]01_SERIE'!$K$14042:$K$16057) -> 335.83327 | N17: 90 | O17: =_xlfn.XLOOKUP(P17,[3]Phidráulica!$A$10:$A$166,[3]Phidráulica!$K$10:$K$166) -> Cuenta con embalse | P17: ALTO ANCHICAYA | Q17: ALBG
A18: URRA | B18: CSU | C18: 0 | D18: =_xlfn.XLOOKUP(P18,[2]CapacidadEfectiva!$B$145:$B$179,[2]CapacidadEfectiva!$C$145:$C$179) -> 338 | E18: =C18/G18 -> 0 | F18: =D18/G18 -> 710.68124 | G18: =_xlfn.XLOOKUP(P18,[3]Phidráulica!$A$10:$A$166,[3]Phidráulica!$J$10:$J$166) -> 0,4756 | H18: =_xlfn.XLOOKUP(A18,[4]Información_Técnica!$A$8:$A$36,[4]Información_Técnica!$F$8:$F$36) -> 354,01 | I18: =_xlfn.XLOOKUP(A18,[4]Información_Técnica!$A$8:$A$36,[4]Información_Técnica!$G$8:$G$36) -> 1418.17 | J18: 0.64770335 | K18: =H18+J18*(I18-H18) -> 1043.27 | L18: 0 | M18: =_xlfn.XLOOKUP(Q18,'[5]01_SERIE'!$H$14042:$H$16057,'[5]01_SERIE'!$K$14042:$K$16057) -> 198.43426 | N18: 120 | O18: =_xlfn.XLOOKUP(P18,[3]Phidráulica!$A$10:$A$166,[3]Phidráulica!$K$10:$K$166) -> Cuenta con embalse | P18: URRA | Q18: =_xlfn.XLOOKUP(P18,[6]Detalle_Unidades!$F$2:$F$886,[6]Detalle_Unidades!$A$2:$A$886) -> URA1 | R18: 7.866667 | S18: -76.283333
A19: SALVAJINA | B19: VAL | C19: 0 | D19: =_xlfn.XLOOKUP(P19,[2]CapacidadEfectiva!$B$145:$B$179,[2]CapacidadEfectiva!$C$145:$C$179) -> 315 | E19: =C19/G19 -> 0 | F19: =D19/G19 -> 365.81117 | G19: =_xlfn.XLOOKUP(P19,[3]Phidráulica!$A$10:$A$166,[3]Phidráulica!$J$10:$J$166) -> 0,8611 | H19: =_xlfn.XLOOKUP(A19,[4]Información_Técnica!$A$8:$A$36,[4]Información_Técnica!$F$8:$F$36) -> 91,45 | I19: =_xlfn.XLOOKUP(A19,[4]Información_Técnica!$A$8:$A$36,[4]Información_Técnica!$G$8:$G$36) -> 807.22 | J19: 0.90181203 | K19: =H19+J19*(I19-H19) -> 736.94 | L19: 0 | M19: =_xlfn.XLOOKUP(Q19,'[5]01_SERIE'!$H$14042:$H$16057,'[5]01_SERIE'!$K$14042:$K$16057) -> 335.55457 | N19: 90 | O19: =_xlfn.XLOOKUP(P19,[3]Phidráulica!$A$10:$A$166,[3]Phidráulica!$K$10:$K$166) -> Cuenta con embalse | P19: SALVAJINA | Q19: =_xlfn.XLOOKUP(P19,[6]Detalle_Unidades!$F$2:$F$886,[6]Detalle_Unidades!$A$2:$A$886) -> SLVJ | R19: 2.563915 | S19: -76.42273
A20: RIOGRANDE2 | B20: ANT | C20: 0 | D20: =_xlfn.XLOOKUP(P20,[2]CapacidadEfectiva!$B$145:$B$179,[2]CapacidadEfectiva!$C$145:$C$179) -> 306 | E20: =C20/G20 -> 0 | F20: =D20/G20 -> 39.154969 | G20: =_xlfn.XLOOKUP(P20,[3]Phidráulica!$A$10:$A$166,[3]Phidráulica!$J$10:$J$166) -> 7,8151 | H20: =_xlfn.XLOOKUP(A20,[4]Información_Técnica!$A$8:$A$36,[4]Información_Técnica!$F$8:$F$36) -> 47,64 | I20: =_xlfn.XLOOKUP(A20,[4]Información_Técnica!$A$8:$A$36,[4]Información_Técnica!$G$8:$G$36) -> 185.26 | J20: 0.70396745 | K20: =H20+J20*(I20-H20) -> 144.52 | L20: 0 | M20: =_xlfn.XLOOKUP(Q20,'[5]01_SERIE'!$H$14042:$H$16057,'[5]01_SERIE'!$K$14042:$K$16057) -> 249.43633 | N20: 0 | O20: =_xlfn.XLOOKUP(P20,[3]Phidráulica!$A$10:$A$166,[3]Phidráulica!$K$10:$K$166) -> Cuenta con embalse | P20: LA TASAJERA | Q20: =_xlfn.XLOOKUP(P20,[6]Detalle_Unidades!$F$2:$F$886,[6]Detalle_Unidades!$A$2:$A$886) -> LTSJ | R20: 6.509308 | S20: -75.452425
A21: PLAYAS | B21: ANT | C21: 0 | D21: =_xlfn.XLOOKUP(P21,[2]CapacidadEfectiva!$B$145:$B$179,[2]CapacidadEfectiva!$C$145:$C$179) -> 207 | E21: =C21/G21 -> 0 | F21: =D21/G21 -> 119.6117 | G21: =_xlfn.XLOOKUP(P21,[3]Phidráulica!$A$10:$A$166,[3]Phidráulica!$J$10:$J$166) -> 1,7306 | H21: =_xlfn.XLOOKUP(A21,[4]Información_Técnica!$A$8:$A$36,[4]Información_Técnica!$F$8:$F$36) -> 19,57 | I21: =_xlfn.XLOOKUP(A21,[4]Información_Técnica!$A$8:$A$36,[4]Información_Técnica!$G$8:$G$36) -> 67.59 | J21: 0.71470221 | K21: =H21+J21*(I21-H21) -> 53.89 | L21: 0 | M21: =_xlfn.XLOOKUP(Q21,'[5]01_SERIE'!$H$14042:$H$16057,'[5]01_SERIE'!$K$14042:$K$16057) -> 25.273338 | N21: 147 | O21: =_xlfn.XLOOKUP(P21,[3]Phidráulica!$A$10:$A$166,[3]Phidráulica!$K$10:$K$166) -> Cuenta con embalse | P21: PLAYAS | Q21: =_xlfn.XLOOKUP(P21,[6]Detalle_Unidades!$F$2:$F$886,[6]Detalle_Unidades!$A$2:$A$886) -> PLYS | R21: 6.295311 | S21: -74.943153
A22: SAN LORENZO | B22: ANT | C22: 0 | D22: =_xlfn.XLOOKUP(P22,[2]CapacidadEfectiva!$B$145:$B$179,[2]CapacidadEfectiva!$C$145:$C$179) -> 170 | E22: =C22/G22 -> 0 | F22: =D22/G22 -> 72.061379 | G22: =_xlfn.XLOOKUP(P22,[3]Phidráulica!$A$10:$A$166,[3]Phidráulica!$J$10:$J$166) -> 2,3591 | H22: =_xlfn.XLOOKUP(A22,[4]Información_Técnica!$A$8:$A$36,[4]Información_Técnica!$F$8:$F$36) -> 16,86 | I22: =_xlfn.XLOOKUP(A22,[4]Información_Técnica!$A$8:$A$36,[4]Información_Técnica!$G$8:$G$36) -> 178.37 | J22: 0.84378676 | K22: =H22+J22*(I22-H22) -> 153.14 | L22: 0 | M22: =_xlfn.XLOOKUP(Q22,'[5]01_SERIE'!$H$14042:$H$16057,'[5]01_SERIE'!$K$14042:$K$16057) -> 207.91006 | N22: 30 | O22: =_xlfn.XLOOKUP(P22,[3]Phidráulica!$A$10:$A$166,[3]Phidráulica!$K$10:$K$166) -> Cuenta con embalse | P22: JAGUAS | Q22: =_xlfn.XLOOKUP(P22,[6]Detalle_Unidades!$F$2:$F$886,[6]Detalle_Unidades!$A$2:$A$886) -> JAGS | R22: 6.386694 | S22: -74.998222
A23: CALIMA | B23: VAL | C23: 0 | D23: =_xlfn.XLOOKUP(P23,[2]CapacidadEfectiva!$B$145:$B$179,[2]CapacidadEfectiva!$C$145:$C$179) -> 132 | E23: =C23/G23 -> 0 | F23: =D23/G23 -> 66.78472 | G23: =_xlfn.XLOOKUP(P23,[3]Phidráulica!$A$10:$A$166,[3]Phidráulica!$J$10:$J$166) -> 1,9765 | H23: =_xlfn.XLOOKUP(A23,[4]Información_Técnica!$A$8:$A$36,[4]Información_Técnica!$F$8:$F$36) -> 104,36 | I23: =_xlfn.XLOOKUP(A23,[4]Información_Técnica!$A$8:$A$36,[4]Información_Técnica!$G$8:$G$36) -> 529.3 | J23: 0.96439497 | K23: =H23+J23*(I23-H23) -> 514.17 | L23: 0 | M23: =_xlfn.XLOOKUP(Q23,'[5]01_SERIE'!$H$14042:$H$16057,'[5]01_SERIE'!$K$14042:$K$16057) -> 335.27587 | N23: 64 | O23: =_xlfn.XLOOKUP(P23,[3]Phidráulica!$A$10:$A$166,[3]Phidráulica!$K$10:$K$166) -> Cuenta con embalse | P23: CALIMA | Q23: =_xlfn.XLOOKUP(P23,[6]Detalle_Unidades!$F$2:$F$886,[6]Detalle_Unidades!$A$2:$A$886) -> CLMG | R23: 3.524585 | S23: -76.333665
A24: PRADO | B24: HTO | C24: 0 | D24: =_xlfn.XLOOKUP(P24,[2]CapacidadEfectiva!$B$145:$B$179,[2]CapacidadEfectiva!$C$145:$C$179) -> 51 | E24: =C24/G24 -> 0 | F24: =D24/G24 -> 102.34798 | G24: =_xlfn.XLOOKUP(P24,[3]Phidráulica!$A$10:$A$166,[3]Phidráulica!$J$10:$J$166) -> 0,4983 | H24: =_xlfn.XLOOKUP(A24,[4]Información_Técnica!$A$8:$A$36,[4]Información_Técnica!$F$8:$F$36) -> 327,82 | I24: =_xlfn.XLOOKUP(A24,[4]Información_Técnica!$A$8:$A$36,[4]Información_Técnica!$G$8:$G$36) -> 980.89 | J24: 0.67548655 | K24: =H24+J24*(I24-H24) -> 768.96 | L24: 0 | M24: =_xlfn.XLOOKUP(Q24,'[5]01_SERIE'!$H$14042:$H$16057,'[5]01_SERIE'!$K$14042:$K$16057) -> 306.56979 | N24: 3 | O24: =_xlfn.XLOOKUP(P24,[3]Phidráulica!$A$10:$A$166,[3]Phidráulica!$K$10:$K$166) -> Cuenta con embalse | P24: PRADO | Q24: =_xlfn.XLOOKUP(P24,[6]Detalle_Unidades!$F$2:$F$886,[6]Detalle_Unidades!$A$2:$A$886) -> PRDO | R24: 3.451501 | S24: -74.531129
A25: TRONERAS | B25: ANT | C25: 0 | D25: =_xlfn.XLOOKUP(P25,[2]CapacidadEfectiva!$B$145:$B$179,[2]CapacidadEfectiva!$C$145:$C$179) -> 40 | E25: =C25/G25 -> 0 | F25: =D25/G25 -> 60.304538 | G25: =_xlfn.XLOOKUP(P25,[3]Phidráulica!$A$10:$A$166,[3]Phidráulica!$J$10:$J$166) -> 0,6633 | H25: 8.45 | I25: 27.65 | J25: 0.596875 | K25: =H25+J25*(I25-H25) -> 19.91 | L25: 0 | M25: =_xlfn.XLOOKUP(Q25,'[5]01_SERIE'!$H$14042:$H$16057,'[5]01_SERIE'!$K$14042:$K$16057) -> 207.91006 | N25: 1 | O25: =_xlfn.XLOOKUP(P25,[3]Phidráulica!$A$10:$A$166,[3]Phidráulica!$K$10:$K$166) -> Cuenta con embalse | P25: TRONERAS | Q25: GTRG | R25: 6.7818 | S25: -75.2555
A26: LA GUACA | B26: BOG | C26: 0 | D26: =_xlfn.XLOOKUP(P26,[2]CapacidadEfectiva!$B$145:$B$179,[2]CapacidadEfectiva!$C$145:$C$179) -> 324 | E26: =C26/G26 -> 0 | F26: =D26/G26 -> 37.421173 | G26: =_xlfn.XLOOKUP(P26,[3]Phidráulica!$A$10:$A$166,[3]Phidráulica!$J$10:$J$166) -> 8,6582 | H26: 10.32 | I26: 228.43 | J26: 0.62491403 | K26: =H26+J26*(I26-H26) -> 146.62 | L26: 0 | M26: =_xlfn.XLOOKUP(Q26,'[5]01_SERIE'!$H$14042:$H$16057,'[5]01_SERIE'!$K$14042:$K$16057) -> 181.15488 | N26: 120 | O26: =_xlfn.XLOOKUP(P26,[3]Phidráulica!$A$10:$A$166,[3]Phidráulica!$K$10:$K$166) -> Cuenta con embalse | P26: LA GUACA | Q26: PGUG
A27: PARAISO | B27: BOG | C27: 0 | D27: =_xlfn.XLOOKUP(P27,[2]CapacidadEfectiva!$B$145:$B$179,[2]CapacidadEfectiva!$C$145:$C$179) -> 276 | E27: =C27/G27 -> 0 | F27: =D27/G27 -> 37.436419 | G27: =_xlfn.XLOOKUP(P27,[3]Phidráulica!$A$10:$A$166,[3]Phidráulica!$J$10:$J$166) -> 7,3725 | H27: 0 | I27: 0 | J27: 0 | K27: =H27+J27*(I27-H27) -> 0 | L27: 0 | M27: =_xlfn.XLOOKUP(Q27,'[5]01_SERIE'!$H$14042:$H$16057,'[5]01_SERIE'!$K$14042:$K$16057) -> 181.15488 | N27: 102 | O27: =_xlfn.XLOOKUP(P27,[3]Phidráulica!$A$10:$A$166,[3]Phidráulica!$K$10:$K$166) -> Cuenta con embalse | P27: PARAISO | Q27: PGUG
A28: GUADALUPE III | B28: ANT | C28: 0 | D28: =_xlfn.XLOOKUP(P28,[2]CapacidadEfectiva!$B$145:$B$179,[2]CapacidadEfectiva!$C$145:$C$179) -> 270 | E28: =C28/G28 -> 0 | F28: =D28/G28 -> 58.498538 | G28: =_xlfn.XLOOKUP(P28,[3]Phidráulica!$A$10:$A$166,[3]Phidráulica!$J$10:$J$166) -> 4,6155 | H28: 0 | I28: 0 | J28: 0 | K28: =H28+J28*(I28-H28) -> 0 | L28: 0 | M28: =_xlfn.XLOOKUP(Q28,'[5]01_SERIE'!$H$14042:$H$16057,'[5]01_SERIE'!$K$14042:$K$16057) -> 207.91006 | N28: 0 | O28: =_xlfn.XLOOKUP(P28,[3]Phidráulica!$A$10:$A$166,[3]Phidráulica!$K$10:$K$166) -> Cuenta con embalse | P28: GUADALUPE III | Q28: GTRG
A29: GUADALUPE IV | B29: ANT | C29: 0 | D29: =_xlfn.XLOOKUP(P29,[2]CapacidadEfectiva!$B$145:$B$179,[2]CapacidadEfectiva!$C$145:$C$179) -> 202 | E29: =C29/G29 -> 0 | F29: =D29/G29 -> 55.337917 | G29: =_xlfn.XLOOKUP(P29,[3]Phidráulica!$A$10:$A$166,[3]Phidráulica!$J$10:$J$166) -> 3,6503 | H29: 0 | I29: 0 | J29: 0 | K29: =H29+J29*(I29-H29) -> 0 | L29: 0 | M29: =_xlfn.XLOOKUP(Q29,'[5]01_SERIE'!$H$14042:$H$16057,'[5]01_SERIE'!$K$14042:$K$16057) -> 207.91006 | N29: 105 | O29: =_xlfn.XLOOKUP(P29,[3]Phidráulica!$A$10:$A$166,[3]Phidráulica!$K$10:$K$166) -> Cuenta con embalse | P29: GUADALUPE IV | Q29: GTRG
A30: DARIO VALENCIA SAMPER | B30: BOG | C30: 0 | D30: =_xlfn.XLOOKUP(P30,[2]CapacidadEfectiva!$B$145:$B$179,[2]CapacidadEfectiva!$C$145:$C$179) -> 150 | E30: =C30/G30 -> 0 | F30: =D30/G30 -> 18.818688 | G30: =_xlfn.XLOOKUP(P30,[3]Phidráulica!$A$10:$A$166,[3]Phidráulica!$J$10:$J$166) -> 7,9708 | H30: 0 | I30: 0 | J30: 0 | K30: =H30+J30*(I30-H30) -> 0 | L30: 0 | M30: =_xlfn.XLOOKUP(Q30,'[5]01_SERIE'!$H$14042:$H$16057,'[5]01_SERIE'!$K$14042:$K$16057) -> 25.320993 | N30: 40 | O30: =_xlfn.XLOOKUP(P30,[3]Phidráulica!$A$10:$A$166,[3]Phidráulica!$K$10:$K$166) -> Filo de agua | P30: DARIO VALENCIA SAMPER | Q30: =_xlfn.XLOOKUP(P30,[6]Detalle_Unidades!$F$2:$F$886,[6]Detalle_Unidades!$A$2:$A$886) -> DVS1
A31: SAN FRANCISCO | B31: CQR | C31: 0 | D31: =_xlfn.XLOOKUP(P31,[2]CapacidadEfectiva!$B$145:$B$179,[2]CapacidadEfectiva!$C$145:$C$179) -> 135 | E31: =C31/G31 -> 0 | F31: =D31/G31 -> 85.54591 | G31: =_xlfn.XLOOKUP(P31,[3]Phidráulica!$A$10:$A$166,[3]Phidráulica!$J$10:$J$166) -> 1,5781 | H31: 0 | I31: 0 | J31: 0 | K31: =H31+J31*(I31-H31) -> 0 | L31: 0 | M31: =_xlfn.XLOOKUP(Q31,'[5]01_SERIE'!$H$14042:$H$16057,'[5]01_SERIE'!$K$14042:$K$16057) -> 25.273335 | N31: 36 | O31: =_xlfn.XLOOKUP(P31,[3]Phidráulica!$A$10:$A$166,[3]Phidráulica!$K$10:$K$166) -> Filo de agua | P31: SAN FRANCISCO | Q31: =_xlfn.XLOOKUP(P31,[6]Detalle_Unidades!$F$2:$F$886,[6]Detalle_Unidades!$A$2:$A$886) -> SNFR
A32: AMOYA LA ESPERANZA | B32: HTO | C32: 0 | D32: =_xlfn.XLOOKUP(P32,[2]CapacidadEfectiva!$B$145:$B$179,[2]CapacidadEfectiva!$C$145:$C$179) -> 80 | E32: =C32/G32 -> 0 | F32: =D32/G32 -> 16.479895 | G32: =_xlfn.XLOOKUP(P32,[3]Phidráulica!$A$10:$A$166,[3]Phidráulica!$J$10:$J$166) -> 4,8544 | H32: 0 | I32: 0 | J32: 0 | K32: =H32+J32*(I32-H32) -> 0 | L32: 0 | M32: =_xlfn.XLOOKUP(Q32,'[5]01_SERIE'!$H$14042:$H$16057,'[5]01_SERIE'!$K$14042:$K$16057) -> 24.968161 | N32: 13.2 | O32: =_xlfn.XLOOKUP(P32,[3]Phidráulica!$A$10:$A$166,[3]Phidráulica!$K$10:$K$166) -> Filo de agua | P32: AMOYA LA ESPERANZA | Q32: =_xlfn.XLOOKUP(P32,[6]Detalle_Unidades!$F$2:$F$886,[6]Detalle_Unidades!$A$2:$A$886) -> MOY1
A33: CARLOS LLERAS | B33: ANT | C33: 0 | D33: =_xlfn.XLOOKUP(P33,[2]CapacidadEfectiva!$B$145:$B$179,[2]CapacidadEfectiva!$C$145:$C$179) -> 78 | E33: =C33/G33 -> 0 | F33: =D33/G33 -> 64.741036 | G33: =_xlfn.XLOOKUP(P33,[3]Phidráulica!$A$10:$A$166,[3]Phidráulica!$J$10:$J$166) -> 1,2048 | H33: 0 | I33: 0 | J33: 0 | K33: =H33+J33*(I33-H33) -> 0 | L33: 0 | M33: =_xlfn.XLOOKUP(Q33,'[5]01_SERIE'!$H$14042:$H$16057,'[5]01_SERIE'!$K$14042:$K$16057) -> 22.295988 | N33: 31.2 | O33: =_xlfn.XLOOKUP(P33,[3]Phidráulica!$A$10:$A$166,[3]Phidráulica!$K$10:$K$166) -> Filo de agua especial | P33: CARLOS LLERAS | Q33: =_xlfn.XLOOKUP(P33,[6]Detalle_Unidades!$F$2:$F$886,[6]Detalle_Unidades!$A$2:$A$886) -> CLL1
A34: BAJO ANCHICAYA | B34: VAL | C34: 0 | D34: =_xlfn.XLOOKUP(P34,[2]CapacidadEfectiva!$B$145:$B$179,[2]CapacidadEfectiva!$C$145:$C$179) -> 72 | E34: =C34/G34 -> 0 | F34: =D34/G34 -> 121.93057 | G34: =_xlfn.XLOOKUP(P34,[3]Phidráulica!$A$10:$A$166,[3]Phidráulica!$J$10:$J$166) -> 0,5905 | H34: 0 | I34: 0 | J34: 0 | K34: =H34+J34*(I34-H34) -> 0 | L34: 0 | M34: =_xlfn.XLOOKUP(Q34,'[5]01_SERIE'!$H$14042:$H$16057,'[5]01_SERIE'!$K$14042:$K$16057) -> 335.83327 | N34: 8 | O34: =_xlfn.XLOOKUP(P34,[3]Phidráulica!$A$10:$A$166,[3]Phidráulica!$K$10:$K$166) -> Cuenta con embalse | P34: BAJO ANCHICAYA | Q34: ALBG
A35: CUCUANA | B35: HTO | C35: 0 | D35: =_xlfn.XLOOKUP(P35,[2]CapacidadEfectiva!$B$145:$B$179,[2]CapacidadEfectiva!$C$145:$C$179) -> 56 | E35: =C35/G35 -> 0 | F35: =D35/G35 -> 9.4155626 | G35: =_xlfn.XLOOKUP(P35,[3]Phidráulica!$A$10:$A$166,[3]Phidráulica!$J$10:$J$166) -> 5,9476 | H35: 0 | I35: 0 | J35: 0 | K35: =H35+J35*(I35-H35) -> 0 | L35: 0 | M35: =_xlfn.XLOOKUP(Q35,'[5]01_SERIE'!$H$14042:$H$16057,'[5]01_SERIE'!$K$14042:$K$16057) -> 26.72118 | N35: 6 | O35: =_xlfn.XLOOKUP(P35,[3]Phidráulica!$A$10:$A$166,[3]Phidráulica!$K$10:$K$166) -> Filo de agua | P35: CUCUANA | Q35: =_xlfn.XLOOKUP(P35,[6]Detalle_Unidades!$F$2:$F$886,[6]Detalle_Unidades!$A$2:$A$886) -> CUC1
A36: ESCUELA DE MINAS | B36: ANT | C36: 0 | D36: =_xlfn.XLOOKUP(P36,[2]CapacidadEfectiva!$B$145:$B$179,[2]CapacidadEfectiva!$C$145:$C$179) -> 55 | E36: =C36/G36 -> 0 | F36: =D36/G36 -> 34.310667 | G36: =_xlfn.XLOOKUP(P36,[3]Phidráulica!$A$10:$A$166,[3]Phidráulica!$J$10:$J$166) -> 1,603 | H36: 0 | I36: 0 | J36: 0 | K36: =H36+J36*(I36-H36) -> 0 | L36: 0 | M36: =_xlfn.XLOOKUP(Q36,'[5]01_SERIE'!$H$14042:$H$16057,'[5]01_SERIE'!$K$14042:$K$16057) -> 22.295985 | N36: 24 | O36: =_xlfn.XLOOKUP(P36,[3]Phidráulica!$A$10:$A$166,[3]Phidráulica!$K$10:$K$166) -> Filo de agua | P36: ESCUELA DE MINAS | Q36: =_xlfn.XLOOKUP(P36,[6]Detalle_Unidades!$F$2:$F$886,[6]Detalle_Unidades!$A$2:$A$886) -> HMIN
A37: SAN MIGUEL | B37: ANT | C37: 0 | D37: =_xlfn.XLOOKUP(P37,[2]CapacidadEfectiva!$B$145:$B$179,[2]CapacidadEfectiva!$C$145:$C$179) -> 50 | E37: =C37/G37 -> 0 | F37: =D37/G37 -> 33.48289 | G37: =_xlfn.XLOOKUP(P37,[3]Phidráulica!$A$10:$A$166,[3]Phidráulica!$J$10:$J$166) -> 1,4933 | H37: 0 | I37: 0 | J37: 0 | K37: =H37+J37*(I37-H37) -> 0 | L37: 0 | M37: =_xlfn.XLOOKUP(Q37,'[5]01_SERIE'!$H$14042:$H$16057,'[5]01_SERIE'!$K$14042:$K$16057) -> 24.968159 | N37: 18.9 | O37: =_xlfn.XLOOKUP(P37,[3]Phidráulica!$A$10:$A$166,[3]Phidráulica!$K$10:$K$166) -> Filo de agua | P37: SAN MIGUEL | Q37: =_xlfn.XLOOKUP(P37,[6]Detalle_Unidades!$F$2:$F$886,[6]Detalle_Unidades!$A$2:$A$886) -> SMI1
A38: SALTO II | B38: BOG | C38: 0 | D38: =_xlfn.XLOOKUP(P38,[2]CapacidadEfectiva!$B$145:$B$179,[2]CapacidadEfectiva!$C$145:$C$179) -> 35 | E38: =C38/G38 -> 0 | F38: =D38/G38 -> 10.374674 | G38: =_xlfn.XLOOKUP(P38,[3]Phidráulica!$A$10:$A$166,[3]Phidráulica!$J$10:$J$166) -> 3,3736 | H38: 0 | I38: 0 | J38: 0 | K38: =H38+J38*(I38-H38) -> 0 | L38: 0 | M38: =_xlfn.XLOOKUP(Q38,'[5]01_SERIE'!$H$14042:$H$16057,'[5]01_SERIE'!$K$14042:$K$16057) -> 25.321271 | N38: 5 | O38: =_xlfn.XLOOKUP(P38,[3]Phidráulica!$A$10:$A$166,[3]Phidráulica!$K$10:$K$166) -> Filo de agua | P38: SALTO II | Q38: =_xlfn.XLOOKUP(P38,[6]Detalle_Unidades!$F$2:$F$886,[6]Detalle_Unidades!$A$2:$A$886) -> 2QEK
A39: ESMERALDA (CQR) | B39: CQR | C39: 0 | D39: =_xlfn.XLOOKUP(P39,[2]CapacidadEfectiva!$B$145:$B$179,[2]CapacidadEfectiva!$C$145:$C$179) -> 30 | E39: =C39/G39 -> 0 | F39: =D39/G39 -> 22.839741 | G39: =_xlfn.XLOOKUP(P39,[3]Phidráulica!$A$10:$A$166,[3]Phidráulica!$J$10:$J$166) -> 1,3135 | H39: 0 | I39: 0 | J39: 0 | K39: =H39+J39*(I39-H39) -> 0 | L39: 0 | M39: =_xlfn.XLOOKUP(Q39,'[5]01_SERIE'!$H$14042:$H$16057,'[5]01_SERIE'!$K$14042:$K$16057) -> 25.27334 | N39: 0 | O39: =_xlfn.XLOOKUP(P39,[3]Phidráulica!$A$10:$A$166,[3]Phidráulica!$K$10:$K$166) -> Filo de agua | P39: ESMERALDA | Q39: =_xlfn.XLOOKUP(P39,[6]Detalle_Unidades!$F$2:$F$886,[6]Detalle_Unidades!$A$2:$A$886) -> ESMR
A40: TUNJITA | B40: BOG | C40: 0 | D40: =_xlfn.XLOOKUP(P40,[2]CapacidadEfectiva!$B$145:$B$179,[2]CapacidadEfectiva!$C$145:$C$179) -> 19 | E40: =C40/G40 -> 0 | F40: =D40/G40 -> 7.7063476 | G40: =_xlfn.XLOOKUP(P40,[3]Phidráulica!$A$10:$A$166,[3]Phidráulica!$J$10:$J$166) -> 2,4655 | H40: 0 | I40: 0 | J40: 0 | K40: =H40+J40*(I40-H40) -> 0 | L40: 0 | M40: =_xlfn.XLOOKUP(Q40,'[5]01_SERIE'!$H$14042:$H$16057,'[5]01_SERIE'!$K$14042:$K$16057) -> 24.491585 | N40: 8.2 | O40: =_xlfn.XLOOKUP(P40,[3]Phidráulica!$A$10:$A$166,[3]Phidráulica!$K$10:$K$166) -> Filo de agua | P40: TUNJITA | Q40: =_xlfn.XLOOKUP(P40,[6]Detalle_Unidades!$F$2:$F$886,[6]Detalle_Unidades!$A$2:$A$886) -> TUJ1

Sheet Aportes
A1: Aportes - Aporte natural por embalse I(h,t)
A2: m3/s, dato diario de XM AporCaudal repartido uniformemente entre las 24 horas. El modelo convierte a Mm3 con k_q2v en el balance.
A4: hora | B4: GUAVIO | C4: SAN CARLOS | D4: ITUANGO | E4: CHIVOR | F4: SOGAMOSO | G4: PORCE III | H4: GUATAPE | I4: BETANIA | J4: PORCE II | K4: EL QUIMBO | L4: MIEL I | M4: ALTO ANCHICAYA | N4: URRA | O4: SALVAJINA | P4: LA TASAJERA | Q4: PLAYAS | R4: JAGUAS | S4: CALIMA | T4: PRADO | U4: GUATRON | V4: PAGUA
B5: m3/s | C5: m3/s | D5: m3/s | E5: m3/s | F5: m3/s | G5: m3/s | H5: m3/s | I5: m3/s | J5: m3/s | K5: m3/s | L5: m3/s | M5: m3/s | N5: m3/s | O5: m3/s | P5: m3/s | Q5: m3/s | R5: m3/s | S5: m3/s | T5: m3/s | U5: m3/s | V5: m3/s
A6: 1 | B6: 77.2 | C6: 9.62 | D6: 331.24 | E6: 164.37 | F6: 203.52 | G6: 9.32 | H6: 10.76 | I6: 199.58 | J6: 12.17 | K6: 336.37 | L6: 23.26 | M6: 17.43 | N6: 285.19 | O6: 65.29 | P6: 12.17 | Q6: 9.32 | R6: 19.1 | S6: 17.49 | T6: 20.32 | U6: 21.71 | V6: 41.96
A7: 2 | B7: 77.2 | C7: 9.62 | D7: 331.24 | E7: 164.37 | F7: 203.52 | G7: 9.32 | H7: 10.76 | I7: 199.58 | J7: 12.17 | K7: 336.37 | L7: 23.26 | M7: 17.43 | N7: 285.19 | O7: 65.29 | P7: 12.17 | Q7: 9.32 | R7: 19.1 | S7: 17.49 | T7: 20.32 | U7: 21.71 | V7: 41.96
A8: 3 | B8: 77.2 | C8: 9.62 | D8: 331.24 | E8: 164.37 | F8: 203.52 | G8: 9.32 | H8: 10.76 | I8: 199.58 | J8: 12.17 | K8: 336.37 | L8: 23.26 | M8: 17.43 | N8: 285.19 | O8: 65.29 | P8: 12.17 | Q8: 9.32 | R8: 19.1 | S8: 17.49 | T8: 20.32 | U8: 21.71 | V8: 41.96
A9: 4 | B9: 77.2 | C9: 9.62 | D9: 331.24 | E9: 164.37 | F9: 203.52 | G9: 9.32 | H9: 10.76 | I9: 199.58 | J9: 12.17 | K9: 336.37 | L9: 23.26 | M9: 17.43 | N9: 285.19 | O9: 65.29 | P9: 12.17 | Q9: 9.32 | R9: 19.1 | S9: 17.49 | T9: 20.32 | U9: 21.71 | V9: 41.96
A10: 5 | B10: 77.2 | C10: 9.62 | D10: 331.24 | E10: 164.37 | F10: 203.52 | G10: 9.32 | H10: 10.76 | I10: 199.58 | J10: 12.17 | K10: 336.37 | L10: 23.26 | M10: 17.43 | N10: 285.19 | O10: 65.29 | P10: 12.17 | Q10: 9.32 | R10: 19.1 | S10: 17.49 | T10: 20.32 | U10: 21.71 | V10: 41.96
A11: 6 | B11: 77.2 | C11: 9.62 | D11: 331.24 | E11: 164.37 | F11: 203.52 | G11: 9.32 | H11: 10.76 | I11: 199.58 | J11: 12.17 | K11: 336.37 | L11: 23.26 | M11: 17.43 | N11: 285.19 | O11: 65.29 | P11: 12.17 | Q11: 9.32 | R11: 19.1 | S11: 17.49 | T11: 20.32 | U11: 21.71 | V11: 41.96
A12: 7 | B12: 77.2 | C12: 9.62 | D12: 331.24 | E12: 164.37 | F12: 203.52 | G12: 9.32 | H12: 10.76 | I12: 199.58 | J12: 12.17 | K12: 336.37 | L12: 23.26 | M12: 17.43 | N12: 285.19 | O12: 65.29 | P12: 12.17 | Q12: 9.32 | R12: 19.1 | S12: 17.49 | T12: 20.32 | U12: 21.71 | V12: 41.96
A13: 8 | B13: 77.2 | C13: 9.62 | D13: 331.24 | E13: 164.37 | F13: 203.52 | G13: 9.32 | H13: 10.76 | I13: 199.58 | J13: 12.17 | K13: 336.37 | L13: 23.26 | M13: 17.43 | N13: 285.19 | O13: 65.29 | P13: 12.17 | Q13: 9.32 | R13: 19.1 | S13: 17.49 | T13: 20.32 | U13: 21.71 | V13: 41.96
A14: 9 | B14: 77.2 | C14: 9.62 | D14: 331.24 | E14: 164.37 | F14: 203.52 | G14: 9.32 | H14: 10.76 | I14: 199.58 | J14: 12.17 | K14: 336.37 | L14: 23.26 | M14: 17.43 | N14: 285.19 | O14: 65.29 | P14: 12.17 | Q14: 9.32 | R14: 19.1 | S14: 17.49 | T14: 20.32 | U14: 21.71 | V14: 41.96
A15: 10 | B15: 77.2 | C15: 9.62 | D15: 331.24 | E15: 164.37 | F15: 203.52 | G15: 9.32 | H15: 10.76 | I15: 199.58 | J15: 12.17 | K15: 336.37 | L15: 23.26 | M15: 17.43 | N15: 285.19 | O15: 65.29 | P15: 12.17 | Q15: 9.32 | R15: 19.1 | S15: 17.49 | T15: 20.32 | U15: 21.71 | V15: 41.96
A16: 11 | B16: 77.2 | C16: 9.62 | D16: 331.24 | E16: 164.37 | F16: 203.52 | G16: 9.32 | H16: 10.76 | I16: 199.58 | J16: 12.17 | K16: 336.37 | L16: 23.26 | M16: 17.43 | N16: 285.19 | O16: 65.29 | P16: 12.17 | Q16: 9.32 | R16: 19.1 | S16: 17.49 | T16: 20.32 | U16: 21.71 | V16: 41.96
A17: 12 | B17: 77.2 | C17: 9.62 | D17: 331.24 | E17: 164.37 | F17: 203.52 | G17: 9.32 | H17: 10.76 | I17: 199.58 | J17: 12.17 | K17: 336.37 | L17: 23.26 | M17: 17.43 | N17: 285.19 | O17: 65.29 | P17: 12.17 | Q17: 9.32 | R17: 19.1 | S17: 17.49 | T17: 20.32 | U17: 21.71 | V17: 41.96
... A29: 24 | B29: 77.2 | C29: 9.62 | D29: 331.24 | E29: 164.37 | F29: 203.52 | G29: 9.32 | H29: 10.76 | I29: 199.58 | J29: 12.17 | K29: 336.37 | L29: 23.26 | M29: 17.43 | N29: 285.19 | O29: 65.29 | P29: 12.17 | Q29: 9.32 | R29: 19.1 | S29: 17.49 | T29: 20.32 | U29: 21.71 | V29: 41.96

Sheet Renovables
A1: Renovables - Generacion solar y eolica
A2: La disponibilidad horaria va en la hoja Demanda o un perfil aparte.
A4: id | B4: nodo | C4: tipo | D4: capacidad | E4: codigo | F4: Latitud | G4: Longitud
C5: solar/eolica | D5: MW | F5: ° | G5: °
A6: PORTON DEL SOL | B6: ANT | C6: solar | D6: 102 | E6: =_xlfn.XLOOKUP(A6,[1]Detalle_Unidades!$B$2:$B$886,[1]Detalle_Unidades!$A$2:$A$886) -> 3IRX
A7: CARACOLI I | B7: ATL | C7: solar | D7: 50 | E7: =_xlfn.XLOOKUP(A7,[1]Detalle_Unidades!$B$2:$B$886,[1]Detalle_Unidades!$A$2:$A$886) -> 3INX
A8: GUAYEPO | B8: ATL | C8: solar | D8: 370 | E8: =_xlfn.XLOOKUP(A8,[1]Detalle_Unidades!$B$2:$B$886,[1]Detalle_Unidades!$A$2:$A$886) -> GYPO
A9: GUAYEPO III | B9: ATL | C9: solar | D9: 200 | E9: =_xlfn.XLOOKUP(A9,[1]Detalle_Unidades!$B$2:$B$886,[1]Detalle_Unidades!$A$2:$A$886) -> GYP3
A10: PARQUE SOLAR LA UNION | B10: CSU | C10: solar | D10: 100 | E10: =_xlfn.XLOOKUP(A10,[1]Detalle_Unidades!$B$2:$B$886,[1]Detalle_Unidades!$A$2:$A$886) -> 3IZ6
A11: PARQUE SOLAR PUERTA DE ORO | B11: CQR | C11: solar | D11: 300 | E11: =_xlfn.XLOOKUP(A11,[1]Detalle_Unidades!$B$2:$B$886,[1]Detalle_Unidades!$A$2:$A$886) -> PORO
A12: PARQUE SOLAR TEPUY | B12: CQR | C12: solar | D12: 83 | E12: =_xlfn.XLOOKUP(A12,[1]Detalle_Unidades!$B$2:$B$886,[1]Detalle_Unidades!$A$2:$A$886) -> TPUY
A13: EL PASO | B13: GCM | C13: solar | D13: 68 | E13: =_xlfn.XLOOKUP(A13,[1]Detalle_Unidades!$B$2:$B$886,[1]Detalle_Unidades!$A$2:$A$886) -> EPFV
A14: FUNDACION | B14: GCM | C14: solar | D14: 100 | E14: =_xlfn.XLOOKUP(A14,[1]Detalle_Unidades!$B$2:$B$886,[1]Detalle_Unidades!$A$2:$A$886) -> 3HF5
A15: LATAM SOLAR LA LOMA | B15: GCM | C15: solar | D15: 150 | E15: =_xlfn.XLOOKUP(A15,[1]Detalle_Unidades!$B$2:$B$886,[1]Detalle_Unidades!$A$2:$A$886) -> 3DDT
A16: SHANGRI LA | B16: HTO | C16: solar | D16: 160 | E16: =_xlfn.XLOOKUP(A16,[1]Detalle_Unidades!$B$2:$B$886,[1]Detalle_Unidades!$A$2:$A$886) -> 4YCF
A17: LA MATA | B17: NDS | C17: solar | D17: 80 | E17: =_xlfn.XLOOKUP(A17,[1]Detalle_Unidades!$B$2:$B$886,[1]Detalle_Unidades!$A$2:$A$886) -> MATA
A18: SUNNORTE | B18: NDS | C18: solar | D18: 35 | E18: =_xlfn.XLOOKUP(A18,[1]Detalle_Unidades!$B$2:$B$886,[1]Detalle_Unidades!$A$2:$A$886) -> 3IQA

Sheet Renov_Perfil
A1: Renov_Perfil - Disponibilidad horaria de generacion renovable
A2: Estructura {hora x recurso}. Fraccion de la capacidad instalada (0-1).
A4: hora | B4: 3IRX | C4: 3INX | D4: GYPO | E4: GYP3 | F4: 3IZ6 | G4: PORO | H4: TPUY | I4: EPFV | J4: 3HF5 | K4: 3DDT | L4: 4YCF | M4: MATA | N4: 3IQA
B5: frac | C5: frac | D5: frac | E5: frac | F5: frac | G5: frac | H5: frac | I5: frac | J5: frac | K5: frac | L5: frac | M5: frac | N5: frac
A6: 1 | B6: 0 | C6: 0 | D6: 0 | E6: 0 | F6: 0 | G6: 0 | H6: 0 | I6: 0 | J6: 0 | K6: 0 | L6: 0 | M6: 0 | N6: 0
A7: 2 | B7: 0 | C7: 0 | D7: 0 | E7: 0 | F7: 0 | G7: 0 | H7: 0 | I7: 0 | J7: 0 | K7: 0 | L7: 0 | M7: 0 | N7: 0
A8: 3 | B8: 0 | C8: 0 | D8: 0 | E8: 0 | F8: 0 | G8: 0 | H8: 0 | I8: 0 | J8: 0 | K8: 0 | L8: 0 | M8: 0 | N8: 0
A9: 4 | B9: 0 | C9: 0 | D9: 0 | E9: 0 | F9: 0 | G9: 0 | H9: 0 | I9: 0 | J9: 0 | K9: 0 | L9: 0 | M9: 0 | N9: 0
A10: 5 | B10: 0 | C10: 0 | D10: 0 | E10: 0 | F10: 0 | G10: 0 | H10: 0 | I10: 0 | J10: 0 | K10: 0 | L10: 0 | M10: 0 | N10: 0
A11: 6 | B11: 0 | C11: 0.001384 | D11: 0.00036908108 | E11: 0 | F11: 0.0003844 | G11: 0 | H11: 0 | I11: 0.0011713235 | J11: 0.0034272 | K11: 0 | L11: 0 | M11: 0 | N11: 0
A12: 7 | B12: 0.17582245 | C12: 0.1032108 | D12: 0.15227819 | E12: 0 | F12: 0.1706981 | G12: 0.14253307 | H12: 0.21020892 | I12: 0.20002662 | J12: 0.1710297 | K12: 0.12295747 | L12: 0.058525937 | M12: 0.09663875 | N12: 0.042192
A13: 8 | B13: 0.59026716 | C13: 0.4172694 | D13: 0.46810405 | E13: 0.09908625 | F13: 0.5868383 | G13: 0.5725076 | H13: 0.71445289 | I13: 0.46684206 | J13: 0.5848869 | K13: 0.24818153 | L13: 0.48498831 | M13: 0.52739837 | N13: 0.25044714
A14: 9 | B14: 0.76800196 | C14: 0.5756992 | D14: 0.66132565 | E14: 0.6924771 | F14: 0.8383498 | G14: 0.77477123 | H14: 0.87469723 | I14: 0.73631044 | J14: 0.746588 | K14: 0.56385833 | L14: 0.8426025 | M14: 0.81981075 | N14: 0.52585114
A15: 10 | B15: 0.74432725 | C15: 0.5296518 | D15: 0.55253868 | E15: 0.5993843 | F15: 0.9041597 | G15: 0.84425827 | H15: 0.84543675 | I15: 0.80787029 | J15: 0.8036675 | K15: 0.50324033 | L15: 0.92421219 | M15: 0.90699725 | N15: 0.724166
A16: 11 | B16: 0.8799302 | C16: 0.6861602 | D16: 0.69391711 | E16: 0.7708363 | F16: 0.5155328 | G16: 0.90618707 | H16: 0.97647265 | I16: 0.85916794 | J16: 0.8040537 | K16: 0.6764508 | L16: 0.90040406 | M16: 0.96598075 | N16: 0.72896343
A17: 12 | B17: 0.90511971 | C17: 0.754981 | D17: 0.773873 | E17: 0.85872845 | F17: 0.8980619 | G17: 0.9337209 | H17: 0.99824892 | I17: 0.91597765 | J17: 0.8041306 | K17: 0.67590907 | L17: 0.96240981 | M17: 0.8729625 | N17: 0.519636
... A29: 24 | B29: 0 | C29: 0 | D29: 0 | E29: 0 | F29: 0 | G29: 0 | H29: 0 | I29: 0 | J29: 0 | K29: 0 | L29: 0 | M29: 0 | N29: 0

Sheet Demanda
A1: Demanda - Perfil horario de demanda por nodo
A2: Estructura {hora x nodo}, igual a la hoja 'load' de XM/Alvaro. Solo columnas de nodos con carga. Filas = horas del horizonte.
A4: hora | B4: ANT | C4: ARA | D4: ATL | E4: BOG | F4: BOL | G4: BYC | H4: CQR | I4: CAQ | J4: CAN | K4: CER | L4: CSU | M4: GCM | N4: HTO | O4: MET | P4: NDS | Q4: PUT | R4: SAN | S4: VAL
B5: MW | C5: MW | D5: MW | E5: MW | F5: MW | G5: MW | H5: MW | I5: MW | J5: MW | K5: MW | L5: MW
A6: 1
A7: 2
A8: 3
A9: 4
A10: 5
A11: 6
A12: 7
A13: 8
A14: 9
A15: 10
A16: 11
A17: 12
... A29: 24

Sheet BESS_Cand
A1: BESS_Cand - Nodos candidatos a instalar BESS
A2: Vacia si no se consideran BESS. duracion = relacion energia/potencia.
A4: nodo | B4: costo_inst | C4: costo_pot | D4: costo_ene | E4: eff_ch | F4: eff_dis | G4: self_dis | H4: soc_ini | I4: duracion
B5: USD | C5: USD/MW | D5: USD/MWh | E5: 0-1 | F5: 0-1 | G5: 0-1 | H5: frac | I5: h

Sheet FACTS_Cand
A1: FACTS_Cand - Lineas candidatas a instalar TCSC
A2: Vacia si no se consideran FACTS. 'linea' debe existir en Lineas.
A4: linea | B4: habilitada
