Workbook
Name _Hlk45015439: EquivUnid!$B$2
Name _Hlk75254411: Restricciones!$D$113
Name _Hlk75254411: 'Restricciones nuevas'!#REF!
Name _Hlk75254411: 'Restricciones SDL'!#REF!
Name _Hlk75254411: Restricciones_Futuras!#REF!

Sheet LEEME
B2: En esta hoja usted encontrará información de utilidad para entender el presente archivo. El entendimiento del contenido y organización aquí presente permitirá la explotación de la información suministrada con automatismos. Esta hoja pretende ser una ayuda para la claridad de cada hoja, columna y fila con el fin de facilitar el fin anterior (que sea usada con automatismos). Por favor, tomese el tiempo de leer cuidadosamente la descripción de cada hoja.
B13: Hoja | C13: Descripción
B14: LEEME | C14: Explicación del contenido de este archivo.
B15: LimitesImport | C15: Lista de las importaciones máximas permitidas por área del SIN. La columna "ElemName" contiene los nombres de los elementos por donde se mide la importación al área. La columna "FKEYS" contiene los foreign keys de PowerFactory para cada elemento por el cual se mide la importación. El signo + o - al frente del foreign key indica la dirección del flujo de potencia con respecto al nombre del mismo. La columna "LimiteSup [MW]" indica el máximo valor permitido.
B16: Restricciones | C16: Lista detallada de las restricciones eléctricas por área y subárea. La columna "FKEYS" contiene los foreign keys de PowerFactory para cada elemento involucrado en las restricciones listadas. El signo + o - al frente del foreign key indica la dirección del flujo de potencia con respecto al nombre del mismo. La columna "Corte [MW]" indica el máximo valor permitido para la suma de todas las potencias (con sus direcciones de flujo) en cada corte.
B17: Restricciones_Futuras | C17: Lista detallada de las restricciones eléctricas por área y subárea que se espera que se materialicen en el horizonte del mediano plazo. Esto está supeditado a la entrada de proyectos, crecimiento de demanda y otros factores. Para más información, por favor, remitirse al IPOEMP vigente.
B18: ReqUnidades_Caribe2 | C18: Tabla con los requerimientos de unidades en la subárea Caribe2 (compuesta por Atlántico, Bolivar y GCM). La demanda listada debe ser medida en estas tres subáreas. Las dos últimas columnas representan la condición del número de unidades a adicionar a la base (columna con el nombre de la subárea o área). Esta condición se refiere a la importación por medio de los elementos reportados en la hoja "Info_Elems_Condiciones". Para más detalle consultar el IPOEMP vigente.
B19: ReqUnidades_GCM | C19: Tabla con los requerimientos de unidades en la subárea GCM. La demanda listada debe ser medida en esta subárea.
B20: ReqUnidades_Suroccidental | C20: Tabla con los requerimientos de unidades en el área Suroccidental. La demanda listada debe ser medida la totalidad del área.
B21: ReqUnidades_BoyacaCasanare | C21: Tabla con los requerimientos de unidades en la subárea Boyacá-Casanare. La demanda listada debe ser medida en la subárea Boyacá-Casanare, por esta razón se lista esta única subárea en dicha tabla. Para el requerimiento de Yopal se debe validar que dentro del total para el segmento de demanda, exista al menos el número de unidades requeridas entre las que están conectadas a este nodo. Para más detalle consultar el IPOEMP vigente. Nota para el admin de este doc: En Nordeste el nombre de la columna que condiciona las yopales debe ser "1. YOPALES (2,3,4 y 5)". No cambiar.
B22: ReqUnidades_NSantander | C22: Tabla con los requerimientos de unidades en la subárea Norte de Santander. La demanda listada debe ser medida en la subárea Norte de Santander, por esta razón se lista esta única subárea en dicha tabla. Para más detalle consultar el IPOEMP vigente.
B23: ReqUnidades_Antioquia | C23: Tabla con los requerimientos de unidades en el área Suroccidental. La demanda listada debe ser medida la totalidad del área. Los requerimientos se listan por las subáreas Norte y Oriente de Antioquia.
B24: ReqUnidades_Oriental | C24: Tabla con los requerimientos de unidades en el área Oriental. La demanda listada debe ser medida en la totalidad del área. Las tres últimas columnas representan la condición del número de unidades a adicionar a la base (columna con el nombre de la subárea o área). Esta condición se refiere a la importación por medio de los elementos reportados en la hoja "Info_Elems_Condiciones". Para más detalle consultar el IPOEMP vigente.
... B30: Gráficas | C30: Esta hoja contiene información de resumen de las restricciones eléctricas listadas en la hoja "Restricciones". La información contenida aquí tiene un propósito descriptivo.
B31: Para mayor información remitirse al IPOEMP vigente.

Sheet LimitesImport
A1: Area | B1: ElemName | C1: FKEYS | D1: LimiteSup [MW]
A2: Caribe | B2: Porce III – Cerromatoso 500 kV + Primavera – Cerromatoso 500 kV + Ocaña – La Loma 500 kV + Antioquia - Cerromatoso 1 y 2 500 kV | C2: "-lrtCmt3Shn15","-LrtCmtPmv51r", "-LinOcaLom512, "+LinAntCer51r","+LinAntCer52r" | D2: 2000
A3: Oriental | B3: Primavera – Bacatá 500 Kv + La Virginia – Nueva Esperanza 500 kV | C3: "-PmvBac500","+ExpLne0135" | D3: 1320
A4: Nordeste
A5: Suroccidental | B5: Heliconia - La Virginia 500 kV + La Virginia - San Carlos 500 Kv + La Virginia - Nueva Esperanza 500 Kv | C5: "+LinVirMed51r","-LrtVirSca51r","-ExpLne0135" | D5: 650
A6: Antioquia

Sheet Restricciones
A1: Area | B1: Subárea | C1: Número | D1: Restricción | E1: FKEYS | F1: Corte [MW] | G1: ESPS | H1: Escenario | I1: Recomendación operativa | J1: Proyecto de Expansión Mediano plazo | K1: Codigo | L1: Acciones de corto plazo recomendadas | M1: Generación a limitar | N1: Generación a subir | O1: Estado restricción | P1: Origen de la restricción
A2: Caribe | B2: Caribe | C2: 1 | D2: Antioquia – Cerromatoso 1 500 kV + Antioquia – Cerromatoso 2 500 kV + Porce 3 – Cerromatoso 500 kV + Primavera – Cerromatoso 500 kV + Ocaña – La Loma 500 kV | E2: "-lrtCmt3Shn15","-LrtCmtPmv51r","-LinOcaLom512","+LinAntCer51r","+LinAntCer52r" | F2: 2000 | G2: NO | H2: Alta importación de potencia del área Caribe. | I2: • Programar generación de seguridad al interior del área Caribe de manera que se cubra el límite de importación y el requerimiento del número de unidades equivalentes • Hacer un uso adecuado de taps de transformadores y compensación reactiva del área y mantener adecuados perfiles de tensión en estado normal de operación. • En caso de que no se puedan programar las unidades equivalentes mínimas requeridas, es necesario disminuir el intercambio de potencia entre el interior y el área Caribe 2 (alrededor de 100 MW por unidad), verficando en cada caso la respuesta del sistema en estado normal de operación y ante N-1 | J2: Aumenta la capacidad de importación PTRA00322 Subestación Toluviejo 220 kV PTRA00482 Circuito Cuestecitas – La Loma 500 kV PTRA00325 UPME 06 - 2017 S/E Colectora 1 500 kV y circuitos asociados PTRA05304 Nueva Toluviejo 220/110 kV PTRA01139 UPME 06-2021 Subestación Carreto 500 kV y PTRA02158 Carreto 66 kV | K2: PTRA00203, PTRA00322, PTRA00482, PTRA00325, PTRA05304, PTRA01139, | M2: No aplica | N2: Guajira, Termonorte, Tebsa, Barranquilla, Flores 1, Flores 4, Candelaria, Cartagena, Proeléctrica | O2: 3 | P2: 0
A3: Caribe | B3: Caribe | C3: 2 | D3: Antioquia – Cerromatoso 1 500 kV + Antioquia – Cerromatoso 2 500 kV + Porce 3 – Cerromatoso 500 kV + Primavera – Cerromatoso 500 kV + Ocaña – La Loma 500 kV | E3: "+lrtCmt3Shn15","+LrtCmtPmv51r","+LinOcaLom512","-LinAntCer51r","-LinAntCer52r" | F3: 2800 | G3: NO | H3: Alta exportación de potencia del área Caribe. | I3: • Limitar la generacion en Caribe | J3: Aumenta la capacidad de importación PTRA00322 Subestación Toluviejo 220 kV PTRA00482 Circuito Cuestecitas – La Loma 500 kV PTRA00325 UPME 06 - 2017 S/E Colectora 1 500 kV y circuitos asociados PTRA05304 Nueva Toluviejo 220/110 kV PTRA01139 UPME 06-2021 Subestación Carreto 500 kV y PTRA02158 Carreto 66 kV | K3: PTRA00203, PTRA00322, PTRA00482, PTRA00325, PTRA05304, PTRA01139, | M3: Guajira, Termonorte, Tebsa, Barranquilla, Flores 1, Flores 4, Candelaria, Cartagena, Proeléctrica | N3: No aplica | O3: 3 | P3: 0
A4: Caribe | B4: Caribe2 | C4: 1 | D4: Chinú – Sabana 1 + Chinú – Sabana 2 500 kV + Ocaña – La Loma 500 kV + Chinú - El Copey 500 kV + Toluviejo – Bolívar 220 kV | E4: "+LrtSabChn51r","+LrtSabchn52r","-LinOcaLom512","+LinChnCop51T", "-LinBolTvj21" | F4: 1400 | G4: NO | H4: Alta importación de potencia del área Caribe 2. | I4: • Programar generación de seguridad al interior del área Caribe de manera que se cubra el límite de importación y el número de unidades • Hacer un uso adecuado de taps de transformadores y compensación reactiva del área y mantener adecuados perfiles de tensión en estado normal de operación. • En caso de que no se puedan programar las unidades equivalentes mínimas requeridas, es necesario disminuir el intercambio de potencia entre el interior y el área Caribe 2 (alrededor de 100 MW por unidad),vericando en cada caso la respuesta del sistema en estado normal de operación y ante N-1 | J4: Aumenta la capacidad de importación PTRA00322 Subestación Toluviejo 220 kV PTRA00482 Circuito Cuestecitas – La Loma 500 kV PTRA00325 UPME 06 - 2017 S/E Colectora 1 500 kV y circuitos asociados PTRA05304 Nueva Toluviejo 220/110 kV PTRA01139 UPME 06-2021 Subestación Carreto 500 kV y PTRA02158 Carreto 66 kV | K4: PTRA00203, PTRA00322, PTRA00482, PTRA00325, PTRA05304, PTRA01139, | M4: No aplica | N4: Guajira, Termonorte, Tebsa, Barranquilla, Flores 1, Flores 4, Candelaria, Cartagena, Proeléctrica | O4: 3 | P4: 0
A5: Caribe | B5: Caribe2 | C5: 2 | D5: Chinú – Sabana 1 + Chinú – Sabana 2 500 kV + Ocaña – La Loma 500 kV + Chinú - El Copey 500 kV + Toluviejo – Bolívar 220 kV | E5: "-LrtSabChn51r","-LrtSabchn52r","+LinOcaLom512","-LinChnCop51T", "+LinBolTvj21" | F5: 2200 | G5: NO | H5: Alta exportacion de potencia del área Caribe 2. | I5: • Limitar la generacion en Caribe 2 | J5: Aumenta la capacidad de importación PTRA00322 Subestación Toluviejo 220 kV PTRA00482 Circuito Cuestecitas – La Loma 500 kV PTRA00325 UPME 06 - 2017 S/E Colectora 1 500 kV y circuitos asociados PTRA05304 Nueva Toluviejo 220/110 kV PTRA01139 UPME 06-2021 Subestación Carreto 500 kV y PTRA02158 Carreto 66 kV | K5: PTRA00203, PTRA00322, PTRA00482, PTRA00325, PTRA05304, PTRA01139, | M5: Guajira, Termonorte, Tebsa, Barranquilla, Flores 1, Flores 4, Candelaria, Cartagena, Proeléctrica | N5: No aplica | O5: 3 | P5: 0
A6: Caribe | B6: Atlántico | C6: 1 | D6: Baja tensión en nodos Atlántico 110 kV en red completa y ante N-1 | H6: Alta demanda y baja generación al interior de la subárea | I6: Si bien, la subárea no tienen requerimiento de unidades definidos, se recomienda evaluar para demanda de Caribe 2 mayor 1671 MW la pertinencia de programar unidades al interior | J6: No hay obra de expansión definida en el horizonte de Mediano Plazo. (PTRA05299: Nueva Río 220/110 kV) Mitiga pero no elimina la restricción | M6: No aplica | N6: Tebsa, Barranquilla, Flores 1, Flores 4 | O6: 3 | P6: 0
A7: Caribe | B7: Atlántico | C7: 2 | D7: Tebsa 1 220/110 kV / Tebsa 2 220/110 kV + Tebsa 5 220/110 kV | E7: "+TrfTbs2146","+TrfTbs2017","+TrfTbs215" | F7: 220 | G7: SI | H7: Alta generación en Tebsa 220 kV y Barranquilla. Baja generación en 110 kV y Flores 4 220 kV. | I7: Realizar balance de generación entre Flores y Tebsa 220 kV + Barranquilla y/o programar generación en la red de 110 kV. En caso de no ser suficiente validar la suficiencia del ESPS asociado a sobrecarga de la transformación Tebsa 220/110 kV | J7: PTRA05299: Nueva Río 220/110 kV | K7: PTRA05299 | M7: Tebsa 220 kV, Barraquilla 220kV | N7: Tebsa 110 kV, Flores 1, Flores 4 | O7: 0 | P7: 0
A8: Caribe | B8: Atlántico | C8: 3 | D8: Tebsa 2 220/110 kV / Tebsa 1 220/110 kV + Tebsa 5 220/110 kV | E8: "+TrfTbs2017","+TrfTbs2146,"+TrfTbs215" | F8: 220 | G8: SI | H8: Alta generación en Tebsa 220 kV y Barranquilla. Baja generación en 110 kV y Flores 4 220 kV. | I8: Realizar balance de generación entre Flores y Tebsa 220 kV + Barranquilla y/o programar generación en la red de 110 kV. En caso de no ser suficiente validar la suficiencia del ESPS asociado a sobrecarga de la transformación Tebsa 220/110 kV | J8: PTRA05299: Nueva Río 220/110 kV | K8: PTRA05299 | M8: Tebsa 220 kV, Barraquilla 220kV | N8: Tebsa 110 kV, Flores 1, Flores 4 | O8: 0 | P8: 0
A9: Caribe | B9: Atlántico | C9: 4 | D9: Tebsa 5 220/110 kV / Tebsa 1 220/110 kV + Tebsa 2 220/110 kV | E9: "+TrfTbs215","+TrfTbs2146,"+TrfTbs2017" | F9: 230 | G9: SI | H9: Alta generación en Tebsa 220 kV y Barranquilla. Baja generación en 110 kV y Flores 4 220 kV. | I9: Realizar balance de generación entre Flores y Tebsa 220 kV + Barranquilla y/o programar generación en la red de 110 kV. En caso de no ser suficiente validar la suficiencia del ESPS asociado a sobrecarga de la transformación Tebsa 220/110 kV | J9: PTRA05299: Nueva Río 220/110 kV | K9: PTRA05299 | M9: Tebsa 220 kV, Barraquilla 220kV | N9: Tebsa 110 kV, Flores 1, Flores 4 | O9: 0 | P9: 0
A10: Caribe | B10: Atlántico | C10: 5 | D10: Termoflores 1 220/110 kV / Flores 2 220/110 kV | E10: "+TrfFls2011","+TrfFls2012" | F10: 220 | G10: NO | H10: Alta generación en Flores 4 a nivel de 220 kV y baja generación de Flores 1 y Flores 4 a nivel de 110 kV, Tebsa y Barranquilla | I10: Realizar balance de generación entre Flores y Tebsa y/o programar generación a nivel de 110 kV. El valor del corte dependerá del escenario de operación y si la S/E Termoflores 110 kV se opera acoplada o desacoplada | J10: PTRA05299: Nueva Río 220/110 kV | K10: PTRA05299 | M10: Flores 4 220 kV | N10: Tebsa, Barranquilla, Flores 1, Flores 4 110 kV | O10: 3 | P10: 0
A11: Caribe | B11: Atlántico | C11: 6 | D11: Flores 2 220/110 kV / Termoflores 1 220/110 kV | E11: "+TrfFls2012","+TrfFls2011" | F11: 215 | G11: NO | H11: Alta generación en Flores 4 a nivel de 220 kV y baja generación de Flores 1 y Flores 4 a nivel de 110 kV, Tebsa y Barranquilla | I11: Realizar balance de generación entre Flores y Tebsa y/o programar generación a nivel de 110 kV. El valor del corte dependerá del escenario de operación y si la S/E Termoflores 110 kV se opera acoplada o desacoplada | J11: PTRA05299: Nueva Río 220/110 kV | K11: PTRA05299 | M11: Flores 4 220 kV | N11: Tebsa, Barranquilla, Flores 1, Flores 4 110 kV | O11: 3 | P11: 0
A12: Caribe | B12: Atlántico | C12: 7 | D12: Termoflores II - Oasis 110 kV / Flores 2 220/110 kV | E12: "-CI0890","+TrfFls2012" | F12: 220 | G12: NO | H12: Con Termoflores 110 kV desacoplada. Alta generación en Flores 4 y baja generación en Flores 1, Tebsa y Barranquilla | I12: Con Termoflores 110 kV desacoplada. Realizar balance de generación entre Flores 4, Tebsa y Barranquilla y/o programar generación en Flores 1. El valor del corte dependerá de la generación que se utilice para cubrirlo | J12: PTRA05299: Nueva Río 220/110 kV | K12: PTRA05299 | M12: Flores 4 | N12: Tebsa, Barranquilla, Flores 1 | O12: 3 | P12: 0
A13: Caribe | B13: Atlántico | C13: 8 | D13: Flores 2 220/110 kV / Termoflores II - Oasis 1 110 kV | E13: "+TrfFls2012","-CI0890" | F13: 200 | G13: SI | H13: Con Termoflores 110 kV desacoplada Alta generación en Flores 4 y baja en Flores 1, Tebsa y Barranquilla | I13: Con Termoflores 110 kV desacoplada. Aumentar generación en Flores 1. Disminuir en Flores IV. Aumentar en Tebsa - Barranquilla. De no ser posible controlar esta restricción con generación, verificar suficiencia ESPS sobrecargas Termoflores II – Oasis 110 kV | J13: PTRA05299: Nueva Río 220/110 kV (mitiga pero no elimina) | M13: Flores 4 | N13: Flores 1, Tebsa, Barranquilla | O13: 0 | P13: 0
A14: Caribe | B14: Atlántico | C14: 9 | D14: Termoflores - Oasis 2 110 (acople abierto) | E14: "-CI0890" | F14: 160 | G14: SI | H14: Alta generación en Flores 1 y Flores 4 con baja generación en Tebsa y Barranquilla | I14: • Balance de generación entre Flores 1 - Flores 4 y Tebsa - Barranquilla. | J14: No hay obra de expansión definida en el horizonte de Mediano Plazo. | L14: Operar acoplada la subestación Termoflores 110 kV. Recomendación al OR y UPME aumentar capacidad de CC de las subestaciones Flores, Centro, Oasis 110 kV | M14: Flores 1, Flores 4 | N14: Tebsa, Barranquilla | O14: 3 | P14: 1
A15: Caribe | B15: Atlántico | C15: 10 | D15: Termoflores - Las Flores 2 110 / Termoflores - Las Flores 1 110 kV | E15: "-CI0564,"-LinLflTfl11" | F15: 140 | G15: SI | H15: Alta generación en Flores 1 y Flores 4 con baja generación en Tebsa y Barranquilla | I15: • Balance de generación entre Flores 1 - Flores 4 y Tebsa - Barranquilla. | J15: No hay obra de expansión definida en el horizonte de Mediano Plazo. (PTRA05299: Nueva Río 220/110 kV) mitiga pero no elimina | L15: Evaluar el aumeto de capacidad de transporte de corriente del circuito | M15: Flores 1, Flores 4 | N15: Tebsa, Barranquilla | O15: 3 | P15: 0
A16: Caribe | B16: Atlántico | C16: 11 | D16: Termoflores - Las Flores 1 110 / Termoflores - Las Flores 2 110 kV | E16: "-LinLflTfl11","-CI0564 | F16: 130 | G16: SI | H16: Alta generación en Flores 1 y Flores 4 con baja generación en Tebsa y Barranquilla | I16: • Balance de generación entre Flores 1 - Flores 4 y Tebsa - Barranquilla. | J16: No hay obra de expansión definida en el horizonte de Mediano Plazo. (PTRA05299: Nueva Río 220/110 kV) mitiga pero no elimina | M16: Flores 1, Flores 4 | N16: Tebsa, Barranquilla | O16: 3 | P16: 0
A17: Caribe | B17: Atlántico | C17: 12 | D17: Tebsa - Caracoli 1 220 / Tebsa - El Rio 1 220 | E17: "-LinCrcTeb21","-LinRioTeb21" | F17: 432 | G17: NO | H17: Maximo despacho en Tebsa y Barranquilla sin Flores 1 y Flores 4. En demanda máxima. | I17: • Disminuir la impedancia de los dispositivos SSSC ubicados en las lineas Sabanalarga - Tebsa 1 y 2 220 kV. • Aumentar la impedancia de los dispositivos SSSC ubicados en las lineas Nv Barranquilla - Termoflores 1 y 2 220 kV. (Aplicar cuidando las corrientes de enganche del dispositivo). • Balance de generacion entre Flores 1 - Flores 4 y Tebsa - Barranquilla. | J17: No hay obra de expansión definida en el horizonte de Mediano Plazo. | K17: PTRA05299 | M17: Tebsa, Barranquilla | N17: Flores 1, Flores 4 | O17: 3 | P17: 0
A18: Caribe | B18: Atlántico | C18: 13 | D18: Sobrecarga Tebsa 1 220/110 kV | E18: "+TrfTbs2146" | F18: 93 | G18: NO | H18: Mínima generación en los recursos conectados en nodos de 110 kV Alta demanda al interior de Atlántico | I18: • Programar generación en la red de 110 kV. * La transformación Tebsa 220/110 kV cuenta con un ESP ante contingencia de uno de los transformadores, sin embargo, debido a desviaciones de la demanda que se han presentado en la operación en tiempo real, es necesario cuidar este corte en red completa. | J18: PTRA05299: Nueva Río 220/110 kV | K18: PTRA05299 | M18: Tebsa 220 kV, Barraquilla 220kV | N18: Tebsa 110 kV, Flores 1, Flores 4 | O18: 1 | P18: 1
A19: Caribe | B19: Atlántico | C19: 14 | D19: Sobrecarga Tebsa 2 220/110 kV | E19: "+TrfTbs2017" | F19: 93 | G19: NO | H19: Mínima generación en los recursos conectados en nodos de 110 kV Alta demanda al interior de Atlántico | I19: • Programar generación en la red de 110 kV. * La transformación Tebsa 220/110 kV cuenta con un ESP ante contingencia de uno de los transformadores, sin embargo, debido a desviaciones de la demanda que se han presentado en la operación en tiempo real, es necesario cuidar este corte en red completa. | J19: PTRA05299: Nueva Río 220/110 kV | K19: PTRA05299 | M19: Tebsa 220 kV, Barraquilla 220kV | N19: Tebsa 110 kV, Flores 1, Flores 4 | O19: 1 | P19: 1
A20: Caribe | B20: Atlántico | C20: 15 | D20: Sobrecarga Tebsa 5 220/110 kV | E20: "+TrfTbs215" | F20: 93 | G20: NO | H20: Mínima generación en los recursos conectados en nodos de 110 kV Alta demanda al interior de Atlántico | I20: • Programar generación en la red de 110 kV. * La transformación Tebsa 220/110 kV cuenta con un ESP ante contingencia de uno de los transformadores, sin embargo, debido a desviaciones de la demanda que se han presentado en la operación en tiempo real, es necesario cuidar este corte en red completa. | J20: PTRA05299: Nueva Río 220/110 kV | K20: PTRA05299 | M20: Tebsa 220 kV, Barraquilla 220kV | N20: Tebsa 110 kV, Flores 1, Flores 4 | O20: 1 | P20: 1
A21: Caribe | B21: Atlántico | C21: 16 | D21: Sabana 9 220/115 kV / Sabana 1 220/115 kV | E21: "+TrfSab9","+TrfSab1" | F21: 90 | G21: NO | H21: Mínima generación en Atlantico Alta demanda al interior de Atlántico | I21: Programar generación en la red de 110 kV. | J21: PTRA05299: Nueva Río 220/110 kV | K21: PTRA05299 | M21: No aplica | N21: Tebsa 110 kV, Flores 1, Flores 4 | O21: 3 | P21: 0
A22: Caribe | B22: Atlántico | C22: 17 | D22: Tebsa - Vte Julio 2 110 T2 / Tebsa - Vte Julio 1 110 T2 | E22: "+LinTebVte221","+LinTebVte211" | F22: 148 | G22: SI | H22: Alta demanda en Veinte Julio 110 kV | I22: Verificar suficiencia ESP LINEAS TEBSA - VTE JULIO 110 kV | J22: No hay obra de expansión definida en el horizonte de Mediano Plazo. | M22: No aplica | N22: No aplica | O22: 0 | P22: 0
A23: Caribe | B23: Atlántico | C23: 18 | D23: Tebsa - Vte Julio 1 110 T2 / Tebsa - Vte Julio 2 110 T2 | E23: "+LinTebVte211","+LinTebVte221" | F23: 148 | G23: SI | H23: Alta demanda en Veinte Julio 110 kV | I23: Verificar suficiencia ESP LINEAS TEBSA - VTE JULIO 110 kV | J23: No hay obra de expansión definida en el horizonte de Mediano Plazo. | M23: No aplica | N23: No aplica | O23: 0 | P23: 0
A24: Caribe | B24: Atlántico | C24: 19 | D24: Agotamiento capacidad de cortocircuito de Las Flores 110 kV | G24: NO | H24: En operación gran numero de unidades de generación electricamente cercanas | I24: Con recursos de generación de la subárea en línea es posible superar la capacidad de cortocircuito de estas subestaciones por lo que se deben tomar las siguientes medidas, primero la apertura de la bahía de línea en Las Flores hacia El Río 110 kV, segundo desacoplar Termoflores 110 kV, y tercero limitar el número de unidades en línea para mitigar la condición. | J24: No hay obra de expansión definida en el horizonte de Mediano Plazo. Aumento de capacidad de corto circuito de Flores 110 kV (capacidad actual 31,5 kA de ambas subestaciones) | O24: 2 | P24: 1
A25: Caribe | B25: Atlántico | C25: 20 | D25: Agotamiento capacidad de cortocircuito de Oasis 110 kV | G25: NO | H25: En operación gran numero de unidades de generación electricamente cercanas | O25: 2 | P25: 1
A26: Caribe | B26: Atlántico | C26: 21 | D26: Agotamiento capacidad de cortocircuito de Silencio 110 kV | G26: NO | H26: En operación gran numero de unidades de generación electricamente cercanas | J26: No hay obra de expansión definida en el horizonte de Mediano Plazo. | O26: 2 | P26: 1
A27: Caribe | B27: Atlántico | C27: 22 | D27: Agotamiento capacidad de cortocircuito de El Río 110 kV | G27: NO | H27: En operación gran numero de unidades de generación electricamente cercanas | J27: No hay obra de expansión definida en el horizonte de Mediano Plazo. | O27: 2 | P27: 1
A28: Caribe | B28: Atlántico | C28: 23 | D28: Agotamiento capacidad de cortocircuito de Centro 110 kV | G28: NO | H28: En operación gran numero de unidades de generación electricamente cercanas | J28: No hay obra de expansión definida en el horizonte de Mediano Plazo. | O28: 2 | P28: 1
A29: Caribe | B29: Atlántico | C29: 24 | D29: Agotamiento capacidad de cortocircuito de Tebsa 110 kV | G29: NO | H29: En operación gran numero de unidades de generación electricamente cercanas | J29: No hay obra de expansión definida en el horizonte de Mediano Plazo. | O29: 2 | P29: 1
A30: Caribe | B30: Atlántico | C30: 25 | D30: Agotamiento capacidad de cortocircuito de Termoflores 110 kV | G30: NO | H30: En operación gran numero de unidades de generación electricamente cercanas | J30: No hay obra de expansión definida en el horizonte de Mediano Plazo. | O30: 2 | P30: 1
A31: Caribe | B31: Atlántico | C31: 26 | D31: Agotamiento capacidad de cortocircuito de Nueva Magdalena 110 kV | G31: NO | H31: En operación gran numero de unidades de generación electricamente cercanas | J31: No hay obra de expansión definida en el horizonte de Mediano Plazo. | O31: 2 | P31: 1
A32: Caribe | B32: Atlántico | C32: 27 | D32: Agotamiento capacidad de cortocircuito de Unión 110 kV | G32: NO | H32: En operación gran numero de unidades de generación electricamente cercanas | J32: No hay obra de expansión definida en el horizonte de Mediano Plazo. | O32: 2 | P32: 1
A33: Caribe | B33: Atlántico | C33: 28 | D33: Agotamiento capacidad de cortocircuito de Tebsa 220 kV | G33: NO | H33: En operación gran numero de unidades de generación electricamente cercanas | I33: Limitar el número de unidades en línea de la subárea Atlántico para mitigar la condición. | J33: No hay obra de expansión definida en el horizonte de Mediano Plazo. | O33: 2 | P33: 1
A34: Caribe | B34: Atlántico | C34: 29 | D34: Agotamiento capacidad de cortocircuito de Sabanalarga 220 kV | G34: NO | H34: En operación gran numero de unidades de generación electricamente cercanas | J34: PTRA13494: Reconfiguración de la Subestación Sabanalarga 220 Kv - FPO: 2026/11/30 | K34: PTRA13494 | O34: 2 | P34: 1
A35: Caribe | B35: Atlántico | C35: 30 | D35: Agotamiento capacidad de cortocircuito de TermoFlores 220 kV | G35: NO | H35: En operación gran numero de unidades de generación electricamente cercanas | J35: No hay obra de expansión definida en el horizonte de Mediano Plazo. | O35: 2 | P35: 1
A36: Caribe | B36: Atlántico | C36: 31 | D36: Agotamiento capacidad de cortocircuito de Nv Barranquilla 220 kV | G36: NO | H36: En operación gran numero de unidades de generación electricamente cercanas | J36: No hay obra de expansión definida en el horizonte de Mediano Plazo. | O36: 2 | P36: 1
A37: Caribe | B37: Bolívar | C37: 1 | D37: Ternera - Zaragocilla 66 kV / Cartagena - Zaragocilla 66 kV | E37: "+CI0759","+ZarCar7" | F37: 64 | G37: SI | H37: Depende de la magnitud de carga en Zaragocilla 66 kV | I37: Validarse suficiencia del ESPS de sobrecarga de las líneas Ternera – Zaragocilla 66 kV y Cartagena – Zaragocilla 66 kV | J37: PTRA02446: Subestación Campestre 66 kV, mitiga pero no es suficiente | M37: No aplica | N37: No aplica | O37: 0 | P37: 0
A38: Caribe | B38: Bolívar | C38: 2 | D38: Cartagena - Zaragocilla 66 kV / Ternera - Zaragocilla 66 kV | E38: "+ZarCar7","+CI0759" | F38: 64 | G38: SI | H38: Depende de la magnitud de carga en Zaragocilla 66 kV | I38: Validarse suficiencia del ESPS de sobrecarga de las líneas Ternera – Zaragocilla 66 kV y Cartagena – Zaragocilla 66 kV | J38: PTRA02446: Subestación Campestre 66 kV, mitiga pero no es suficiente | M38: No aplica | N38: No aplica | O38: 0 | P38: 0
A39: Caribe | B39: Bolívar | C39: 3 | D39: Baja tensión en Gambote 66 kV y Sobrecarga de Ternera – Gambote 66 kV en estado normal de operación | E39: "-CI0757" | F39: 26 | G39: NO | H39: Depende de la magnitud de carga en Gambote 66 kV | I39: Operar con tensión similar en los nodos de Ternera y Bosque 66 kV, para disminuir los Mvar en tránsito. En caso de sobrecarga o baja tensión, solicitar desatención de demanda en Gambote 66 kV | J39: PTRA01139: Carreto 500 kV y circuitos asociados. PTRA02158: Carreto 66 kV y circuitos asociados. | K39: PTRA01139, PTRA02158 | L39: Identificar obras entre los OR y la UPME para eliminar la condición radial | M39: No aplica | N39: No aplica | O39: 1 | P39: 1
A40: Caribe | B40: Bolívar | C40: 4 | D40: Proelectrica - Mamonal 66 kV / Proelectrica - Membrillal 66 kV | E40: "-CI0741","-CI1238" | F40: 94 | G40: NO | H40: Maximo despacho en Proelectrica sin Termocandelaria En demanda máxima con acople 6030 en Proelectrica 66 kV cerrado. | I40: Aumentar perfil de tension en Ternera 66 kV, limitar generación en Proelectrica | J40: No hay obra de expansión definida en el horizonte de Mediano Plazo. | M40: Proeléctrica | N40: Candelaria | O40: 0 | P40: 0
...

Sheet Restricciones SDL
A1: Area | B1: Subárea | C1: Número | D1: Restricción | E1: FKEYS | F1: Corte [MW] | G1: ESPS | H1: Escenario | I1: Recomendación operativa | J1: Proyecto de Expansión Mediano plazo | K1: Codigo | L1: Acciones de corto plazo recomendadas | M1: Generación a limitar | N1: Generación a subir | O1: Estado restricción | P1: Origen de la restricción
A2: Caribe | B2: Atlántico | C2: 1 | D2: Las Flores 1 110/34.5 kV / Las Flores 2 110/34.5 kV | E2: "+TR0456","+TR0531" | F2: 60 | G2: NO | H2: Independiente del escenario de generación. En demanda máxima y media. | I2: • No hay manera de cubrir esta restricción ni de disminuir su impacto, por lo que se presentaría desatención de demanda de manera descontrolada. • Para cubrirla sería necesario programar DNA preventiva si aplica la CREG 224 de 2016 • Cabe resaltar que este valor de corte es dependiente del escenario de generación, por lo que puede existir un valor diferente dependiendo de la manera como se cubra. | J2: No hay obra de expansión definida en el horizonte de Mediano Plazo. Sí bien las SAEB tienen impacto positivo esta restricción no hace parte de su lógica. Se requieren definir TDC, obras a nivel de SDL, o proyectos de expansión • Evaluar la pertinencia de instalar un ESPS | L2: Evaluar el aumeto de capacidad de transporte de corriente del circuito. Se recomienda al OR evaluar la implementación de un esquema suplementario para mitigar el impacto de la restricción | M2: No aplica | N2: No aplica | O2: 1 | P2: 0
A3: Caribe | B3: Atlántico | C3: 2 | D3: Las Flores 2 110/34.5 kV / Las Flores 1 110/34.5 kV | E3: "+TR0531","+TR0456" | F3: 60 | G3: NO | H3: Independiente del escenario de generación. En demanda máxima y media. | I3: • No hay manera de cubrir esta restricción ni de disminuir su impacto, por lo que se presentaría desatención de demanda de manera descontrolada. • Para cubrirla sería necesario programar DNA preventiva si aplica la CREG 224 de 2016 • Cabe resaltar que este valor de corte es dependiente del escenario de generación, por lo que puede existir un valor diferente dependiendo de la manera como se cubra. | J3: No hay obra de expansión definida en el horizonte de Mediano Plazo. Sí bien las SAEB tienen impacto positivo esta restricción no hace parte de su lógica. Se requieren definir TDC, obras a nivel de SDL, o proyectos de expansión • Evaluar la pertinencia de instalar un ESPS | L3: Evaluar el aumeto de capacidad de transporte de corriente del circuito. Se recomienda al OR evaluar la implementación de un esquema suplementario para mitigar el impacto de la restricción | M3: No aplica | N3: No aplica | O3: 1 | P3: 0
A4: Caribe | B4: Atlántico | C4: 3 | D4: Silencio 4N 110/34.5 / Las Flores 1 110/34.5 + Las Flores 2 110/34.5 | E4: "+TrfSil1374","+TR0456","+TR0531" | F4: 120 | G4: NO | H4: Independiente del escenario de generación. En demanda máxima y media. | I4: • No hay manera de cubrir esta restricción ni de disminuir su impacto, por lo que se presentaría desatención de demanda de manera descontrolada. • Para cubrirla sería necesario programar DNA preventiva si aplica la CREG 224 de 2016 • Cabe resaltar que este valor de corte es dependiente del escenario de generación, por lo que puede existir un valor diferente dependiendo de la manera como se cubra. | J4: No hay obra de expansión definida en el horizonte de Mediano Plazo., si bien las SAEB tienen impacto positivo esta restricción no hace parte de su lógica. Se requieren definir TDC, obras a nivel de SDL, o proyectos de expansión • Evaluar la pertinencia de instalar un ESPS | L4: Evaluar el aumeto de capacidad de transporte de corriente del circuito. Se recomienda al OR evaluar la implementación de un esquema suplementario para mitigar el impacto de la restricción | M4: No aplica | N4: No aplica | O4: 1 | P4: 0
A5: Caribe | B5: Atlántico | C5: 4 | D5: Silencio 5 110/34.5 / Las Flores 1 110/34.5 + Las Flores 2 110/34.5 | E5: "+TR0466","+TR0456","+TR0531" | F5: 120 | G5: NO | H5: Independiente del escenario de generación. En demanda máxima y media. | I5: • No hay manera de cubrir esta restricción ni de disminuir su impacto, por lo que se presentaría desatención de demanda de manera descontrolada. • Para cubrirla sería necesario programar DNA preventiva si aplica la CREG 224 de 2016 • Cabe resaltar que este valor de corte es dependiente del escenario de generación, por lo que puede existir un valor diferente dependiendo de la manera como se cubra. | J5: No hay obra de expansión definida en el horizonte de Mediano Plazo. si bien las SAEB tienen impacto positivo esta restricción no hace parte de su lógica. Se requieren definir TDC, obras a nivel de SDL, o proyectos de expansión • Evaluar la pertinencia de instalar un ESPS | L5: Evaluar el aumeto de capacidad de transporte de corriente del circuito. Se recomienda al OR evaluar la implementación de un esquema suplementario para mitigar el impacto de la restricción | M5: No aplica | N5: No aplica | O5: 1 | P5: 0
A6: Caribe | B6: Bolívar | C6: 1 | D6: Ternera 5 66/13.8/6.9 kV / Ternera 3 66/13.8/6.9 kV | E6: "+TrfTer675","+TrfTer673" | F6: 38 | G6: SI | H6: Depende de la magnitud de carga en Ternera 13.8 y 6.9 kV | I6: Verificar suficiencia ESPS Ternera 66/13.8/6.9 kV | J6: No hay proyecto definido, los traslados a Campestre y Turbaco no son suficientes | M6: No aplica | N6: No aplica | O6: 0 | P6: 1
A7: Caribe | B7: Bolívar | C7: 2 | D7: Ternera 3 66/13.8/6.9 kV / Ternera 5 66/13.8/6.9 kV | E7: "+TrfTer673","+TrfTer675" | F7: 38 | G7: SI | H7: Depende de la magnitud de carga en Ternera 13.8 y 6.9 kV | I7: Verificar suficiencia ESPS Ternera 66/13.8/6.9 kV | J7: No hay proyecto definido, los traslados a Campestre y Turbaco no son suficientes | M7: No aplica | N7: No aplica | O7: 0 | P7: 1
A8: Caribe | B8: GCM | C8: 1 | D8: Sobrecarga Valledupar 9 110/34.5 kV | E8: "+Trf1889" | F8: 37 | G8: NO | H8: Demanda media y máxima | I8: Operar con alto perfil de tensión, se requieren TDC por parte del OR | J8: No hay obra de expansión definida en el horizonte de Mediano Plazo. (con el proyecto PTRA05302: Nueva San Juan 110 kV, se revizará la posibilidad de anillar por 34.5kV) | L8: Identificar obras entre los OR y la UPME para eliminar la condición radial | M8: No aplica | N8: No aplica | O8: 1 | P8: 1
A9: Caribe | B9: GCM | C9: 2 | D9: Sobrecarga Valledupar 9 110/34.5 kV (Sentido 34.5 kV a 110 kV) | E9: "-Trf1889" | F9: 37 | G9: NO | H9: Demanda mínima con alta generación de en los recursos solares conectados en la barra 3 de Valledupar 34.5 kV. | I9: Limitar la generación de los recursos solares conectados en la barra 3 de Valledupar 34.5 kV | J9: No hay obra de expansión definida en el horizonte de Mediano Plazo. | M9: Valledupar 1, Valledupar 2 | N9: No aplica | O9: 3 | P9: 0
A10: Caribe | B10: GCM | C10: 3 | D10: Valledupar – Guatapurí 34,5 kV LN 599 / Valledupar – Guatapurí 34,5 kV LN 513 | E10: "-LinGuaVal71","-LinGuaVal72" | F10: 30 | G10: SI | H10: Dependiente de la demanda en Guatapurí 34,5 | I10: Validar suficiencia del ESPS asociado a sobrecarga de los circuitos Valledupar – Guatapurí 34,5 kV | J10: PTRA05302: Nueva San Juan 110 kV | K10: PTRA05302 | M10: No aplica | N10: No aplica | O10: 0 | P10: 1

Sheet Restricciones nuevas
A1: Area | B1: Subárea | C1: Número | D1: Restricción | E1: FKEYS | F1: Corte [MW] | G1: CAUSA | H1: Escenario | I1: Recomendación operativa | J1: Proyecto de Expansión Mediano plazo | K1: Codigo | L1: Acciones de corto plazo recomendadas | M1: Generación a limitar | N1: Generación a subir | O1: Estado restricción | P1: Origen de la restricción
A2: Oriental | B2: Bogotá | C2: 38 | D2: Bacata 1 500/120 kV / Bacata 2 500/120 kV | E2: "+TrfBac5171","+TrfBac5172" | F2: 590 | G2: Refuerza restricción existente de Bacata 2 500/120 kV / Bacata 1 500/120 kV, ya que por la sensibilidad en reactiva puede activarse primero | H2: Demanda máxima, media Baja generación al interior del área Oriental | I2: Controlar mediante taps de transformadores Bacatá 500/115 kV y compensación reactiva en la red de 115 kV. Si no es suficiente, incrementar generación al interior del área. | J2: No hay obra de expansión definida en el horizonte de Mediano Plazo | M2: No aplica | N2: Guavio, Chivor, Pagua, Zipa | O2: 3 | P2: 0
A3: Oriental | B3: Bogotá | C3: 41 | D3: Nva Esperanza - San Mateo 1 230 kV / Nva Esperanza 3 500/115/11.4 kV | E3: "+LinNEsSMa21","+TrfNvE5171" | F3: 650 | G3: El crecimiento en la demanda del Meta contribuyó a la identificación de esta contingencia, está muy cercana en sobrecarga a la que impone el límite de Oriental. Se marca debido a la sensibilidad que tiene con los escenarios de demanda. | H3: Demanda máxima en el Meta Baja generación en Oriental | I3: Incrementar generación al interior de Oriental, siendo las más efectivas Guavio y Chivor | J3: No hay obra de expansión definida en el horizonte de Mediano Plazo | M3: No aplica | N3: Guavio, Chivor | O3: 3 | P3: 0
A4: Antioquia | B4: Antioquia | C4: 18 | D4: San Carlos 2 230/500 kV / San Carlos 3 230/500 kV | E4: "-TrfSc55232","-TrfSc55233" | F4: 650 | G4: Crecimiento de recursos de generación en antioquia en niveles de 220 kV o inferiores | H4: Demanda máxima y media. Baja generación en Recursos de generación de Antioquia 500 kV y Caribe, alta generación de recursos de Antioquia 220 kV o inferiores. | I4: En orden de impacto: 1. Bajar generación en San Carlos 2. Bajar generación en Termosierra 3. Bajar generación en Porce II 4. Subir generación en Porce III 5. Subir generación Caribe | J4: No hay obra de expansión definida en el horizonte de Mediano Plazo | M4: San Carlos, Termosierra | N4: Ituango, Porce III, Urrá | O4: 3 | P4: 0
A5: Antioquia | B5: Antioquia | C5: 19 | D5: San Carlos 3 230/500 kV / San Carlos 4 230/500 kV | E5: "-TrfSc55233","-TrfSc55234" | F5: 650 | G5: Crecimiento de recursos de generación en antioquia en niveles de 220 kV o inferiores | H5: Demanda máxima y media. Baja generación en Recursos de generación de Antioquia 500 kV y Caribe, alta generación de recursos de Antioquia 220 kV o inferiores. | I5: En orden de impacto: 1. Bajar generación en San Carlos 2. Bajar generación en Termosierra 3. Bajar generación en Porce II 4. Subir generación en Porce III 5. Subir generación Caribe | J5: No hay obra de expansión definida en el horizonte de Mediano Plazo | M5: San Carlos, Termosierra | N5: Ituango, Porce III, Urrá | O5: 3 | P5: 0
A6: Antioquia | B6: Antioquia | C6: 20 | D6: San Carlos 4 230/500 kV / San Carlos 2 230/500 kV | E6: "-TrfSc55234","-TrfSc55232" | F6: 650 | G6: Crecimiento de recursos de generación en antioquia en niveles de 220 kV o inferiores | H6: Demanda máxima y media. Baja generación en Recursos de generación de Antioquia 500 kV y Caribe, alta generación de recursos de Antioquia 220 kV o inferiores. | I6: En orden de impacto: 1. Bajar generación en San Carlos 2. Bajar generación en Termosierra 3. Bajar generación en Porce II 4. Subir generación en Porce III 5. Subir generación Caribe | J6: No hay obra de expansión definida en el horizonte de Mediano Plazo | M6: San Carlos, Termosierra | N6: Ituango, Porce III, Urrá | O6: 3 | P6: 0
A7: Antioquia | B7: Antioquia | C7: 24 | D7: Agotamiento capacidad de cortocircuito de Primavera220 kV | G7: El nivel de cortocircuito se encontraba cercano al 100%. Con la entrada del proyecto PTRA03852 – Segundo Transformador Primavera 500/230 kV – 450 MVA (UPME 01 – 2023), se ve superada su capacidad nominal. | H7: En línea un alto número de recursos de generación cercanos eléctricamente | I7: Evaluar la pertinencia de disminuir el número de unidades en línea. En caso de requerirse, techar generación en:Termocentro, Termosierra. Merilectrica, San Carlos | J7: No hay obra de expansión definida en el horizonte de Mediano Plazo | M7: Termocentro, Termosierra. Merilectrica, San Carlos | O7: 2 | P7: 1
A8: Antioquia | B8: Antioquia | C8: 24 | D8: Agotamiento capacidad de cortocircuito de Central 110 kV | G8: El nivel de cortocircuito se encontraba cercano al 100%. Con la entrada del proyecto PTRA04454 – SE Industriales 110 kV, se ve superada su capacidad nominal. | H8: En línea un alto número de recursos de generación cercanos eléctricamente | I8: Evaluar la pertinencia de disminuir el número de unidades en línea. | J8: No hay obra de expansión definida en el horizonte de Mediano Plazo | O8: 2 | P8: 1
A9: Oriental | B9: Bogotá | C9: 42 | D9: Agotamiento capacidad de cortocircuito de Nva Esperanza 115 kV | H9: En línea un alto número de recursos de generación cercanos eléctricamente | I9: Evaluar la pertinencia de disminuir el número y unidades en línea | J9: No hay obra de expansión definida en el horizonte de Mediano Plazo | O9: 2 | P9: 1
A10: Suroccidental | B10: Suroccidente | C10: 1 | D10: La Virginia - San Marcos 1 500 kV / Virginia 500/230 kV | E10: "+LrtSmaVir51r","+TrfVr55231" | F10: 650 | G10: Se activa restricción debido al incremento en el límite de importación por la entrada de la S/E Alferez 500 kV | H10: Demandas máxima y media. Estas restricciones se activan cuando la importación del área es mayor a 650 MW, es decir, en un escenario con baja generación al interior del área suroccidental | I10: -Subir la generación al interior del área Suroccidental y Oriental -Bajar la generación en áreas como Antioquia y Caribe Solo en caso de ser necesario, considerar abrir el enlace Heliconia - La Virginia 500 kV | J10: No hay obra de expansión definida en el horizonte de mediano plazo | M10: No aplica | N10: Quimbo, Betania, Alto y bajo Anchicayá, Termoemcali, Termovalle, en general la generación de suroccidental | O10: 3 | P10: 0
A11: Suroccidental | B11: Suroccidente | C11: 2 | D11: Alferez - San Marcos 1 500 kV / San Marcos 230/500 kV | E11: "+LinAlfSma51","-TrfSm55231" | F11: 530 | G11: Se activa restricción debido al incremento en el límite de importación por la entrada de la S/E Alferez 500 kV | H11: Demanda minima. Alta generación en suroccidental y alta importación desde Ecuador (altos excedentes desde el suroccidente) | I11: -Bajar la generación al interior del área Suroccidental -Subir la generación en las otras áreas del SIN, especialmente Antioquia y Oriental | J11: No hay obra de expansión definida en el horizonte de mediano plazo | M11: Quimbo, Betania, Alto y bajo Anchicayá, Termoemcali, Termovalle, en general la generación de suroccidental | N11: No aplica | O11: 3 | P11: 0
A12: Suroccidental | B12: Suroccidente | C12: 3 | D12: San Marcos - La Virginia 1 500 kV / Virginia 230/500 kV | E12: "-LrtSmaVir51r","-TrfVr55231" | F12: 680
A13: Suroccidental | B13: Caquetá | C13: 2 | D13: Interruptor S200 Betania 220 kV (Barra 1-Sección 2 a Barra 1-Sección 1) / Altamira - Hobo 115 kV | E13: "-Brk06466","+CI0006" | F13: 270 | G13: Es ante un escenario particular de generación, donde se existe un desbalance en la generación de Betania. Es decir, alta generación en Betania 3 y baja generación en Betania 1 y 2. | H13: Todos los escenarios de demanda. Alta generación en Betania 3 y Baja generación en Betania 1 y 2. Alta importación desde Ecuador. Alta generación en Quimbo, Termovalle y TermoEmcali. Coordinar la entrada de operasción en Betania. | I13: Reducir importaciones desde Ecuador - Reducir generación en Quimbo - Aumentar generación en Betania 1 y 2 - Disminuir generación en Betania 3 | J13: Los siguientes proyectos permiten mitigar mas no eliminar la restricción (la nueva generación prevista vuelve a activarla) - PROG08336: Campoalaegre Solar - PTRA09586 y PTRA03843 (Huila 230/115 kV) | M13: Betania 3, Quimbo, Termoemcali y Termovalle | N13: Betania 1 y 2 | O13: 3 | P13: 0
A14: Suroccidental | B14: Huila-Tolima | C14: 1 | D14: Betania - TSeboruco 1 115 k V / Betania - Sur 1 115 kV | E14: "+LinBetSbr11","+LinBetSur11" | F14: 135 | G14: Con la repotenciación de la línea Betania - Tseboruco, ahora la restricción de nivel 1 es la que impacta a la línea sin repotencia Betania - Sur 115 kV | H14: Demandas máxima, media y mínima, en escenarios de alta generación en Betania, Quimbo, alta importación desde Ecuador, baja generación en el área oriental y alta generación en el Valle, baja generación a nivel de 115 kV en Huila-Tolima, Prado, Amoyá y Cucuana. | I14: La acción más efectiva para mitigar este corte es aumentar la generación en Prado, de igual manera se recomienda realizar los siguientes balances de generación: - Bajar la generación en Betania y Quimbo, bajar la importación desde Ecuador y bajar la generación en el Valle - Subir la generación menor de la subárea Huila -Tolima y subir la generación en Oriental | J14: No hay obra de expansión definida en el horizonte de mediano plazo | M14: Quimbo, Betania | N14: Amoya, Cucuana y Prado | O14: 3 | P14: 0
A15: Suroccidental | B15: Huila-Tolima | C15: 2 | D15: Betania - El Bote 1 115 k V / Betania - Sur 1 115 kV | E15: "+CI0063","+LinBetSur11" | F15: 135 | G15: Con la repotenciación de la línea Betania - Tseboruco, ahora la restricción de nivel 1 es la que impacta a la línea sin repotencia Betania - Sur 115 kV | M15: Quimbo, Betania | N15: Amoya, Cucuana y Prado | O15: 3 | P15: 0

Sheet Restricciones_Futuras
A1: Area | B1: Subarea | C1: Número | D1: Restricción | E1: FKEYS | F1: Corte [MW] | G1: ESPS | H1: Escenario | I1: Recomendación operativa | J1: Proyecto de Expansión Mediano plazo | K1: Codigo | L1: Acciones de corto plazo recomendadas | M1: Generación a limitar | N1: Generación a subir | O1: Estado restricción | P1: Origen de la restricción | Q1: Cuando ingresa la restricción?
A2: Suroccidental | B2: Valle | C2: Nueva | D2: Estambul – Juanchito 1 115 kV / Estambul - Juanchito 2 115 kV | E2: "+LinEstJua11", "+LinEstJua12" | F2: 170 | G2: No
A3: Antioquia | B3: Antioquia | C3: Nueva | D3: Urabá – Nueva Colonia 110 kV / Urabá – Apartadó 110 kV | E3: "+CI0806", "+LinNCoUrb11" | F3: 70 | G3: No | H3: Alta generación en las subestaciones Apartadó 110 kV y Nueva Colonia 110 kV (con el circuito Apartadó - Caucheras 110 kV abierto en un extremo). | I3: Desatender demanda en Apartadó 110 kV o Nueva Colonia 110 kV.
A4: Caribe | B4: Atlántico | C4: nueva | D4: Tebsa – Caracolí 220 kV / Tebsa – El Río 220 kV | F4: 390 | G4: NO | H4: Alta generación Tebsa y Barranquilla y baja en Flores 1 y Flores 4 | I4: • Balance de generación entre Flores 1 - Flores 4 y Tebsa - Barranquilla. | J4: No hay obra de expansión definida en el horizonte de Mediano Plazo. | M4: Tebsa, Barranquilla | N4: Flores 1, Flores 4 | O4: 0 | P4: 0 | Q4: Ingresa con los trafos de El Río 220/110kV
A5: Caribe | B5: Atlántico | C5: nueva | D5: Sabanalarga 2 500/220 kV / Sabanalarga 1 y 3 500/220 kV | F5: 880 | H5: Alta generación recursos de generación a conectar en Sabanalarga 500 kV | M5: Recursos en Sabanalarga 500 kV | N5: Genergación al interior de Caribe 2 | O5: 0 | P5: 0 | Q5: Ingresa con el proyecto Guayepo 400MW
B6: TOMA DE CARGA METRO | D6: Salitre - Chicalá 1 115 T1 kV / Colegio - Porvenir 1 115 kV | E6: "+CI0982","+LinColPor11" | F6: 150 | G6: NO | H6: Gestión de demanda. Radialidad.
B7: Occidente. | D7: Noroeste 1 230 kV/115 kV / Balsillas – Mosquera 115 kV | E7: "+TrfNor2171", "+CI0033" | F7: 230 | G7: NO | H7: Baja generación en Oriental Demanda máxima y media Subir generación en Zipa.

Sheet Restricciones_Eliminadas
A1: Area | B1: Subarea | C1: Número | D1: Restricción | E1: FKEYS | F1: Corte [MW] | G1: ESPS | H1: Escenario | I1: Recomendación operativa | J1: Proyecto de Expansión Mediano plazo | K1: Codigo | L1: Acciones de corto plazo recomendadas | M1: Generación a limitar | N1: Generación a subir | O1: Estado restricción | P1: Origen de la restricción | Q1: AAAAMMDD_NOTA
A2: Caribe | B2: Atlántico | C2: 24 | D2: Oasis - Silencio 110 kV / Oasis - Centro 110 kV | E2: "+CI0316","-CI0123" | F2: 95 | G2: SI | H2: Alta generación en Flores 1 y Flores 4 con baja generación en Tebsa y Barranquilla | I2: Balance de generación entre Flores 1 - Flores 4 y Tebsa – Barranquilla. De no ser posible eliminar esta restricción con balance de generación, verificar suficiencia ESPS sobrecarga de Oasis – Centro 110 kV | J2: PTRA00669: Convocatoria Atlántico ETAPA 4 Subestación Estadio 110 kV y circuitos asociados | K2: PTRA00669 | M2: Flores 1, Flores 4 | N2: Tebsa, Barranquilla | O2: 0 | P2: 0 | Q2: 20231102_Con el ingreso de la etapa 4 del proyectos UPME STR-02 Atlántico se eliminó esta restricción
A3: Caribe | B3: Atlántico | C3: 24 | D3: Tebsa - Unión 110 kV / Tebsa - El Río 110 kV | E3: "+CI0484","-CI0454" | F3: 140 | G3: SI | H3: Alta generación en Tebsa y Barranquilla. Baja generación en Flores 1 y Flores 4. | I3: • Balance de generación entre Flores 1 - Flores 4 y Tebsa - Barranquilla. • De no ser posible eliminar esta restricción con balance de generación, verificar suficiencia ESPS de sobrecarga de la línea Tebsa – El Río 110 kV . | J3: PTRA00669: Convocatoria Atlántico ETAPA 5 circuito Tebsa - Magdalena 110 kV | K3: PTRA00669 | M3: Tebsa, Barranquilla | N3: Flores 1, Flores 4 | O3: 1 | P3: 0 | Q3: 20231103_Con el ingreso de la etapa 5 del proyectos UPME STR-02 Atlántico se eliminó esta restricción
A4: Caribe | B4: Atlántico | C4: 25 | D4: El Río 110/34.5 kV / Tebsa - Unión 110 kV | E4: "+TR0454","+CI0484" | F4: 105 | G4: SI | H4: Independiente del escenario. | I4: • No hay manera de cubrir esta restricción ni de disminuir su impacto, por lo que se presentaría desatención de demanda de manera descontrolada. • Para cubrirla sería necesario programar DNA preventiva si aplica la CREG 224 de 2016 | J4: PTRA00669: Convocatoria Atlántico ETAPA 5 circuito Tebsa - Magdalena 110 kV | K4: PTRA00669 | L4: Evaluar el aumeto de capacidad de transporte de corriente del circuito. Se recomienda al OR evaluar la implementación de un esquema suplementario para mitigar el impacto de la restricción | M4: No aplica | N4: No aplica | O4: 1 | P4: 0
A5: Caribe | B5: Atlántico | C5: 26 | D5: Sobrecarga en del circuito Tebsa - Unión 110 kV | E5: "+CI0484" | F5: 110 | G5: SI | H5: Independiente del escenario. | I5: Si bien puede mitigarse con balance de generación, se identifica que su criticidad esta asociada principalmente a la demanda. | J5: PTRA00669: Convocatoria Atlántico ETAPA 5 circuito Tebsa - Magdalena 110 kV | K5: PTRA00669 | M5: Tebsa, Barranquilla | N5: Flores 1, Flores 4 | O5: 1 | P5: 1
A6: Caribe | B6: Atlántico | C6: 27 | D6: Tebsa - El Río 110 kV / Tebsa - Unión 110 kV | E6: "-CI0454","+CI0484" | F6: 135 | G6: SI | H6: Alta generación en Tebsa y Barranquilla. Baja generación en Flores 1 y Flores 4. | I6: • Balance de generación entre Flores 1 - Flores 4 y Tebsa – Barranquilla. • De no ser posible eliminar esta restricción con balance de generación. • Verificar suficiencia ESPS de sobrecarga de Tebsa – Cordialidad 110 kV | J6: PTRA00669: Convocatoria Atlántico ETAPA 5 circuito Tebsa - Magdalena 110 kV | K6: PTRA00669 | M6: Tebsa, Barranquilla | N6: Flores 1, Flores 4 | O6: 1 | P6: 0
A7: Caribe | B7: Cordoba-Sucre | C7: =C6+1 -> 28 | D7: Sobrecarga del transformador El Carmen 110/66/13.8 kV | E7: "+TR0522" | F7: 44 | G7: NO | H7: Demanda media y máxima | I7: En lo posible operar en sus devanados de 110 y 66 kV con una tensión alta pero segura y regulatoria. Durante el transitorio asociado a fallas, entre mayor es la carga de este equipo en menor la recuperación transitoria de tensión en nodos radiales a 66 kV que se alimentan de este equipo. | J7: PTRA01139: Carreto 500 kV y circuitos asociados. PTRA02158: Carreto 66 kV y circuitos asociados. | K7: PTRA01139, PTRA02158 | L7: Identificar obras entre los OR y la UPME para eliminar la condición radial | M7: No aplica | N7: No aplica | O7: 1 | P7: 1 | Q7: 20231029_Con la entrada en operación del segundo transformador El Carmen 110/66/13.8kV empachado con el transformador El Carmen 1 110/66/13.8kV en los niveles de tensión 110kV y 66kV
A8: Caribe | B8: GCM | C8: 2 | D8: Baja tensión en los nodos El Paso y La Jagua 110 kV en estado normal de operación y ante N-1 de La Loma – EL Copey - 500 kV o Chinú - El Copey 500 kV | G8: SI | H8: Independiente del escenario. | I8: Operar con perfil alto de tensión en nodos de la subárea GCM, buscar alta tensión en los nodos de EL Paso y La Jagua110 kV. Cubrir con MW internos las posibles restricciones por sobrecarga ante contingencia sencilla. Realizar conexión de bancos capacitivos al interior | J8: PTRA00203: Circuitos a 110 kV La Loma – La Jagua y La Loma – El Paso | K8: PTRA00203 | M8: No aplica | N8: No aplica | O8: 1 | P8: 0 | Q8: 20231201_Con el ingreso del proyecto La Loma – El Paso y La Loma - La Jagua a 110 kV se eliminan estas restricciones
A9: Caribe | B9: GCM | C9: 3 | D9: Valledupar 11 220/110 kV / Valledupar 2 220/110 kV | E9: "+TrfVll2111","+TrfVal2131" | F9: 95 | G9: SI | H9: Dependiente de la demanda | I9: Validar sufiiencia del ESPS asociado a sobrecarga del ATR Valledupar 2 220/110 kV. Evaluar la necesidad de solicitar desatención de demanda. En Valledupar 34,5 kV no cerrar interruptor 5100 sin la aprobación del equipo de protecciones | J9: PTRA00203: Circuito La Loma – La Jagua 110 kV | K9: PTRA00203 | M9: No aplica | N9: No aplica | O9: 1 | P9: 0
A10: Caribe | B10: GCM | C10: 4 | D10: Copey 1 500/220 kV / Copey 2 500/220 kV | E10: "+TrfCop5231","+TrfCop5232" | F10: 495 | G10: NO | H10: Alta importación de potencia de la subárea GCM | I10: Disminuir la importación de potencia de la subárea GCM aumentando la magnitud de generación al interior. | J10: PTRA00203: Circuitos a 110 kV La Loma – La Jagua y La Loma – El Paso PTRA00243: UPME 09 - 2016 Subestación Cuestecitas 500 kV y Líneas Copey - Cuestecitas 500 kV y Copey - Fundación 220 kV | K10: PTRA00203, PTRA00243 | M10: No aplica | N10: Guajira, Termonorte | O10: 0 | P10: 0
A11: Caribe | B11: Bolívar | C11: =Restricciones!C38+1 -> 3 | D11: Cartagena - Bocagrande 66 kV / Bosque - Bocagrande 66 kV | E11: "-CI0714","-CI0713" | F11: 40 | G11: SI | H11: Depende de la magnitud de carga en Bocagrande 66 kV | I11: • Validar suficiencia del ESPS de sobrecarga en la línea Bosque – Bocagrande 66 kV | J11: PTRA07064: Aumento de capacidad circuito Bosque – Bocagrande 66 kV (FPO: 2023) | K11: PTRA00617, PTRA07064 | M11: No aplica | N11: No aplica | O11: 1 | P11: 0 | Q11: 20231215_Actualización de parámetros técnicos de línea Bocagrande-Bosque 1 66kV
A12: Suroccidental | B12: Huila-Tolima | C12: 1 | D12: Primavera - Bacata 500 kV / Brisas - Nva Cajamarca 1 115 kV | E12: "-PmvBac500,"+LinBriNca11" | F12: 480 | G12: NO | H12: Demanda mínima. Alta generación en Huila-Tolima, Amoyá, Prado, Cucuana, Betania y Quimbo, alta generación en Oriental, generación mínima en Valle y CQR y alta importación desde Ecuador. | I12: La acción más efectiva para controlar el corte es reducir la generación en Huila – Tolima y aumentar la generación en el Valle y CQR | J12: PTRA01398: Repotenciación líneas STR-Tolima. Especialmente la repotenciación de los circuitos: CAJAMARCA - REGIVIT 115 kV y BRISAS - CAJAMARCA 115 kV de 400 A a 757 A. Fecha de entrada: 18/12/2023 | K12: PTRA01398 | M12: Betania, Quimbo, Amoyá, Prado y Cucuana | N12: Calima, Emcali, Termovalle y Salvajina | O12: 0 | P12: 0
A13: Suroccidental | B13: Huila-Tolima | C13: 2 | D13: Primavera - Bacata 500 kV / Nva Cajamarca - Regevit 1 115 kV | E13: "-PmvBac500","+LinCajNca11" | F13: 990 | G13: NO | H13: Demandas máxima y media. Alta generación en el Valle, Antioquia y Caribe, alta exportación hacia Ecuador y baja generación en Betania, Quimbo, CQR y Oriental | I13: La acción más efectiva para controlar el corte es aumentar la generación en Huila – Tolima y reducir la generación en el Valle y CQR | J13: PTRA01398: Repotenciación líneas STR-Tolima. Especialmente la repotenciación de los circuitos: CAJAMARCA - REGIVIT 115 kV y BRISAS - CAJAMARCA 115 kV de 400 A a 757 A. Fecha de entrada: 18/12/2024 | K13: PTRA01398 | M13: Quimbo, Betania y Oriental. | N13: Antioquia y Valle | O13: 0 | P13: 0
A14: Suroccidental | B14: Valle | C14: 3 | D14: Agotamiento capacidad de cortocircuito de Juanchito 115 kV | G14: NO | H14: En línea un alto número de recursos de generación cercanos eléctricamente | J14: Aumento de capacidad de corto circuito a de 26.2 kA a 40 kA | O14: 2 | P14: 1 | Q14: 20231226_Actualización de parámetros por parte del OR
A15: Caribe | B15: Atlántico | C15: 11 | D15: Caracolí – Malambo 1 110 kV / Caracolí – Malambo 2 110 kV | E15: "+LinCrcMal11","+LinCrcMal12" | F15: 120 | G15: NO | H15: Dependiente del escenario de generación | I15: • Balance de generación entre Solar Caracolí - Flores 1 - Flores 4 y Tebsa - Barranquilla. | J15: No hay obra de expansión definida en el horizonte de Mediano Plazo. | M15: Solar Caracolí | N15: No aplica | O15: 0 | P15: 0 | Q15: 20240319_La demanda del MP y los proyectos de generación aún no activa esta restricción
A16: Caribe | B16: Atlántico | C16: =C15+1 -> 12 | D16: Unión 110/34.5 kV / El Río - Magdalena 34.5 kV | E16: "+TR0483","+CI0743-2" | F16: 55 | G16: NO | H16: Independiente del escenario. | I16: • No hay manera de cubrir esta restricción ni de disminuir su impacto, por lo que se presentaría desatención de demanda de manera descontrolada. • Para cubrirla sería necesario programar DNA preventiva si aplica la CREG 224 de 2016 | J16: Traslados de carga que realizará AIR-E a la subestación Magdalena 110 kV (FPO: 2025) • Evaluar la pertinencia de instalar un ESPS | L16: Evaluar el aumeto de capacidad de transporte de corriente del circuito. Se recomienda al OR evaluar la implementación de un esquema suplementario para mitigar el impacto de la restricción | M16: No aplica | N16: No aplica | O16: 1 | P16: 0 | Q16: 20240319_Esta restricción se elimina por el ingreso de Magdalena 110kV
A17: Antioquia | B17: Antioquia | C17: 7 | D17: Calizas – Rio Claro 1 110 kV / Calderas – Guatapé 1 110 kV | E17: "+LinClzRcl11","+NOR-CLD-GTP1" | F17: 110 | G17: NO | H17: Demanda mínima con alta generación de las plantas menores en Antioquia | I17: Bajar generación en las unidades de San Miguel y menores (<20MW). | J17: PTRA00324: UPME 10 -2021 Subestación San Lorenzo 230 kV. | M17: Calderas, Popal, San Miguel, San Matías, El Molino | N17: No aplica | O17: 0 | P17: 0 | Q17: 20240321_En el horizonte analizado no se observó la restricción
A18: Oriental | B18: Meta | C18: 2 | D18: Reforma 3 230/115 kV / Reforma 2 230/115 kV | E18: "+TrfRef2173","+Trfref2172" | F18: 310 | G18: NO | H18: En escenarios de baja generación interna en el Meta y demanda alta, esta sobrecarga podría no ser controlada mediante balances de generación, por lo cual se recomienda que ante dicho escenario se considere desatención de demanda o el traslado de carga a la subestación Villavicencio 115 kV. | I18: En escenarios de baja generación interna en el Meta y demanda alta, esta sobrecarga podría no ser controlada mediante balances de generación, por lo cual se recomienda que ante dicho escenario se considere desatención de demanda o el traslado de carga a la subestación Villavicencio 115 kV. | J18: PTRA00623: Etapa 2 Transformadores Santa Helena 230/115 kV 2X150 MVA (Suria 2) | K18: PTRA00623 | L18: Evaluar el aumeto de capacidad de transporte de corriente del circuito. Se recomienda al OR evaluar la implementación de un esquema suplementario para mitigar el impacto de la restricción | M18: No aplica | N18: No aplica | O18: 3 | P18: 0 | Q18: 20240912_Esta restricción se elimina, ya que existe una más restrictiva Reforma 3 230/115 kV / Reforma 1 230/115 kV
